Workbook

Sheet 在庫一覧
A1: 拠点コード | B1: 拠点名 | C1: 商品コード | D1: 商品名 | E1: 仕入先コード | F1: 仕入先名 | G1: Brand | H1: BrandName | I1: 分類１コード | J1: 分類１名 | K1: 分類２コード | L1: 分類２名 | M1: 分類３コード | N1: 分類３名 | O1: 繰越数量 | P1: 受入数量 | Q1: 払出数量 | R1: 現在数量 | S1: 標準価格 | T1: 標準価格合計 | U1: 原価単価 | V1: 原価合計 | W1: 特価 | X1: 21列目
A2: 130 | B2: FJALLRAVEN STORE 名古屋ファッションワン | C2: 10001006X | D2: タッチウッド (サクラ) | E2: 320008 | F2: 合同会社しもかぷ工房 | G2: SMK | H2: Shimokap | I2: JLB | J2: JLB | K2: ACC | L2: ACC | M2: ACC | N2: ACC | O2: 0 | P2: 55 | Q2: 49 | R2: 6 | S2: 650 | T2: 3900 | U2: 455 | V2: 2730 | W2: #N/A
A3: 130 | B3: FJALLRAVEN STORE 名古屋ファッションワン | C3: 10002X | D3: ジップタブ | E3: 320008 | F3: 合同会社しもかぷ工房 | G3: SMK | H3: Shimokap | I3: JLB | J3: JLB | K3: ACC | L3: ACC | M3: ACC | N3: ACC | O3: 0 | P3: 183 | Q3: 130 | R3: 53 | S3: 500 | T3: 26500 | U3: 350 | V3: 18550 | W3: #N/A
A4: 130 | B4: FJALLRAVEN STORE 名古屋ファッションワン | C4: 10003006X | D4: タッチウッドミニ(サクラ) | E4: 320008 | F4: 合同会社しもかぷ工房 | G4: SMK | H4: Shimokap | I4: JLB | J4: JLB | K4: ACC | L4: ACC | M4: ACC | N4: ACC | O4: 0 | P4: 35 | Q4: 26 | R4: 9 | S4: 600 | T4: 5400 | U4: 420 | V4: 3780 | W4: #N/A
A5: 130 | B5: FJALLRAVEN STORE 名古屋ファッションワン | C5: 11859X | D5: Fire Starter | E5: 320002 | F5: (株)アンプラージュインターナショナル | G5: MRK | H5: Morakniv | I5: JLB | J5: JLB | K5: Knife | L5: Knife | O5: 0 | P5: 5 | Q5: 2 | R5: 3 | S5: 2300 | T5: 6900 | U5: 1380 | V5: 4140 | W5: #N/A
A6: 130 | B6: FJALLRAVEN STORE 名古屋ファッションワン | C6: 12051X | D6: Bush Craft Survival/Orange | E6: 320002 | F6: (株)アンプラージュインターナショナル | G6: MRK | H6: Morakniv | I6: JLB | J6: JLB | K6: Knife | L6: Knife | O6: 0 | P6: 10 | Q6: 9 | R6: 1 | S6: 8500 | T6: 8500 | U6: 5100 | V6: 5100 | W6: #N/A
A7: 130 | B7: FJALLRAVEN STORE 名古屋ファッションワン | C7: 12058X | D7: Camping Axe Oramge | E7: 320002 | F7: (株)アンプラージュインターナショナル | G7: MRK | H7: Morakniv | I7: JLB | J7: JLB | K7: Knife | L7: Knife | M7: AXE | N7: AXE | O7: 0 | P7: 4 | Q7: 3 | R7: 1 | S7: 7000 | T7: 7000 | U7: 4200 | V7: 4200 | W7: #N/A
A8: 130 | B8: FJALLRAVEN STORE 名古屋ファッションワン | C8: 12100003210L/XL | D8: Varmland Cap | E8: 310002 | F8: Fenix APD | G8: FRV | H8: FJALLRAVEN | I8: Apparel | J8: Apparel | K8: Headwears | L8: Headwears | M8: Caps | N8: Caps | O8: 0 | P8: 2 | Q8: 1 | R8: 1 | S8: 6700 | T8: 6700 | U8: 2146 | V8: 2146 | W8: 0
A9: 130 | B9: FJALLRAVEN STORE 名古屋ファッションワン | C9: 12100003210S/M | D9: Varmland Cap | E9: 310002 | F9: Fenix APD | G9: FRV | H9: FJALLRAVEN | I9: Apparel | J9: Apparel | K9: Headwears | L9: Headwears | M9: Caps | N9: Caps | O9: 0 | P9: 2 | Q9: 1 | R9: 1 | S9: 6700 | T9: 6700 | U9: 2146 | V9: 2146 | W9: 0
A10: 130 | B10: FJALLRAVEN STORE 名古屋ファッションワン | C10: 12100003625L/XL | D10: Varmland Cap | E10: 310002 | F10: Fenix APD | G10: FRV | H10: FJALLRAVEN | I10: Apparel | J10: Apparel | K10: Headwears | L10: Headwears | M10: Caps | N10: Caps | O10: 0 | P10: 3 | Q10: 2 | R10: 1 | S10: 6700 | T10: 6700 | U10: 2146 | V10: 2146 | W10: 0
A11: 130 | B11: FJALLRAVEN STORE 名古屋ファッションワン | C11: 12100003625S/M | D11: Varmland Cap | E11: 310002 | F11: Fenix APD | G11: FRV | H11: FJALLRAVEN | I11: Apparel | J11: Apparel | K11: Headwears | L11: Headwears | M11: Caps | N11: Caps | O11: 0 | P11: 3 | Q11: 1 | R11: 2 | S11: 6700 | T11: 13400 | U11: 2146 | V11: 4292 | W11: 0
A12: 130 | B12: FJALLRAVEN STORE 名古屋ファッションワン | C12: 12100003662L/XL | D12: Varmland Cap | E12: 310002 | F12: Fenix APD | G12: FRV | H12: FJALLRAVEN | I12: Apparel | J12: Apparel | K12: Headwears | L12: Headwears | M12: Caps | N12: Caps | O12: 0 | P12: 2 | Q12: 1 | R12: 1 | S12: 6700 | T12: 6700 | U12: 2146 | V12: 2146 | W12: 0
A13: 130 | B13: FJALLRAVEN STORE 名古屋ファッションワン | C13: 12100003662S/M | D13: Varmland Cap | E13: 310002 | F13: Fenix APD | G13: FRV | H13: FJALLRAVEN | I13: Apparel | J13: Apparel | K13: Headwears | L13: Headwears | M13: Caps | N13: Caps | O13: 0 | P13: 2 | Q13: 1 | R13: 1 | S13: 6700 | T13: 6700 | U13: 2146 | V13: 2146 | W13: 0
A14: 130 | B14: FJALLRAVEN STORE 名古屋ファッションワン | C14: 12100004113L/XL | D14: High Coast Wind Cap | E14: 310002 | F14: Fenix APD | G14: FRV | H14: FJALLRAVEN | I14: Apparel | J14: Apparel | K14: Headwears | L14: Headwears | M14: Caps | N14: Caps | O14: 0 | P14: 1 | Q14: 0 | R14: 1 | S14: 6200 | T14: 6200 | U14: 2248 | V14: 2248 | W14: 0
A15: 130 | B15: FJALLRAVEN STORE 名古屋ファッションワン | C15: 12100004300L/XL | D15: High Coast Wind Cap | E15: 310002 | F15: Fenix APD | G15: FRV | H15: FJALLRAVEN | I15: Apparel | J15: Apparel | K15: Headwears | L15: Headwears | M15: Caps | N15: Caps | O15: 0 | P15: 2 | Q15: 1 | R15: 1 | S15: 6200 | T15: 6200 | U15: 2296 | V15: 2296 | W15: 0
A16: 130 | B16: FJALLRAVEN STORE 名古屋ファッションワン | C16: 12100004300S/M | D16: High Coast Wind Cap | E16: 310002 | F16: Fenix APD | G16: FRV | H16: FJALLRAVEN | I16: Apparel | J16: Apparel | K16: Headwears | L16: Headwears | M16: Caps | N16: Caps | O16: 0 | P16: 5 | Q16: 4 | R16: 1 | S16: 6200 | T16: 6200 | U16: 2296 | V16: 2296 | W16: 0
A17: 130 | B17: FJALLRAVEN STORE 名古屋ファッションワン | C17: 12100004550L/XL | D17: High Coast Wind Cap | E17: 310002 | F17: Fenix APD | G17: FRV | H17: FJALLRAVEN | I17: Apparel | J17: Apparel | K17: Headwears | L17: Headwears | M17: Caps | N17: Caps | O17: 0 | P17: 4 | Q17: 3 | R17: 1 | S17: 6200 | T17: 6200 | U17: 2296 | V17: 2296 | W17: 0
A18: 130 | B18: FJALLRAVEN STORE 名古屋ファッションワン | C18: 12100004550S/M | D18: High Coast Wind Cap | E18: 310002 | F18: Fenix APD | G18: FRV | H18: FJALLRAVEN | I18: Apparel | J18: Apparel | K18: Headwears | L18: Headwears | M18: Caps | N18: Caps | O18: 0 | P18: 4 | Q18: 3 | R18: 1 | S18: 6200 | T18: 6200 | U18: 2296 | V18: 2296 | W18: 0
A19: 130 | B19: FJALLRAVEN STORE 名古屋ファッションワン | C19: 1220019755044 | D19: Hoja Hybrid Trousers M | E19: 310002 | F19: Fenix APD | G19: FRV | H19: FJALLRAVEN | I19: Apparel | J19: Apparel | K19: Bottoms | L19: Bottoms | M19: Trousers | N19: Trousers | O19: 0 | P19: 1 | Q19: 0 | R19: 1 | S19: 25500 | T19: 25500 | U19: 9204 | V19: 9204 | W19: 0
A20: 130 | B20: FJALLRAVEN STORE 名古屋ファッションワン | C20: 1220019755046 | D20: Hoja Hybrid Trousers M | E20: 310002 | F20: Fenix APD | G20: FRV | H20: FJALLRAVEN | I20: Apparel | J20: Apparel | K20: Bottoms | L20: Bottoms | M20: Trousers | N20: Trousers | O20: 0 | P20: 1 | Q20: 0 | R20: 1 | S20: 25500 | T20: 25500 | U20: 9204 | V20: 9204 | W20: 0
A21: 130 | B21: FJALLRAVEN STORE 名古屋ファッションワン | C21: 1220019755048 | D21: Hoja Hybrid Trousers M | E21: 310002 | F21: Fenix APD | G21: FRV | H21: FJALLRAVEN | I21: Apparel | J21: Apparel | K21: Bottoms | L21: Bottoms | M21: Trousers | N21: Trousers | O21: 0 | P21: 3 | Q21: 2 | R21: 1 | S21: 25500 | T21: 25500 | U21: 9204 | V21: 9204 | W21: 0
A22: 130 | B22: FJALLRAVEN STORE 名古屋ファッションワン | C22: 1220019755050 | D22: Hoja Hybrid Trousers M | E22: 310002 | F22: Fenix APD | G22: FRV | H22: FJALLRAVEN | I22: Apparel | J22: Apparel | K22: Bottoms | L22: Bottoms | M22: Trousers | N22: Trousers | O22: 0 | P22: 3 | Q22: 2 | R22: 1 | S22: 25500 | T22: 25500 | U22: 9204 | V22: 9204 | W22: 0
A23: 130 | B23: FJALLRAVEN STORE 名古屋ファッションワン | C23: 1220020755046 | D23: High Coast Pack Shorts M | E23: 310002 | F23: Fenix APD | G23: FRV | H23: FJALLRAVEN | I23: Apparel | J23: Apparel | K23: Bottoms | L23: Bottoms | M23: Shorts | N23: Shorts | O23: 0 | P23: 2 | Q23: 1 | R23: 1 | S23: 15000 | T23: 15000 | U23: 5730 | V23: 5730 | W23: 0
A24: 130 | B24: FJALLRAVEN STORE 名古屋ファッションワン | C24: 1220020755048 | D24: High Coast Pack Shorts M | E24: 310002 | F24: Fenix APD | G24: FRV | H24: FJALLRAVEN | I24: Apparel | J24: Apparel | K24: Bottoms | L24: Bottoms | M24: Shorts | N24: Shorts | O24: 0 | P24: 2 | Q24: 1 | R24: 1 | S24: 15000 | T24: 15000 | U24: 5730 | V24: 5730 | W24: 0
A25: 130 | B25: FJALLRAVEN STORE 名古屋ファッションワン | C25: 1220020755050 | D25: High Coast Pack Shorts M | E25: 310002 | F25: Fenix APD | G25: FRV | H25: FJALLRAVEN | I25: Apparel | J25: Apparel | K25: Bottoms | L25: Bottoms | M25: Shorts | N25: Shorts | O25: 0 | P25: 2 | Q25: 1 | R25: 1 | S25: 15000 | T25: 15000 | U25: 5730 | V25: 5730 | W25: 0
A26: 130 | B26: FJALLRAVEN STORE 名古屋ファッションワン | C26: 1220020755052 | D26: High Coast Pack Shorts M | E26: 310002 | F26: Fenix APD | G26: FRV | H26: FJALLRAVEN | I26: Apparel | J26: Apparel | K26: Bottoms | L26: Bottoms | M26: Shorts | N26: Shorts | O26: 0 | P26: 2 | Q26: 1 | R26: 1 | S26: 15000 | T26: 15000 | U26: 5730 | V26: 5730 | W26: 0
A27: 130 | B27: FJALLRAVEN STORE 名古屋ファッションワン | C27: 1220020762546 | D27: High Coast Pack Shorts M | E27: 310002 | F27: Fenix APD | G27: FRV | H27: FJALLRAVEN | I27: Apparel | J27: Apparel | K27: Bottoms | L27: Bottoms | M27: Shorts | N27: Shorts | O27: 0 | P27: 2 | Q27: 1 | R27: 1 | S27: 15000 | T27: 15000 | U27: 5730 | V27: 5730 | W27: 0
A28: 130 | B28: FJALLRAVEN STORE 名古屋ファッションワン | C28: 1220020762548 | D28: High Coast Pack Shorts M | E28: 310002 | F28: Fenix APD | G28: FRV | H28: FJALLRAVEN | I28: Apparel | J28: Apparel | K28: Bottoms | L28: Bottoms | M28: Shorts | N28: Shorts | O28: 0 | P28: 2 | Q28: 1 | R28: 1 | S28: 15000 | T28: 15000 | U28: 5730 | V28: 5730 | W28: 0
A29: 130 | B29: FJALLRAVEN STORE 名古屋ファッションワン | C29: 1220020762550 | D29: High Coast Pack Shorts M | E29: 310002 | F29: Fenix APD | G29: FRV | H29: FJALLRAVEN | I29: Apparel | J29: Apparel | K29: Bottoms | L29: Bottoms | M29: Shorts | N29: Shorts | O29: 0 | P29: 2 | Q29: 1 | R29: 1 | S29: 15000 | T29: 15000 | U29: 5730 | V29: 5730 | W29: 0
A30: 130 | B30: FJALLRAVEN STORE 名古屋ファッションワン | C30: 12200218550L | D30: Keb GTX Trousers M | E30: 310002 | F30: Fenix APD | G30: FRV | H30: FJALLRAVEN | I30: Apparel | J30: Apparel | K30: Bottoms | L30: Bottoms | M30: Trousers | N30: Trousers | O30: 0 | P30: 1 | Q30: 0 | R30: 1 | S30: 85000 | T30: 85000 | U30: 33449 | V30: 33449 | W30: 0
A31: 130 | B31: FJALLRAVEN STORE 名古屋ファッションワン | C31: 12200218550M | D31: Keb GTX Trousers M | E31: 310002 | F31: Fenix APD | G31: FRV | H31: FJALLRAVEN | I31: Apparel | J31: Apparel | K31: Bottoms | L31: Bottoms | M31: Trousers | N31: Trousers | O31: 0 | P31: 1 | Q31: 0 | R31: 1 | S31: 85000 | T31: 85000 | U31: 33449 | V31: 33449 | W31: 0
A32: 130 | B32: FJALLRAVEN STORE 名古屋ファッションワン | C32: 12200218550S | D32: Keb GTX Trousers M | E32: 310002 | F32: Fenix APD | G32: FRV | H32: FJALLRAVEN | I32: Apparel | J32: Apparel | K32: Bottoms | L32: Bottoms | M32: Trousers | N32: Trousers | O32: 0 | P32: 1 | Q32: 0 | R32: 1 | S32: 85000 | T32: 85000 | U32: 33449 | V32: 33449 | W32: 0
A33: 130 | B33: FJALLRAVEN STORE 名古屋ファッションワン | C33: 12200218550XS | D33: Keb GTX Trousers M | E33: 310002 | F33: Fenix APD | G33: FRV | H33: FJALLRAVEN | I33: Apparel | J33: Apparel | K33: Bottoms | L33: Bottoms | M33: Trousers | N33: Trousers | O33: 0 | P33: 1 | Q33: 0 | R33: 1 | S33: 85000 | T33: 85000 | U33: 33449 | V33: 33449 | W33: 0
A34: 130 | B34: FJALLRAVEN STORE 名古屋ファッションワン | C34: 12200219537M | D34: Vardag Summer Shorts M | E34: 310002 | F34: Fenix APD | G34: FRV | H34: FJALLRAVEN | I34: Apparel | J34: Apparel | K34: Bottoms | L34: Bottoms | M34: Shorts | N34: Shorts | O34: 0 | P34: 2 | Q34: 1 | R34: 1 | S34: 14000 | T34: 14000 | U34: 4957 | V34: 4957 | W34: 0
A35: 130 | B35: FJALLRAVEN STORE 名古屋ファッションワン | C35: 12200219537S | D35: Vardag Summer Shorts M | E35: 310002 | F35: Fenix APD | G35: FRV | H35: FJALLRAVEN | I35: Apparel | J35: Apparel | K35: Bottoms | L35: Bottoms | M35: Shorts | N35: Shorts | O35: 0 | P35: 2 | Q35: 1 | R35: 1 | S35: 14000 | T35: 14000 | U35: 4957 | V35: 4957 | W35: 0
A36: 130 | B36: FJALLRAVEN STORE 名古屋ファッションワン | C36: 12200219550L | D36: Vardag Summer Shorts M | E36: 310002 | F36: Fenix APD | G36: FRV | H36: FJALLRAVEN | I36: Apparel | J36: Apparel | K36: Bottoms | L36: Bottoms | M36: Shorts | N36: Shorts | O36: 0 | P36: 2 | Q36: 1 | R36: 1 | S36: 14000 | T36: 14000 | U36: 4957 | V36: 4957 | W36: 0
A37: 130 | B37: FJALLRAVEN STORE 名古屋ファッションワン | C37: 12200219550M | D37: Vardag Summer Shorts M | E37: 310002 | F37: Fenix APD | G37: FRV | H37: FJALLRAVEN | I37: Apparel | J37: Apparel | K37: Bottoms | L37: Bottoms | M37: Shorts | N37: Shorts | O37: 0 | P37: 2 | Q37: 1 | R37: 1 | S37: 14000 | T37: 14000 | U37: 4957 | V37: 4957 | W37: 0
A38: 130 | B38: FJALLRAVEN STORE 名古屋ファッションワン | C38: 12200219550S | D38: Vardag Summer Shorts M | E38: 310002 | F38: Fenix APD | G38: FRV | H38: FJALLRAVEN | I38: Apparel | J38: Apparel | K38: Bottoms | L38: Bottoms | M38: Shorts | N38: Shorts | O38: 0 | P38: 2 | Q38: 1 | R38: 1 | S38: 14000 | T38: 14000 | U38: 4957 | V38: 4957 | W38: 0
A39: 130 | B39: FJALLRAVEN STORE 名古屋ファッションワン | C39: 12200219625M | D39: Vardag Summer Shorts M | E39: 310002 | F39: Fenix APD | G39: FRV | H39: FJALLRAVEN | I39: Apparel | J39: Apparel | K39: Bottoms | L39: Bottoms | M39: Shorts | N39: Shorts | O39: 0 | P39: 2 | Q39: 1 | R39: 1 | S39: 14000 | T39: 14000 | U39: 4957 | V39: 4957 | W39: 0
A40: 130 | B40: FJALLRAVEN STORE 名古屋ファッションワン | C40: 12200219625S | D40: Vardag Summer Shorts M | E40: 310002 | F40: Fenix APD | G40: FRV | H40: FJALLRAVEN | I40: Apparel | J40: Apparel | K40: Bottoms | L40: Bottoms | M40: Shorts | N40: Shorts | O40: 0 | P40: 2 | Q40: 1 | R40: 1 | S40: 14000 | T40: 14000 | U40: 4957 | V40: 4957 | W40: 0
...

Sheet 全店特価
A1: 拠点コード | B1: 拠点名 | C1: 商品コード | D1: 商品名 | E1: Brand | F1: BrandName | G1: 分類２名 | H1: 繰越数量 | I1: 受入数量 | J1: 払出数量 | K1: 現在数量 | L1: 特価フラグ
A2: 130 | B2: FJALLRAVEN STORE 名古屋ファッションワン | C2: 23795319X | D2: Kanken Rain Cover Mini | E2: FRV | F2: FJALLRAVEN | G2: Kanken | H2: 0 | I2: 8 | J2: 6 | K2: 2 | L2: 1
A3: 130 | B3: FJALLRAVEN STORE 名古屋ファッションワン | C3: 23795525X | D3: Kanken Rain Cover Mini | E3: FRV | F3: FJALLRAVEN | G3: Kanken | H3: 0 | I3: 7 | J3: 5 | K3: 2 | L3: 1
A4: 130 | B4: FJALLRAVEN STORE 名古屋ファッションワン | C4: 24401991X | D4: Packbags | E4: FRV | F4: FJALLRAVEN | G4: Accessories | H4: 0 | I4: 16 | J4: 14 | K4: 2 | L4: 1
A5: 130 | B5: FJALLRAVEN STORE 名古屋ファッションワン | C5: 81761030-03044 | D5: Barents Pro Trousers | E5: FRV | F5: FJALLRAVEN | G5: Bottoms | H5: 0 | I5: 1 | J5: 0 | K5: 1 | L5: 1
A6: 130 | B6: FJALLRAVEN STORE 名古屋ファッションワン | C6: 81761550-55044 | D6: Barents Pro Trousers | E6: FRV | F6: FJALLRAVEN | G6: Bottoms | H6: 0 | I6: 5 | J6: 4 | K6: 1 | L6: 1
A7: 130 | B7: FJALLRAVEN STORE 名古屋ファッションワン | C7: 81761550-55046 | D7: Barents Pro Trousers | E7: FRV | F7: FJALLRAVEN | G7: Bottoms | H7: 0 | I7: 6 | J7: 5 | K7: 1 | L7: 1
A8: 130 | B8: FJALLRAVEN STORE 名古屋ファッションワン | C8: 81761620-03048 | D8: Barents Pro Trousers | E8: FRV | F8: FJALLRAVEN | G8: Bottoms | H8: 0 | I8: 1 | J8: 0 | K8: 1 | L8: 1
A9: 130 | B9: FJALLRAVEN STORE 名古屋ファッションワン | C9: 81761633-63344 | D9: Barents Pro Trousers | E9: FRV | F9: FJALLRAVEN | G9: Bottoms | H9: 0 | I9: 8 | J9: 7 | K9: 1 | L9: 1
A10: 130 | B10: FJALLRAVEN STORE 名古屋ファッションワン | C10: 81900662M | D10: Singi Merino Henley M | E10: FRV | F10: FJALLRAVEN | G10: Inners | H10: 0 | I10: 1 | J10: 0 | K10: 1 | L10: 1
A11: 130 | B11: FJALLRAVEN STORE 名古屋ファッションワン | C11: 81900662S | D11: Singi Merino Henley M | E11: FRV | F11: FJALLRAVEN | G11: Inners | H11: 0 | I11: 3 | J11: 2 | K11: 1 | L11: 1
A12: 130 | B12: FJALLRAVEN STORE 名古屋ファッションワン | C12: 84100208M | D12: Bergtagen Thinwool SS W | E12: FRV | F12: FJALLRAVEN | G12: Inners | H12: 0 | I12: 4 | J12: 3 | K12: 1 | L12: 1
A13: 130 | B13: FJALLRAVEN STORE 名古屋ファッションワン | C13: 84100208S | D13: Bergtagen Thinwool SS W | E13: FRV | F13: FJALLRAVEN | G13: Inners | H13: 0 | I13: 4 | J13: 3 | K13: 1 | L13: 1
... A47: 150 | B47: FJALLRAVEN by 3NITY TOKYO | C47: 90170626-625S | D47: Lappland Hybrid Jacket M | E47: FRV | F47: FJALLRAVEN | G47: Outers | H47: 0 | I47: 8 | J47: 7 | K47: 1 | L47: 1
A48: 150 | B48: FJALLRAVEN by 3NITY TOKYO | C48: 9022863346 | D48: Barents Pro Hydratic Trs M | E48: FRV | F48: FJALLRAVEN | G48: Bottoms | H48: 0 | I48: 5 | J48: 4 | K48: 1 | L48: 1
A49: 150 | B49: FJALLRAVEN by 3NITY TOKYO | C49: 9070263336 | D49: Sormland Tapered Winter Trs W | E49: FRV | F49: FJALLRAVEN | G49: Bottoms | H49: 0 | I49: 5 | J49: 4 | K49: 1 | L49: 1
A50: 150 | B50: FJALLRAVEN by 3NITY TOKYO | C50: 9070263338 | D50: Sormland Tapered Winter Trs W | E50: FRV | F50: FJALLRAVEN | G50: Bottoms | H50: 0 | I50: 6 | J50: 5 | K50: 1 | L50: 1
A51: 160 | B51: FJALLRAVEN by 3NITY ルクア大阪 | C51: 23795319X | D51: Kanken Rain Cover Mini | E51: FRV | F51: FJALLRAVEN | G51: Kanken | H51: 0 | I51: 7 | J51: 5 | K51: 2 | L51: 1
A52: 160 | B52: FJALLRAVEN by 3NITY ルクア大阪 | C52: 23795525X | D52: Kanken Rain Cover Mini | E52: FRV | F52: FJALLRAVEN | G52: Kanken | H52: 0 | I52: 5 | J52: 3 | K52: 2 | L52: 1
A53: 160 | B53: FJALLRAVEN by 3NITY ルクア大阪 | C53: 24401991X | D53: Packbags | E53: FRV | F53: FJALLRAVEN | G53: Accessories | H53: 0 | I53: 14 | J53: 12 | K53: 2 | L53: 1
A54: 160 | B54: FJALLRAVEN by 3NITY ルクア大阪 | C54: 81761550-55044 | D54: Barents Pro Trousers | E54: FRV | F54: FJALLRAVEN | G54: Bottoms | H54: 0 | I54: 3 | J54: 2 | K54: 1 | L54: 1
A55: 160 | B55: FJALLRAVEN by 3NITY ルクア大阪 | C55: 81761550-55046 | D55: Barents Pro Trousers | E55: FRV | F55: FJALLRAVEN | G55: Bottoms | H55: 0 | I55: 6 | J55: 5 | K55: 1 | L55: 1
A56: 160 | B56: FJALLRAVEN by 3NITY ルクア大阪 | C56: 81761633-63344 | D56: Barents Pro Trousers | E56: FRV | F56: FJALLRAVEN | G56: Bottoms | H56: 0 | I56: 2 | J56: 1 | K56: 1 | L56: 1
A57: 160 | B57: FJALLRAVEN by 3NITY ルクア大阪 | C57: 83775550XS | D57: Abisko Padded Vest | E57: FRV | F57: FJALLRAVEN | G57: Outers | H57: 0 | I57: 2 | J57: 1 | K57: 1 | L57: 1
A58: 160 | B58: FJALLRAVEN by 3NITY ルクア大阪 | C58: 84100208M | D58: Bergtagen Thinwool SS W | E58: FRV | F58: FJALLRAVEN | G58: Inners | H58: 0 | I58: 1 | J58: 0 | K58: 1 | L58: 1
A59: 160 | B59: FJALLRAVEN by 3NITY ルクア大阪 | C59: 84100208S | D59: Bergtagen Thinwool SS W | E59: FRV | F59: FJALLRAVEN | G59: Inners | H59: 0 | I59: 1 | J59: 0 | K59: 1 | L59: 1
A60: 160 | B60: FJALLRAVEN by 3NITY ルクア大阪 | C60: 84100570S | D60: Bergtagen Thinwool SS W | E60: FRV | F60: FJALLRAVEN | G60: Inners | H60: 0 | I60: 1 | J60: 0 | K60: 1 | L60: 1
A61: 160 | B61: FJALLRAVEN by 3NITY ルクア大阪 | C61: 84784981-982X | D61: Campfire Bandana | E61: FRV | F61: FJALLRAVEN | G61: Accessories | H61: 0 | I61: 5 | J61: 2 | K61: 3 | L61: 1
A62: 160 | B62: FJALLRAVEN by 3NITY ルクア大阪 | C62: 84784987-986X | D62: Campfire Bandana | E62: FRV | F62: FJALLRAVEN | G62: Accessories | H62: 0 | I62: 5 | J62: 1 | K62: 4 | L62: 1
... A194: 250 | B194: FJALLRAVEN by 3NITY | C194: 89738575XS | D194: Greenland Winter Parka W | E194: FRV | F194: FJALLRAVEN | G194: Outers | H194: 0 | I194: 13 | J194: 12 | K194: 1 | L194: 1
A195: 250 | B195: FJALLRAVEN by 3NITY | C195: 8980955036 | D195: Karla Pro Winter Trousers W | E195: FRV | F195: FJALLRAVEN | G195: Bottoms | H195: 0 | I195: 16 | J195: 15 | K195: 1 | L195: 1
A196: 250 | B196: FJALLRAVEN by 3NITY | C196: 8980955038 | D196: Karla Pro Winter Trousers W | E196: FRV | F196: FJALLRAVEN | G196: Bottoms | H196: 0 | I196: 14 | J196: 13 | K196: 1 | L196: 1
A197: 250 | B197: FJALLRAVEN by 3NITY | C197: 8980963338 | D197: Karla Pro Winter Trousers W | E197: FRV | F197: FJALLRAVEN | G197: Bottoms | H197: 0 | I197: 13 | J197: 12 | K197: 1 | L197: 1
A198: 250 | B198: FJALLRAVEN by 3NITY | C198: 89827S55036 | D198: Abisko Midsummer Trs W Short | E198: FRV | F198: FJALLRAVEN | G198: Bottoms | H198: 0 | I198: 10 | J198: 9 | K198: 1 | L198: 1
A199: 250 | B199: FJALLRAVEN by 3NITY | C199: 89827S562-56334 | D199: Abisko Midsummer Trs W Short | E199: FRV | F199: FJALLRAVEN | G199: Bottoms | H199: 0 | I199: 9 | J199: 8 | K199: 1 | L199: 1
A200: 250 | B200: FJALLRAVEN by 3NITY | C200: 89827S562-56338 | D200: Abisko Midsummer Trs W Short | E200: FRV | F200: FJALLRAVEN | G200: Bottoms | H200: 0 | I200: 10 | J200: 9 | K200: 1 | L200: 1
A201: 250 | B201: FJALLRAVEN by 3NITY | C201: 89829160-04636 | D201: Kaipak Trousers Curved W | E201: FRV | F201: FJALLRAVEN | G201: Bottoms | H201: 0 | I201: 8 | J201: 7 | K201: 1 | L201: 1
A202: 250 | B202: FJALLRAVEN by 3NITY | C202: 89829160-04638 | D202: Kaipak Trousers Curved W | E202: FRV | F202: FJALLRAVEN | G202: Bottoms | H202: 0 | I202: 8 | J202: 7 | K202: 1 | L202: 1
A203: 250 | B203: FJALLRAVEN by 3NITY | C203: 89829356-03038 | D203: Kaipak Trousers Curved W | E203: FRV | F203: FJALLRAVEN | G203: Bottoms | H203: 0 | I203: 8 | J203: 7 | K203: 1 | L203: 1
A204: 250 | B204: FJALLRAVEN by 3NITY | C204: 89843516M | D204: Ovik Travel Shirt LS W | E204: FRV | F204: FJALLRAVEN | G204: Middlers | H204: 0 | I204: 13 | J204: 12 | K204: 1 | L204: 1
...

Sheet 2026特価在庫
A1: 拠点コード | B1: 店舗名 | C1: 総数量
A2: 130 | B2: 名古屋 | C2: =SUMIF(全店特価!A:A,'2026特価在庫'!A:A,全店特価!K:K) -> 29
A3: 150 | B3: 東京 | C3: =SUMIF(全店特価!A:A,'2026特価在庫'!A:A,全店特価!K:K) -> 33
A4: 160 | B4: ルクア | C4: =SUMIF(全店特価!A:A,'2026特価在庫'!A:A,全店特価!K:K) -> 28
A5: 180 | B5: HUTTE | C5: =SUMIF(全店特価!A:A,'2026特価在庫'!A:A,全店特価!K:K) -> 24
A6: 300 | B6: 京王 | C6: =SUMIF(全店特価!A:A,'2026特価在庫'!A:A,全店特価!K:K) -> 9
A7: 320 | B7: 玉川 | C7: =SUMIF(全店特価!A:A,'2026特価在庫'!A:A,全店特価!K:K) -> 8
A8: 340 | B8: 心斎橋 | C8: =SUMIF(全店特価!A:A,'2026特価在庫'!A:A,全店特価!K:K) -> 15
A9: 330 | B9: NODE | C9: =SUMIF(全店特価!A:A,'2026特価在庫'!A:A,全店特価!K:K) -> 14
A10: 250 | B10: EC | C10: =SUMIF(全店特価!A:A,'2026特価在庫'!A:A,全店特価!K:K) -> 151
A11: 220 | B11: ZOZO | C11: =SUMIF(全店特価!A:A,'2026特価在庫'!A:A,全店特価!K:K) -> 10
A12: 240 | B12: OIOI | C12: =SUMIF(全店特価!A:A,'2026特価在庫'!A:A,全店特価!K:K) -> 1
A13: RPP2 | B13: 6142 | C13: =SUMIF(全店特価!A:A,'2026特価在庫'!A:A,全店特価!K:K) -> 35
A14: 全店総数 | C14: =SUM(C2:C13) -> 357

Sheet 名古屋
K1: =SUBTOTAL(9,K3:K25) -> 29
A2: 拠点コード | B2: 拠点名 | C2: 商品コード | D2: 商品名 | E2: Brand | F2: BrandName | G2: 分類２名 | H2: 繰越数量 | I2: 受入数量 | J2: 払出数量 | K2: 現在数量
A3: 130 | B3: FJALLRAVEN STORE 名古屋ファッションワン | C3: 23795319X | D3: Kanken Rain Cover Mini | E3: FRV | F3: FJALLRAVEN | G3: Kanken | H3: 0 | I3: 8 | J3: 6 | K3: 2
A4: 130 | B4: FJALLRAVEN STORE 名古屋ファッションワン | C4: 23795525X | D4: Kanken Rain Cover Mini | E4: FRV | F4: FJALLRAVEN | G4: Kanken | H4: 0 | I4: 7 | J4: 5 | K4: 2
A5: 130 | B5: FJALLRAVEN STORE 名古屋ファッションワン | C5: 24401991X | D5: Packbags | E5: FRV | F5: FJALLRAVEN | G5: Accessories | H5: 0 | I5: 16 | J5: 14 | K5: 2
A6: 130 | B6: FJALLRAVEN STORE 名古屋ファッションワン | C6: 81761030-03044 | D6: Barents Pro Trousers | E6: FRV | F6: FJALLRAVEN | G6: Bottoms | H6: 0 | I6: 1 | J6: 0 | K6: 1
A7: 130 | B7: FJALLRAVEN STORE 名古屋ファッションワン | C7: 81761550-55044 | D7: Barents Pro Trousers | E7: FRV | F7: FJALLRAVEN | G7: Bottoms | H7: 0 | I7: 5 | J7: 4 | K7: 1
A8: 130 | B8: FJALLRAVEN STORE 名古屋ファッションワン | C8: 81761550-55046 | D8: Barents Pro Trousers | E8: FRV | F8: FJALLRAVEN | G8: Bottoms | H8: 0 | I8: 6 | J8: 5 | K8: 1
A9: 130 | B9: FJALLRAVEN STORE 名古屋ファッションワン | C9: 81761620-03048 | D9: Barents Pro Trousers | E9: FRV | F9: FJALLRAVEN | G9: Bottoms | H9: 0 | I9: 1 | J9: 0 | K9: 1
A10: 130 | B10: FJALLRAVEN STORE 名古屋ファッションワン | C10: 81761633-63344 | D10: Barents Pro Trousers | E10: FRV | F10: FJALLRAVEN | G10: Bottoms | H10: 0 | I10: 8 | J10: 7 | K10: 1
A11: 130 | B11: FJALLRAVEN STORE 名古屋ファッションワン | C11: 81900662M | D11: Singi Merino Henley M | E11: FRV | F11: FJALLRAVEN | G11: Inners | H11: 0 | I11: 1 | J11: 0 | K11: 1
A12: 130 | B12: FJALLRAVEN STORE 名古屋ファッションワン | C12: 81900662S | D12: Singi Merino Henley M | E12: FRV | F12: FJALLRAVEN | G12: Inners | H12: 0 | I12: 3 | J12: 2 | K12: 1
A13: 130 | B13: FJALLRAVEN STORE 名古屋ファッションワン | C13: 84100208M | D13: Bergtagen Thinwool SS W | E13: FRV | F13: FJALLRAVEN | G13: Inners | H13: 0 | I13: 4 | J13: 3 | K13: 1
A14: 130 | B14: FJALLRAVEN STORE 名古屋ファッションワン | C14: 84100208S | D14: Bergtagen Thinwool SS W | E14: FRV | F14: FJALLRAVEN | G14: Inners | H14: 0 | I14: 4 | J14: 3 | K14: 1
... A25: 130 | B25: FJALLRAVEN STORE 名古屋ファッションワン | C25: 90170626-625S | D25: Lappland Hybrid Jacket M | E25: FRV | F25: FJALLRAVEN | G25: Outers | H25: 0 | I25: 6 | J25: 5 | K25: 1

Sheet 東京
K1: =SUBTOTAL(9,K3:K28) -> 33
A2: 拠点コード | B2: 拠点名 | C2: 商品コード | D2: 商品名 | E2: Brand | F2: BrandName | G2: 分類２名 | H2: 繰越数量 | I2: 受入数量 | J2: 払出数量 | K2: 現在数量
A3: 150 | B3: FJALLRAVEN by 3NITY TOKYO | C3: 23795319X | D3: Kanken Rain Cover Mini | E3: FRV | F3: FJALLRAVEN | G3: Kanken | H3: 0 | I3: 19 | J3: 17 | K3: 2
A4: 150 | B4: FJALLRAVEN by 3NITY TOKYO | C4: 23795525X | D4: Kanken Rain Cover Mini | E4: FRV | F4: FJALLRAVEN | G4: Kanken | H4: 0 | I4: 16 | J4: 14 | K4: 2
A5: 150 | B5: FJALLRAVEN by 3NITY TOKYO | C5: 24401991X | D5: Packbags | E5: FRV | F5: FJALLRAVEN | G5: Accessories | H5: 0 | I5: 14 | J5: 11 | K5: 3
A6: 150 | B6: FJALLRAVEN by 3NITY TOKYO | C6: 81761550-55044 | D6: Barents Pro Trousers | E6: FRV | F6: FJALLRAVEN | G6: Bottoms | H6: 0 | I6: 6 | J6: 5 | K6: 1
A7: 150 | B7: FJALLRAVEN by 3NITY TOKYO | C7: 81761550-55046 | D7: Barents Pro Trousers | E7: FRV | F7: FJALLRAVEN | G7: Bottoms | H7: 0 | I7: 7 | J7: 6 | K7: 1
A8: 150 | B8: FJALLRAVEN by 3NITY TOKYO | C8: 81761620-03046 | D8: Barents Pro Trousers | E8: FRV | F8: FJALLRAVEN | G8: Bottoms | H8: 0 | I8: 4 | J8: 3 | K8: 1
A9: 150 | B9: FJALLRAVEN by 3NITY TOKYO | C9: 81761633-63344 | D9: Barents Pro Trousers | E9: FRV | F9: FJALLRAVEN | G9: Bottoms | H9: 0 | I9: 10 | J9: 9 | K9: 1
A10: 150 | B10: FJALLRAVEN by 3NITY TOKYO | C10: 84100208M | D10: Bergtagen Thinwool SS W | E10: FRV | F10: FJALLRAVEN | G10: Inners | H10: 0 | I10: 2 | J10: 1 | K10: 1
A11: 150 | B11: FJALLRAVEN by 3NITY TOKYO | C11: 84100208S | D11: Bergtagen Thinwool SS W | E11: FRV | F11: FJALLRAVEN | G11: Inners | H11: 0 | I11: 3 | J11: 2 | K11: 1
A12: 150 | B12: FJALLRAVEN by 3NITY TOKYO | C12: 84100570S | D12: Bergtagen Thinwool SS W | E12: FRV | F12: FJALLRAVEN | G12: Inners | H12: 0 | I12: 4 | J12: 3 | K12: 1
A13: 150 | B13: FJALLRAVEN by 3NITY TOKYO | C13: 84784981-982X | D13: Campfire Bandana | E13: FRV | F13: FJALLRAVEN | G13: Accessories | H13: 0 | I13: 14 | J13: 12 | K13: 2
A14: 150 | B14: FJALLRAVEN by 3NITY TOKYO | C14: 84784987-986X | D14: Campfire Bandana | E14: FRV | F14: FJALLRAVEN | G14: Accessories | H14: 0 | I14: 12 | J14: 9 | K14: 3
... A25: 150 | B25: FJALLRAVEN by 3NITY TOKYO | C25: 90170626-625S | D25: Lappland Hybrid Jacket M | E25: FRV | F25: FJALLRAVEN | G25: Outers | H25: 0 | I25: 8 | J25: 7 | K25: 1
A26: 150 | B26: FJALLRAVEN by 3NITY TOKYO | C26: 9022863346 | D26: Barents Pro Hydratic Trs M | E26: FRV | F26: FJALLRAVEN | G26: Bottoms | H26: 0 | I26: 5 | J26: 4 | K26: 1
A27: 150 | B27: FJALLRAVEN by 3NITY TOKYO | C27: 9070263336 | D27: Sormland Tapered Winter Trs W | E27: FRV | F27: FJALLRAVEN | G27: Bottoms | H27: 0 | I27: 5 | J27: 4 | K27: 1
A28: 150 | B28: FJALLRAVEN by 3NITY TOKYO | C28: 9070263338 | D28: Sormland Tapered Winter Trs W | E28: FRV | F28: FJALLRAVEN | G28: Bottoms | H28: 0 | I28: 6 | J28: 5 | K28: 1

Sheet 大阪ルクア
K1: =SUBTOTAL(9,K3:K21) -> 28
A2: 拠点コード | B2: 拠点名 | C2: 商品コード | D2: 商品名 | E2: Brand | F2: BrandName | G2: 分類２名 | H2: 繰越数量 | I2: 受入数量 | J2: 払出数量 | K2: 現在数量
A3: 160 | B3: FJALLRAVEN by 3NITY ルクア大阪 | C3: 23795319X | D3: Kanken Rain Cover Mini | E3: FRV | F3: FJALLRAVEN | G3: Kanken | H3: 0 | I3: 7 | J3: 5 | K3: 2
A4: 160 | B4: FJALLRAVEN by 3NITY ルクア大阪 | C4: 23795525X | D4: Kanken Rain Cover Mini | E4: FRV | F4: FJALLRAVEN | G4: Kanken | H4: 0 | I4: 5 | J4: 3 | K4: 2
A5: 160 | B5: FJALLRAVEN by 3NITY ルクア大阪 | C5: 24401991X | D5: Packbags | E5: FRV | F5: FJALLRAVEN | G5: Accessories | H5: 0 | I5: 14 | J5: 12 | K5: 2
A6: 160 | B6: FJALLRAVEN by 3NITY ルクア大阪 | C6: 81761550-55044 | D6: Barents Pro Trousers | E6: FRV | F6: FJALLRAVEN | G6: Bottoms | H6: 0 | I6: 3 | J6: 2 | K6: 1
A7: 160 | B7: FJALLRAVEN by 3NITY ルクア大阪 | C7: 81761550-55046 | D7: Barents Pro Trousers | E7: FRV | F7: FJALLRAVEN | G7: Bottoms | H7: 0 | I7: 6 | J7: 5 | K7: 1
A8: 160 | B8: FJALLRAVEN by 3NITY ルクア大阪 | C8: 81761633-63344 | D8: Barents Pro Trousers | E8: FRV | F8: FJALLRAVEN | G8: Bottoms | H8: 0 | I8: 2 | J8: 1 | K8: 1
A9: 160 | B9: FJALLRAVEN by 3NITY ルクア大阪 | C9: 83775550XS | D9: Abisko Padded Vest | E9: FRV | F9: FJALLRAVEN | G9: Outers | H9: 0 | I9: 2 | J9: 1 | K9: 1
A10: 160 | B10: FJALLRAVEN by 3NITY ルクア大阪 | C10: 84100208M | D10: Bergtagen Thinwool SS W | E10: FRV | F10: FJALLRAVEN | G10: Inners | H10: 0 | I10: 1 | J10: 0 | K10: 1
A11: 160 | B11: FJALLRAVEN by 3NITY ルクア大阪 | C11: 84100208S | D11: Bergtagen Thinwool SS W | E11: FRV | F11: FJALLRAVEN | G11: Inners | H11: 0 | I11: 1 | J11: 0 | K11: 1
A12: 160 | B12: FJALLRAVEN by 3NITY ルクア大阪 | C12: 84100570S | D12: Bergtagen Thinwool SS W | E12: FRV | F12: FJALLRAVEN | G12: Inners | H12: 0 | I12: 1 | J12: 0 | K12: 1
A13: 160 | B13: FJALLRAVEN by 3NITY ルクア大阪 | C13: 84784981-982X | D13: Campfire Bandana | E13: FRV | F13: FJALLRAVEN | G13: Accessories | H13: 0 | I13: 5 | J13: 2 | K13: 3
A14: 160 | B14: FJALLRAVEN by 3NITY ルクア大阪 | C14: 84784987-986X | D14: Campfire Bandana | E14: FRV | F14: FJALLRAVEN | G14: Accessories | H14: 0 | I14: 5 | J14: 1 | K14: 4
... A21: 160 | B21: FJALLRAVEN by 3NITY ルクア大阪 | C21: 89886570S | D21: Bergtagen Thinwool LS W | E21: FRV | F21: FJALLRAVEN | G21: Inners | H21: 0 | I21: 1 | J21: 0 | K21: 1

Sheet HUTTE
K1: =SUBTOTAL(9,K3:K16) -> 24
A2: 拠点コード | B2: 拠点名 | C2: 商品コード | D2: 商品名 | E2: Brand | F2: BrandName | G2: 分類２名 | H2: 繰越数量 | I2: 受入数量 | J2: 払出数量 | K2: 現在数量
A3: 180 | B3: FJALLRAVEN by 3NITY SAPPORO HUTTE | C3: 23561539X | D3: Kanken Mini | E3: FRV | F3: FJALLRAVEN | G3: Kanken | H3: 0 | I3: 14 | J3: 4 | K3: 10
A4: 180 | B4: FJALLRAVEN by 3NITY SAPPORO HUTTE | C4: 23795319X | D4: Kanken Rain Cover Mini | E4: FRV | F4: FJALLRAVEN | G4: Kanken | H4: 0 | I4: 3 | J4: 2 | K4: 1
A5: 180 | B5: FJALLRAVEN by 3NITY SAPPORO HUTTE | C5: 23795525X | D5: Kanken Rain Cover Mini | E5: FRV | F5: FJALLRAVEN | G5: Kanken | H5: 0 | I5: 1 | J5: 0 | K5: 1
A6: 180 | B6: FJALLRAVEN by 3NITY SAPPORO HUTTE | C6: 77363249X | D6: Leather Passport Cover | E6: FRV | F6: FJALLRAVEN | G6: Accessories | H6: 0 | I6: 2 | J6: 0 | K6: 2
A7: 180 | B7: FJALLRAVEN by 3NITY SAPPORO HUTTE | C7: 77398249X | D7: Ovik Card Holder Large | E7: FRV | F7: FJALLRAVEN | G7: Accessories | H7: 0 | I7: 2 | J7: 1 | K7: 1
A8: 180 | B8: FJALLRAVEN by 3NITY SAPPORO HUTTE | C8: 84100208M | D8: Bergtagen Thinwool SS W | E8: FRV | F8: FJALLRAVEN | G8: Inners | H8: 0 | I8: 1 | J8: 0 | K8: 1
A9: 180 | B9: FJALLRAVEN by 3NITY SAPPORO HUTTE | C9: 84100208XS | D9: Bergtagen Thinwool SS W | E9: FRV | F9: FJALLRAVEN | G9: Inners | H9: 0 | I9: 1 | J9: 0 | K9: 1
A10: 180 | B10: FJALLRAVEN by 3NITY SAPPORO HUTTE | C10: 84100570S | D10: Bergtagen Thinwool SS W | E10: FRV | F10: FJALLRAVEN | G10: Inners | H10: 0 | I10: 5 | J10: 4 | K10: 1
A11: 180 | B11: FJALLRAVEN by 3NITY SAPPORO HUTTE | C11: 84784981-982X | D11: Campfire Bandana | E11: FRV | F11: FJALLRAVEN | G11: Accessories | H11: 0 | I11: 3 | J11: 2 | K11: 1
A12: 180 | B12: FJALLRAVEN by 3NITY SAPPORO HUTTE | C12: 8622463346/30 | D12: Vidda Pro Ventilated Trs M Short | E12: FRV | F12: FJALLRAVEN | G12: Bottoms | H12: 0 | I12: 1 | J12: 0 | K12: 1
A13: 180 | B13: FJALLRAVEN by 3NITY SAPPORO HUTTE | C13: 87192208M | D13: Bergtagen Thinwool SS M | E13: FRV | F13: FJALLRAVEN | G13: Inners | H13: 0 | I13: 1 | J13: 0 | K13: 1
A14: 180 | B14: FJALLRAVEN by 3NITY SAPPORO HUTTE | C14: 87192208S | D14: Bergtagen Thinwool SS M | E14: FRV | F14: FJALLRAVEN | G14: Inners | H14: 0 | I14: 3 | J14: 2 | K14: 1
... A16: 180 | B16: FJALLRAVEN by 3NITY SAPPORO HUTTE | C16: 90170626-625S | D16: Lappland Hybrid Jacket M | E16: FRV | F16: FJALLRAVEN | G16: Outers | H16: 0 | I16: 8 | J16: 7 | K16: 1

Sheet 京王
K1: =SUBTOTAL(9,K3:K6) -> 9
A2: 拠点コード | B2: 拠点名 | C2: 商品コード | D2: 商品名 | E2: Brand | F2: BrandName | G2: 分類２名 | H2: 繰越数量 | I2: 受入数量 | J2: 払出数量 | K2: 現在数量
A3: 300 | B3: FJALLRAVEN by 3NITY 京王新宿 | C3: 23795319X | D3: Kanken Rain Cover Mini | E3: FRV | F3: FJALLRAVEN | G3: Kanken | H3: 0 | I3: 1 | J3: 0 | K3: 1
A4: 300 | B4: FJALLRAVEN by 3NITY 京王新宿 | C4: 23795525X | D4: Kanken Rain Cover Mini | E4: FRV | F4: FJALLRAVEN | G4: Kanken | H4: 0 | I4: 1 | J4: 0 | K4: 1
A5: 300 | B5: FJALLRAVEN by 3NITY 京王新宿 | C5: 84784981-982X | D5: Campfire Bandana | E5: FRV | F5: FJALLRAVEN | G5: Accessories | H5: 0 | I5: 4 | J5: 0 | K5: 4
A6: 300 | B6: FJALLRAVEN by 3NITY 京王新宿 | C6: 84784987-986X | D6: Campfire Bandana | E6: FRV | F6: FJALLRAVEN | G6: Accessories | H6: 0 | I6: 6 | J6: 3 | K6: 3

Sheet 玉川
K1: =SUBTOTAL(9,K3:K9) -> 8
A2: 拠点コード | B2: 拠点名 | C2: 商品コード | D2: 商品名 | E2: Brand | F2: BrandName | G2: 分類２名 | H2: 繰越数量 | I2: 受入数量 | J2: 払出数量 | K2: 現在数量
A3: 320 | B3: FJALLRAVEN by 3NITY玉川高島屋S・C | C3: 81761550-55044 | D3: Barents Pro Trousers | E3: FRV | F3: FJALLRAVEN | G3: Bottoms | H3: 0 | I3: 1 | J3: 0 | K3: 1
A4: 320 | B4: FJALLRAVEN by 3NITY玉川高島屋S・C | C4: 81761550-55046 | D4: Barents Pro Trousers | E4: FRV | F4: FJALLRAVEN | G4: Bottoms | H4: 0 | I4: 1 | J4: 0 | K4: 1
A5: 320 | B5: FJALLRAVEN by 3NITY玉川高島屋S・C | C5: 81761633-63344 | D5: Barents Pro Trousers | E5: FRV | F5: FJALLRAVEN | G5: Bottoms | H5: 0 | I5: 2 | J5: 1 | K5: 1
A6: 320 | B6: FJALLRAVEN by 3NITY玉川高島屋S・C | C6: 84784981-982X | D6: Campfire Bandana | E6: FRV | F6: FJALLRAVEN | G6: Accessories | H6: 0 | I6: 2 | J6: 0 | K6: 2
A7: 320 | B7: FJALLRAVEN by 3NITY玉川高島屋S・C | C7: 84784987-986X | D7: Campfire Bandana | E7: FRV | F7: FJALLRAVEN | G7: Accessories | H7: 0 | I7: 2 | J7: 1 | K7: 1
A8: 320 | B8: FJALLRAVEN by 3NITY玉川高島屋S・C | C8: 89827S55036 | D8: Abisko Midsummer Trs W Short | E8: FRV | F8: FJALLRAVEN | G8: Bottoms | H8: 0 | I8: 1 | J8: 0 | K8: 1
A9: 320 | B9: FJALLRAVEN by 3NITY玉川高島屋S・C | C9: 89827S55038 | D9: Abisko Midsummer Trs W Short | E9: FRV | F9: FJALLRAVEN | G9: Bottoms | H9: 0 | I9: 2 | J9: 1 | K9: 1

Sheet 心斎橋
K1: =SUBTOTAL(9,K3:K14) -> 15
A2: 拠点コード | B2: 拠点名 | C2: 商品コード | D2: 商品名 | E2: Brand | F2: BrandName | G2: 分類２名 | H2: 繰越数量 | I2: 受入数量 | J2: 払出数量 | K2: 現在数量
A3: 340 | B3: FJALLRAVEN by 3NITY 大丸心斎橋 | C3: 23795319X | D3: Kanken Rain Cover Mini | E3: FRV | F3: FJALLRAVEN | G3: Kanken | H3: 0 | I3: 1 | J3: 0 | K3: 1
A4: 340 | B4: FJALLRAVEN by 3NITY 大丸心斎橋 | C4: 23795525X | D4: Kanken Rain Cover Mini | E4: FRV | F4: FJALLRAVEN | G4: Kanken | H4: 0 | I4: 2 | J4: 0 | K4: 2
A5: 340 | B5: FJALLRAVEN by 3NITY 大丸心斎橋 | C5: 24401991X | D5: Packbags | E5: FRV | F5: FJALLRAVEN | G5: Accessories | H5: 0 | I5: 2 | J5: 0 | K5: 2
A6: 340 | B6: FJALLRAVEN by 3NITY 大丸心斎橋 | C6: 81761550-55044 | D6: Barents Pro Trousers | E6: FRV | F6: FJALLRAVEN | G6: Bottoms | H6: 0 | I6: 2 | J6: 1 | K6: 1
A7: 340 | B7: FJALLRAVEN by 3NITY 大丸心斎橋 | C7: 81761550-55046 | D7: Barents Pro Trousers | E7: FRV | F7: FJALLRAVEN | G7: Bottoms | H7: 0 | I7: 1 | J7: 0 | K7: 1
A8: 340 | B8: FJALLRAVEN by 3NITY 大丸心斎橋 | C8: 81761633-63344 | D8: Barents Pro Trousers | E8: FRV | F8: FJALLRAVEN | G8: Bottoms | H8: 0 | I8: 1 | J8: 0 | K8: 1
A9: 340 | B9: FJALLRAVEN by 3NITY 大丸心斎橋 | C9: 84122555S | D9: Karla Hydratic Jacket W | E9: FRV | F9: FJALLRAVEN | G9: Outers | H9: 0 | I9: 1 | J9: 0 | K9: 1
A10: 340 | B10: FJALLRAVEN by 3NITY 大丸心斎橋 | C10: 84122662S | D10: Karla Hydratic Jacket W | E10: FRV | F10: FJALLRAVEN | G10: Outers | H10: 0 | I10: 1 | J10: 0 | K10: 1
A11: 340 | B11: FJALLRAVEN by 3NITY 大丸心斎橋 | C11: 84122662XS | D11: Karla Hydratic Jacket W | E11: FRV | F11: FJALLRAVEN | G11: Outers | H11: 0 | I11: 1 | J11: 0 | K11: 1
A12: 340 | B12: FJALLRAVEN by 3NITY 大丸心斎橋 | C12: 84784981-982X | D12: Campfire Bandana | E12: FRV | F12: FJALLRAVEN | G12: Accessories | H12: 0 | I12: 1 | J12: 0 | K12: 1
A13: 340 | B13: FJALLRAVEN by 3NITY 大丸心斎橋 | C13: 84784987-986X | D13: Campfire Bandana | E13: FRV | F13: FJALLRAVEN | G13: Accessories | H13: 0 | I13: 2 | J13: 0 | K13: 2
A14: 340 | B14: FJALLRAVEN by 3NITY 大丸心斎橋 | C14: 90170626-625S | D14: Lappland Hybrid Jacket M | E14: FRV | F14: FJALLRAVEN | G14: Outers | H14: 0 | I14: 1 | J14: 0 | K14: 1

Sheet NODE
K1: =SUBTOTAL(9,K3:K15) -> 14
A2: 拠点コード | B2: 拠点名 | C2: 商品コード | D2: 商品名 | E2: Brand | F2: BrandName | G2: 分類２名 | H2: 繰越数量 | I2: 受入数量 | J2: 払出数量 | K2: 現在数量
A3: 330 | B3: FJALLRAVEN by 3NITY TOKYO NODE | C3: 23795319X | D3: Kanken Rain Cover Mini | E3: FRV | F3: FJALLRAVEN | G3: Kanken | H3: 0 | I3: 4 | J3: 3 | K3: 1
A4: 330 | B4: FJALLRAVEN by 3NITY TOKYO NODE | C4: 23795525X | D4: Kanken Rain Cover Mini | E4: FRV | F4: FJALLRAVEN | G4: Kanken | H4: 0 | I4: 1 | J4: 0 | K4: 1
A5: 330 | B5: FJALLRAVEN by 3NITY TOKYO NODE | C5: 86975050L | D5: Kanken Art T-shirt M | E5: FRV | F5: FJALLRAVEN | G5: Inners | H5: 0 | I5: 2 | J5: 1 | K5: 1
A6: 330 | B6: FJALLRAVEN by 3NITY TOKYO NODE | C6: 86975050M | D6: Kanken Art T-shirt M | E6: FRV | F6: FJALLRAVEN | G6: Inners | H6: 0 | I6: 2 | J6: 1 | K6: 1
A7: 330 | B7: FJALLRAVEN by 3NITY TOKYO NODE | C7: 86975135S | D7: Kanken Art T-shirt M | E7: FRV | F7: FJALLRAVEN | G7: Inners | H7: 0 | I7: 2 | J7: 1 | K7: 1
A8: 330 | B8: FJALLRAVEN by 3NITY TOKYO NODE | C8: 86975534S | D8: Kanken Art T-shirt M | E8: FRV | F8: FJALLRAVEN | G8: Inners | H8: 0 | I8: 2 | J8: 1 | K8: 1
A9: 330 | B9: FJALLRAVEN by 3NITY TOKYO NODE | C9: 86975620L | D9: Kanken Art T-shirt M | E9: FRV | F9: FJALLRAVEN | G9: Inners | H9: 0 | I9: 3 | J9: 2 | K9: 1
A10: 330 | B10: FJALLRAVEN by 3NITY TOKYO NODE | C10: 86975620M | D10: Kanken Art T-shirt M | E10: FRV | F10: FJALLRAVEN | G10: Inners | H10: 0 | I10: 3 | J10: 1 | K10: 2
A11: 330 | B11: FJALLRAVEN by 3NITY TOKYO NODE | C11: 86976113M | D11: Fjallraven Equipment T-shirt M | E11: FRV | F11: FJALLRAVEN | G11: Inners | H11: 0 | I11: 2 | J11: 1 | K11: 1
A12: 330 | B12: FJALLRAVEN by 3NITY TOKYO NODE | C12: 86976207M | D12: Fjallraven Equipment T-shirt M | E12: FRV | F12: FJALLRAVEN | G12: Inners | H12: 0 | I12: 2 | J12: 1 | K12: 1
A13: 330 | B13: FJALLRAVEN by 3NITY TOKYO NODE | C13: 86976207S | D13: Fjallraven Equipment T-shirt M | E13: FRV | F13: FJALLRAVEN | G13: Inners | H13: 0 | I13: 2 | J13: 1 | K13: 1
A14: 330 | B14: FJALLRAVEN by 3NITY TOKYO NODE | C14: 86976534S | D14: Fjallraven Equipment T-shirt M | E14: FRV | F14: FJALLRAVEN | G14: Inners | H14: 0 | I14: 2 | J14: 1 | K14: 1
A15: 330 | B15: FJALLRAVEN by 3NITY TOKYO NODE | C15: 86976620S | D15: Fjallraven Equipment T-shirt M | E15: FRV | F15: FJALLRAVEN | G15: Inners | H15: 0 | I15: 2 | J15: 1 | K15: 1

Sheet EC
K1: =SUBTOTAL(9,K3:K133) -> 151
A2: 拠点コード | B2: 拠点名 | C2: 商品コード | D2: 商品名 | E2: Brand | F2: BrandName | G2: 分類２名 | H2: 繰越数量 | I2: 受入数量 | J2: 払出数量 | K2: 現在数量
A3: 250 | B3: FJALLRAVEN by 3NITY | C3: 23200208X | D3: Bergtagen 38 S/M | E3: FRV | F3: FJALLRAVEN | G3: Bags | H3: 0 | I3: 17 | J3: 15 | K3: 2
A4: 250 | B4: FJALLRAVEN by 3NITY | C4: 23200570X | D4: Bergtagen 38 S/M | E4: FRV | F4: FJALLRAVEN | G4: Bags | H4: 0 | I4: 17 | J4: 14 | K4: 3
A5: 250 | B5: FJALLRAVEN by 3NITY | C5: 23201208X | D5: Bergtagen 38 M/L | E5: FRV | F5: FJALLRAVEN | G5: Bags | H5: 0 | I5: 16 | J5: 14 | K5: 2
A6: 250 | B6: FJALLRAVEN by 3NITY | C6: 23201570X | D6: Bergtagen 38 M/L | E6: FRV | F6: FJALLRAVEN | G6: Bags | H6: 0 | I6: 19 | J6: 17 | K6: 2
A7: 250 | B7: FJALLRAVEN by 3NITY | C7: 23795319X | D7: Kanken Rain Cover Mini | E7: FRV | F7: FJALLRAVEN | G7: Kanken | H7: 0 | I7: 28 | J7: 27 | K7: 1
A8: 250 | B8: FJALLRAVEN by 3NITY | C8: 24401991X | D8: Packbags | E8: FRV | F8: FJALLRAVEN | G8: Accessories | H8: 0 | I8: 33 | J8: 31 | K8: 2
A9: 250 | B9: FJALLRAVEN by 3NITY | C9: 80634510L | D9: Fjallraven Polar Parka M | E9: FRV | F9: FJALLRAVEN | G9: Outers | H9: 0 | I9: 11 | J9: 10 | K9: 1
A10: 250 | B10: FJALLRAVEN by 3NITY | C10: 80634510M | D10: Fjallraven Polar Parka M | E10: FRV | F10: FJALLRAVEN | G10: Outers | H10: 0 | I10: 11 | J10: 10 | K10: 1
A11: 250 | B11: FJALLRAVEN by 3NITY | C11: 80634510S | D11: Fjallraven Polar Parka M | E11: FRV | F11: FJALLRAVEN | G11: Outers | H11: 0 | I11: 11 | J11: 10 | K11: 1
A12: 250 | B12: FJALLRAVEN by 3NITY | C12: 80634510XS | D12: Fjallraven Polar Parka M | E12: FRV | F12: FJALLRAVEN | G12: Outers | H12: 0 | I12: 10 | J12: 9 | K12: 1
A13: 250 | B13: FJALLRAVEN by 3NITY | C13: 81152R030-55046 | D13: Abisko Midsummer Trs M Reg | E13: FRV | F13: FJALLRAVEN | G13: Bottoms | H13: 0 | I13: 8 | J13: 7 | K13: 1
A14: 250 | B14: FJALLRAVEN by 3NITY | C14: 81152R030-55048 | D14: Abisko Midsummer Trs M Reg | E14: FRV | F14: FJALLRAVEN | G14: Bottoms | H14: 0 | I14: 8 | J14: 7 | K14: 1
... A102: 250 | B102: FJALLRAVEN by 3NITY | C102: 89738575XS | D102: Greenland Winter Parka W | E102: FRV | F102: FJALLRAVEN | G102: Outers | H102: 0 | I102: 13 | J102: 12 | K102: 1
A103: 250 | B103: FJALLRAVEN by 3NITY | C103: 8980955036 | D103: Karla Pro Winter Trousers W | E103: FRV | F103: FJALLRAVEN | G103: Bottoms | H103: 0 | I103: 16 | J103: 15 | K103: 1
A104: 250 | B104: FJALLRAVEN by 3NITY | C104: 8980955038 | D104: Karla Pro Winter Trousers W | E104: FRV | F104: FJALLRAVEN | G104: Bottoms | H104: 0 | I104: 14 | J104: 13 | K104: 1
A105: 250 | B105: FJALLRAVEN by 3NITY | C105: 8980963338 | D105: Karla Pro Winter Trousers W | E105: FRV | F105: FJALLRAVEN | G105: Bottoms | H105: 0 | I105: 13 | J105: 12 | K105: 1
A106: 250 | B106: FJALLRAVEN by 3NITY | C106: 89827S55036 | D106: Abisko Midsummer Trs W Short | E106: FRV | F106: FJALLRAVEN | G106: Bottoms | H106: 0 | I106: 10 | J106: 9 | K106: 1
A107: 250 | B107: FJALLRAVEN by 3NITY | C107: 89827S562-56334 | D107: Abisko Midsummer Trs W Short | E107: FRV | F107: FJALLRAVEN | G107: Bottoms | H107: 0 | I107: 9 | J107: 8 | K107: 1
A108: 250 | B108: FJALLRAVEN by 3NITY | C108: 89827S562-56338 | D108: Abisko Midsummer Trs W Short | E108: FRV | F108: FJALLRAVEN | G108: Bottoms | H108: 0 | I108: 10 | J108: 9 | K108: 1
A109: 250 | B109: FJALLRAVEN by 3NITY | C109: 89829160-04636 | D109: Kaipak Trousers Curved W | E109: FRV | F109: FJALLRAVEN | G109: Bottoms | H109: 0 | I109: 8 | J109: 7 | K109: 1
A110: 250 | B110: FJALLRAVEN by 3NITY | C110: 89829160-04638 | D110: Kaipak Trousers Curved W | E110: FRV | F110: FJALLRAVEN | G110: Bottoms | H110: 0 | I110: 8 | J110: 7 | K110: 1
A111: 250 | B111: FJALLRAVEN by 3NITY | C111: 89829356-03038 | D111: Kaipak Trousers Curved W | E111: FRV | F111: FJALLRAVEN | G111: Bottoms | H111: 0 | I111: 8 | J111: 7 | K111: 1
A112: 250 | B112: FJALLRAVEN by 3NITY | C112: 89843516M | D112: Ovik Travel Shirt LS W | E112: FRV | F112: FJALLRAVEN | G112: Middlers | H112: 0 | I112: 13 | J112: 12 | K112: 1
A113: 250 | B113: FJALLRAVEN by 3NITY | C113: 89843516S | D113: Ovik Travel Shirt LS W | E113: FRV | F113: FJALLRAVEN | G113: Middlers | H113: 0 | I113: 13 | J113: 12 | K113: 1
A114: 250 | B114: FJALLRAVEN by 3NITY | C114: 89857562-56334 | D114: Abisko Midsummer Shorts W | E114: FRV | F114: FJALLRAVEN | G114: Bottoms | H114: 0 | I114: 8 | J114: 7 | K114: 1
A115: 250 | B115: FJALLRAVEN by 3NITY | C115: 89857562-56336 | D115: Abisko Midsummer Shorts W | E115: FRV | F115: FJALLRAVEN | G115: Bottoms | H115: 0 | I115: 8 | J115: 7 | K115: 1
A116: 250 | B116: FJALLRAVEN by 3NITY | C116: 89857562-56338 | D116: Abisko Midsummer Shorts W | E116: FRV | F116: FJALLRAVEN | G116: Bottoms | H116: 0 | I116: 8 | J116: 7 | K116: 1
A117: 250 | B117: FJALLRAVEN by 3NITY | C117: 89886570M | D117: Bergtagen Thinwool LS W | E117: FRV | F117: FJALLRAVEN | G117: Inners | H117: 0 | I117: 9 | J117: 8 | K117: 1
... A127: 250 | B127: FJALLRAVEN by 3NITY | C127: 90222626-66244 | D127: Barents Pro Hunting Trousers M | E127: FRV | F127: FJALLRAVEN | G127: Bottoms | H127: 0 | I127: 13 | J127: 12 | K127: 1
A128: 250 | B128: FJALLRAVEN by 3NITY | C128: 9022863346 | D128: Barents Pro Hydratic Trs M | E128: FRV | F128: FJALLRAVEN | G128: Bottoms | H128: 0 | I128: 11 | J128: 10 | K128: 1
A129: 250 | B129: FJALLRAVEN by 3NITY | C129: 90662550L | D129: Expedition Down Booties | E129: FRV | F129: FJALLRAVEN | G129: Accessories | H129: 0 | I129: 9 | J129: 8 | K129: 1
A130: 250 | B130: FJALLRAVEN by 3NITY | C130: 90662550M | D130: Expedition Down Booties | E130: FRV | F130: FJALLRAVEN | G130: Accessories | H130: 0 | I130: 8 | J130: 7 | K130: 1
A131: 250 | B131: FJALLRAVEN by 3NITY | C131: 90662550S | D131: Expedition Down Booties | E131: FRV | F131: FJALLRAVEN | G131: Accessories | H131: 0 | I131: 8 | J131: 7 | K131: 1
A132: 250 | B132: FJALLRAVEN by 3NITY | C132: 90662550XL | D132: Expedition Down Booties | E132: FRV | F132: FJALLRAVEN | G132: Accessories | H132: 0 | I132: 9 | J132: 8 | K132: 1
A133: 250 | B133: FJALLRAVEN by 3NITY | C133: 9070263338 | D133: Sormland Tapered Winter Trs W | E133: FRV | F133: FJALLRAVEN | G133: Bottoms | H133: 0 | I133: 12 | J133: 11 | K133: 1

Sheet ZOZO
K1: =SUBTOTAL(9,K3:K12) -> 10
A2: 拠点コード | B2: 拠点名 | C2: 商品コード | D2: 商品名 | E2: Brand | F2: BrandName | G2: 分類２名 | H2: 繰越数量 | I2: 受入数量 | J2: 払出数量 | K2: 現在数量
A3: 220 | B3: ZOZO | C3: 23200208X | D3: Bergtagen 38 S/M | E3: FRV | F3: FJALLRAVEN | G3: Bags | H3: 0 | I3: 4 | J3: 3 | K3: 1
A4: 220 | B4: ZOZO | C4: 23200570X | D4: Bergtagen 38 S/M | E4: FRV | F4: FJALLRAVEN | G4: Bags | H4: 0 | I4: 3 | J4: 2 | K4: 1
A5: 220 | B5: ZOZO | C5: 23201208X | D5: Bergtagen 38 M/L | E5: FRV | F5: FJALLRAVEN | G5: Bags | H5: 0 | I5: 3 | J5: 2 | K5: 1
A6: 220 | B6: ZOZO | C6: 23201570X | D6: Bergtagen 38 M/L | E6: FRV | F6: FJALLRAVEN | G6: Bags | H6: 0 | I6: 4 | J6: 3 | K6: 1
A7: 220 | B7: ZOZO | C7: 23332290X | D7: Norrvage Briefpack | E7: FRV | F7: FJALLRAVEN | G7: Bags | H7: 0 | I7: 6 | J7: 5 | K7: 1
A8: 220 | B8: ZOZO | C8: 25514330X | D8: Travel Pack | E8: FRV | F8: FJALLRAVEN | G8: Bags | H8: 0 | I8: 5 | J8: 4 | K8: 1
A9: 220 | B9: ZOZO | C9: 81765030L | D9: Sten Fleece | E9: FRV | F9: FJALLRAVEN | G9: Middlers | H9: 0 | I9: 3 | J9: 2 | K9: 1
A10: 220 | B10: ZOZO | C10: 81765633XS | D10: Sten Fleece | E10: FRV | F10: FJALLRAVEN | G10: Middlers | H10: 0 | I10: 4 | J10: 3 | K10: 1
A11: 220 | B11: ZOZO | C11: 84784981-982X | D11: Campfire Bandana | E11: FRV | F11: FJALLRAVEN | G11: Accessories | H11: 0 | I11: 3 | J11: 2 | K11: 1
A12: 220 | B12: ZOZO | C12: 90222626-66244 | D12: Barents Pro Hunting Trousers M | E12: FRV | F12: FJALLRAVEN | G12: Bottoms | H12: 0 | I12: 2 | J12: 1 | K12: 1

Sheet 丸井
A1: 拠点コード | B1: 拠点名 | C1: 商品コード | D1: 商品名 | E1: Brand | F1: BrandName | G1: 分類２名 | H1: 繰越数量 | I1: 受入数量 | J1: 払出数量 | K1: 現在数量
A2: 240 | B2: 丸井ｳｪﾌﾞﾁｬﾝﾈﾙ | C2: 23332290X | D2: Norrvage Briefpack | E2: FRV | F2: FJALLRAVEN | G2: Bags | H2: 0 | I2: 5 | J2: 4 | K2: 1

Sheet 6142
K1: =SUBTOTAL(9,K3:K35) -> 35
A2: 拠点コード | B2: 拠点名 | C2: 商品コード | D2: 商品名 | E2: Brand | F2: BrandName | G2: 分類２名 | H2: 繰越数量 | I2: 受入数量 | J2: 払出数量 | K2: 現在数量
A3: RPP2 | B3: 6142 | C3: 80538614110 | D3: Kids Fjallraven Logo T-shirt | E3: FRV | F3: FJALLRAVEN | G3: Inners | H3: 0 | I3: 4 | J3: 3 | K3: 1
A4: RPP2 | B4: 6142 | C4: 80538614122 | D4: Kids Fjallraven Logo T-shirt | E4: FRV | F4: FJALLRAVEN | G4: Inners | H4: 0 | I4: 3 | J4: 2 | K4: 1
A5: RPP2 | B5: 6142 | C5: 80538614134 | D5: Kids Fjallraven Logo T-shirt | E5: FRV | F5: FJALLRAVEN | G5: Inners | H5: 0 | I5: 2 | J5: 1 | K5: 1
A6: RPP2 | B6: 6142 | C6: 81152R030-55050 | D6: Abisko Midsummer Trs M Reg | E6: FRV | F6: FJALLRAVEN | G6: Bottoms | H6: 0 | I6: 2 | J6: 1 | K6: 1
A7: RPP2 | B7: 6142 | C7: 81153030-55044 | D7: Abisko Midsummer Shorts M | E7: FRV | F7: FJALLRAVEN | G7: Bottoms | H7: 0 | I7: 4 | J7: 3 | K7: 1
A8: RPP2 | B8: 6142 | C8: 81761550-55044 | D8: Barents Pro Trousers | E8: FRV | F8: FJALLRAVEN | G8: Bottoms | H8: 0 | I8: 1 | J8: 0 | K8: 1
A9: RPP2 | B9: 6142 | C9: 81761550-55046 | D9: Barents Pro Trousers | E9: FRV | F9: FJALLRAVEN | G9: Bottoms | H9: 0 | I9: 2 | J9: 1 | K9: 1
A10: RPP2 | B10: 6142 | C10: 81761633-63344 | D10: Barents Pro Trousers | E10: FRV | F10: FJALLRAVEN | G10: Bottoms | H10: 0 | I10: 1 | J10: 0 | K10: 1
A11: RPP2 | B11: 6142 | C11: 84128550-030XS | D11: Vardag Lite Padded Jacket M | E11: FRV | F11: FJALLRAVEN | G11: Outers | H11: 0 | I11: 1 | J11: 0 | K11: 1
A12: RPP2 | B12: 6142 | C12: 84784981-982X | D12: Campfire Bandana | E12: FRV | F12: FJALLRAVEN | G12: Accessories | H12: 0 | I12: 2 | J12: 0 | K12: 2
A13: RPP2 | B13: 6142 | C13: 84784987-986X | D13: Campfire Bandana | E13: FRV | F13: FJALLRAVEN | G13: Accessories | H13: 0 | I13: 2 | J13: 0 | K13: 2
A14: RPP2 | B14: 6142 | C14: 86121154M | D14: Expedition Pack Down Hoodie M | E14: FRV | F14: FJALLRAVEN | G14: Outers | H14: 0 | I14: 1 | J14: 0 | K14: 1
A15: RPP2 | B15: 6142 | C15: 86121154S | D15: Expedition Pack Down Hoodie M | E15: FRV | F15: FJALLRAVEN | G15: Outers | H15: 0 | I15: 1 | J15: 0 | K15: 1
A16: RPP2 | B16: 6142 | C16: 86121525M | D16: Expedition Pack Down Hoodie M | E16: FRV | F16: FJALLRAVEN | G16: Outers | H16: 0 | I16: 1 | J16: 0 | K16: 1
A17: RPP2 | B17: 6142 | C17: 86121525S | D17: Expedition Pack Down Hoodie M | E17: FRV | F17: FJALLRAVEN | G17: Outers | H17: 0 | I17: 1 | J17: 0 | K17: 1
... A35: RPP2 | B35: 6142 | C35: 89898S563-56236 | D35: Keb Trousers W | E35: FRV | F35: FJALLRAVEN | G35: Bottoms | H35: 0 | I35: 10 | J35: 9 | K35: 1
