Workbook

Sheet 店舗コード
A2: 店舗名称
A3: FJALLRAVEN by 3NITY 札幌ステラプレイス | B3: 99 XXX
A4: FJALLRAVEN STORE OSAKA ALBi | B4: 99 XXX
A5: FJALLRAVEN STORE 新宿小田急ハルク | B5: 99 XXX
A6: フェールラーベンストア名古屋ファッションワン | B6: 04 名古屋
A7: FJALLRAVEN by 3NITY ｱﾐｭﾌﾟﾗｻﾞ博多 | B7: 99 XXX
A8: FJALLRAVEN by 3NITY TOKYO | B8: 07 TOKYO
A9: FJALLRAVEN STORE 石井山専新宿東口ビックロ | B9: 99 XXX
A10: FJALLRAVEN by 3NITY 新宿小田急ハルク | B10: 99 XXX
A11: FJALLRAVEN by 3NITY 博多阪急イングス | B11: 99 XXX
A12: FJALLERAVEN by 3NITYルクア大阪 | B12: 08 ルクア大阪
A13: ハルク売上 | B13: 99 XXX
A14: FJALLRAVEN by 3NITY ルクア大阪 | B14: 08 ルクア大阪
... A22: FJALLRAVEN by 3NITY 心斎橋パルコ | B22: 99 XXX
A23: 6142 | B23: 16 6142
A24: FJALLRAVEN by 3NITY玉川高島屋S・C | B24: 17 玉川高島屋
A25: FJALLRAVEN POP-UP | B25: 99 XXX
A26: FJALLRAVEN by 3NITY POPUP | B26: 19 NODE
A27: FJALLRAVEN by 3NITY 大丸心斎橋 | B27: 15 大丸心斎橋
A28: FJALLRAVEN POPUP NARITA | B28: 20 NARITA
A29: FJALLRAVEN by 3NITY TOKYO NODE | B29: 19 NODE

Sheet 営業日付別売上分析 貼り付け
A1: 店舗名称 | B1: 3rd Item No. | C1: 表記部門名1 | D1: StyleNo | E1: 商品名 | F1: ColorNo | G1: ColorName | H1: Size | I1: 数量 | J1: 店舗
A2: FJALLRAVEN STORE 名古屋ファッションワン | B2: 77292633S/M | C2: FJALLRAVEN | D2: 77292 | E2: Singi Gaiters | F2: 633 | G2: Dark Olive | H2: S/M | I2: 1 | J2: =VLOOKUP(A2,店舗コード!A:B,2,FALSE) -> 04 名古屋
A3: FJALLRAVEN by 3NITY 大丸心斎橋 | B3: 23225550X | C3: FJALLRAVEN | D3: 23225 | E3: High Coast Totepack | F3: 550 | G3: Black | H3: X | I3: 1 | J3: =VLOOKUP(A3,店舗コード!A:B,2,FALSE) -> 15 大丸心斎橋
A4: FJALLRAVEN by 3NITY 大丸心斎橋 | B4: 23225550X | C4: FJALLRAVEN | D4: 23225 | E4: High Coast Totepack | F4: 550 | G4: Black | H4: X | I4: -1 | J4: =VLOOKUP(A4,店舗コード!A:B,2,FALSE) -> 15 大丸心斎橋
A5: FJALLRAVEN by 3NITY 大丸心斎橋 | B5: 23225550X | C5: FJALLRAVEN | D5: 23225 | E5: High Coast Totepack | F5: 550 | G5: Black | H5: X | I5: 1 | J5: =VLOOKUP(A5,店舗コード!A:B,2,FALSE) -> 15 大丸心斎橋
A6: FJALLRAVEN by 3NITY SAPPORO HUTTE | B6: 77357520L/XL | C6: FJALLRAVEN | D6: 77357 | E6: Vidda Cap | F6: 520 | G6: Uncle Blue | H6: L/XL | I6: 1 | J6: =VLOOKUP(A6,店舗コード!A:B,2,FALSE) -> 10 ヒュッテ
A7: FJALLRAVEN by 3NITY SAPPORO HUTTE | B7: 77357520L/XL | C7: FJALLRAVEN | D7: 77357 | E7: Vidda Cap | F7: 520 | G7: Uncle Blue | H7: L/XL | I7: -1 | J7: =VLOOKUP(A7,店舗コード!A:B,2,FALSE) -> 10 ヒュッテ
A8: FJALLRAVEN POPUP NARITA | B8: 23225424X | C8: FJALLRAVEN | D8: 23225 | E8: High Coast Totepack | F8: 424 | G8: Blackberry | H8: X | I8: 1 | J8: =VLOOKUP(A8,店舗コード!A:B,2,FALSE) -> 20 NARITA
A9: FJALLRAVEN POPUP NARITA | B9: 23226424X | C9: FJALLRAVEN | D9: 23226 | E9: High Coast Pocket | F9: 424 | G9: Blackberry | H9: X | I9: 1 | J9: =VLOOKUP(A9,店舗コード!A:B,2,FALSE) -> 20 NARITA
A10: FJALLRAVEN by 3NITY SAPPORO HUTTE | B10: 77357520L/XL | C10: FJALLRAVEN | D10: 77357 | E10: Vidda Cap | F10: 520 | G10: Uncle Blue | H10: L/XL | I10: 1 | J10: =VLOOKUP(A10,店舗コード!A:B,2,FALSE) -> 10 ヒュッテ
A11: FJALLRAVEN by 3NITY SAPPORO HUTTE | B11: 79030X | C11: FJALLRAVEN | D11: 79030 | E11: Greenland Wax travel pack | H11: X | I11: 1 | J11: =VLOOKUP(A11,店舗コード!A:B,2,FALSE) -> 10 ヒュッテ
A12: FJALLRAVEN by 3NITY玉川高島屋S・C | B12: 23510126X | C12: FJALLRAVEN | D12: 23510 | E12: Kanken | F12: 126 | G12: Corn | H12: X | I12: 1 | J12: =VLOOKUP(A12,店舗コード!A:B,2,FALSE) -> 17 玉川高島屋
A13: FJALLRAVEN POPUP NARITA | B13: 23561126X | C13: FJALLRAVEN | D13: 23561 | E13: Kanken Mini | F13: 126 | G13: Corn | H13: X | I13: 1 | J13: =VLOOKUP(A13,店舗コード!A:B,2,FALSE) -> 20 NARITA
A14: FJALLRAVEN POPUP NARITA | B14: 23561457X | C14: FJALLRAVEN | D14: 23561 | E14: Kanken Mini | F14: 457 | G14: Pastel Lavender | H14: X | I14: 1 | J14: =VLOOKUP(A14,店舗コード!A:B,2,FALSE) -> 20 NARITA
A15: FJALLRAVEN STORE 名古屋ファッションワン | B15: 23524560X | C15: FJALLRAVEN | D15: 23524 | E15: Kanken Laptop 15 | F15: 560 | G15: Navy | H15: X | I15: 1 | J15: =VLOOKUP(A15,店舗コード!A:B,2,FALSE) -> 04 名古屋
A16: FJALLRAVEN POPUP NARITA | B16: 23803560X | C16: FJALLRAVEN | D16: 23803 | E16: Kanken no. 2 Laptop 15 | F16: 560 | G16: Navy | H16: X | I16: 1 | J16: =VLOOKUP(A16,店舗コード!A:B,2,FALSE) -> 20 NARITA
A17: FJALLRAVEN by 3NITY ルクア大阪 | B17: 24215560X | C17: FJALLRAVEN | D17: 24215 | E17: Gear Pocket | F17: 560 | G17: Navy | H17: X | I17: 1 | J17: =VLOOKUP(A17,店舗コード!A:B,2,FALSE) -> 08 ルクア大阪
A18: FJALLRAVEN STORE 名古屋ファッションワン | B18: 23349577X | C18: FJALLRAVEN | D18: 23349 | E18: Skule 20 | F18: 577 | G18: Nimbus Blue | H18: X | I18: 1 | J18: =VLOOKUP(A18,店舗コード!A:B,2,FALSE) -> 04 名古屋
A19: FJALLRAVEN STORE 名古屋ファッションワン | B19: 24213030X | C19: FJALLRAVEN | D19: 24213 | E19: Gear Bag | F19: 30 | G19: Dark Grey | H19: X | I19: 1 | J19: =VLOOKUP(A19,店舗コード!A:B,2,FALSE) -> 04 名古屋
A20: FJALLRAVEN STORE 名古屋ファッションワン | B20: 25862664X | C20: FJALLRAVEN | D20: 25862 | E20: Kanken Gear Bag | F20: 664 | G20: Frost Green | H20: X | I20: 1 | J20: =VLOOKUP(A20,店舗コード!A:B,2,FALSE) -> 04 名古屋
A21: 6142 | B21: 23200330620X | C21: FJALLRAVEN | D21: 23200330 | E21: High Coast Backpack 24 | F21: 620 | G21: Green | H21: X | I21: 1 | J21: =VLOOKUP(A21,店舗コード!A:B,2,FALSE) -> 16 6142
A22: 6142 | B22: 23226623X | C22: FJALLRAVEN | D22: 23226 | E22: High Coast Pocket | F22: 623 | G22: Mountain Green | H22: X | I22: 1 | J22: =VLOOKUP(A22,店舗コード!A:B,2,FALSE) -> 16 6142
A23: FJALLRAVEN STORE 名古屋ファッションワン | B23: 86984550S | C23: FJALLRAVEN | D23: 86984 | E23: HC Hydratic Trail Jacket M | F23: 550 | G23: Black | H23: S | I23: 1 | J23: =VLOOKUP(A23,店舗コード!A:B,2,FALSE) -> 04 名古屋
A24: FJALLRAVEN POPUP NARITA | B24: 23785620X | C24: FJALLRAVEN | D24: 23785 | E24: Kanken Keyring | F24: 620 | G24: Green | H24: X | I24: 1 | J24: =VLOOKUP(A24,店舗コード!A:B,2,FALSE) -> 20 NARITA
A25: FJALLRAVEN by 3NITY 大丸心斎橋 | B25: 23510664X | C25: FJALLRAVEN | D25: 23510 | E25: Kanken | F25: 664 | G25: Frost Green | H25: X | I25: 1 | J25: =VLOOKUP(A25,店舗コード!A:B,2,FALSE) -> 15 大丸心斎橋
A26: FJALLRAVEN by 3NITY 京王新宿 | B26: 23165550X | C26: FJALLRAVEN | D26: 23165 | E26: Ulvo Hip Pack Medium | F26: 550 | G26: Black | H26: X | I26: 1 | J26: =VLOOKUP(A26,店舗コード!A:B,2,FALSE) -> 13 京王新宿
A27: FJALLRAVEN by 3NITY TOKYO | B27: 23565633X | C27: FJALLRAVEN | D27: 23565 | E27: Kanken No.2 | F27: 633 | G27: Dark Olive | H27: X | I27: 1 | J27: =VLOOKUP(A27,店舗コード!A:B,2,FALSE) -> 07 TOKYO
A28: 6142 | B28: 23222620X | C28: FJALLRAVEN | D28: 23222 | E28: High Coast Foldsack 24 | F28: 620 | G28: Green | H28: X | I28: 1 | J28: =VLOOKUP(A28,店舗コード!A:B,2,FALSE) -> 16 6142
A29: FJALLRAVEN POPUP NARITA | B29: 23802424X | C29: FJALLRAVEN | D29: 23802 | E29: Kanken Weekender | F29: 424 | G29: Blackberry | H29: X | I29: 1 | J29: =VLOOKUP(A29,店舗コード!A:B,2,FALSE) -> 20 NARITA
A30: FJALLRAVEN by 3NITY ルクア大阪 | B30: 23796600X | C30: FJALLRAVEN | D30: 23796 | E30: Kanken Hip Pack | F30: 600 | G30: Mint Green | H30: X | I30: 1 | J30: =VLOOKUP(A30,店舗コード!A:B,2,FALSE) -> 08 ルクア大阪
A31: FJALLRAVEN POPUP NARITA | B31: 23227550X | C31: FJALLRAVEN | D31: 23227 | E31: High Coast Crossbody | F31: 550 | G31: Black | H31: X | I31: 1 | J31: =VLOOKUP(A31,店舗コード!A:B,2,FALSE) -> 20 NARITA
A32: FJALLRAVEN POPUP NARITA | B32: 77357570-050L/XL | C32: FJALLRAVEN | D32: 77357 | E32: Vidda Cap | F32: 570-050 | G32: Mountain Blue-Basalt | H32: L/XL | I32: 1 | J32: =VLOOKUP(A32,店舗コード!A:B,2,FALSE) -> 20 NARITA
A33: FJALLRAVEN by 3NITY ルクア大阪 | B33: 25863550X | C33: FJALLRAVEN | D33: 25863 | E33: Kanken Gear Pocket | F33: 550 | G33: Black | H33: X | I33: 1 | J33: =VLOOKUP(A33,店舗コード!A:B,2,FALSE) -> 08 ルクア大阪
A34: FJALLRAVEN by 3NITY ルクア大阪 | B34: 25863560X | C34: FJALLRAVEN | D34: 25863 | E34: Kanken Gear Pocket | F34: 560 | G34: Navy | H34: X | I34: 1 | J34: =VLOOKUP(A34,店舗コード!A:B,2,FALSE) -> 08 ルクア大阪
A35: 6142 | B35: 23510021-312X | C35: FJALLRAVEN | D35: 23510 | E35: Kanken | F35: 021-312 | G35: Fog-Pink | H35: X | I35: 1 | J35: =VLOOKUP(A35,店舗コード!A:B,2,FALSE) -> 16 6142
A36: FJALLRAVEN by 3NITY 大丸心斎橋 | B36: 23510501X | C36: FJALLRAVEN | D36: 23510 | E36: Kanken | F36: 501 | G36: Sky blue | H36: X | I36: 1 | J36: =VLOOKUP(A36,店舗コード!A:B,2,FALSE) -> 15 大丸心斎橋
A37: FJALLRAVEN by 3NITY 大丸心斎橋 | B37: 23346550X | C37: FJALLRAVEN | D37: 23346 | E37: Skule 28 | F37: 550 | G37: Black | H37: X | I37: 1 | J37: =VLOOKUP(A37,店舗コード!A:B,2,FALSE) -> 15 大丸心斎橋
A38: FJALLRAVEN by 3NITY ルクア大阪 | B38: 23346550X | C38: FJALLRAVEN | D38: 23346 | E38: Skule 28 | F38: 550 | G38: Black | H38: X | I38: 1 | J38: =VLOOKUP(A38,店舗コード!A:B,2,FALSE) -> 08 ルクア大阪
A39: FJALLRAVEN by 3NITY ルクア大阪 | B39: 23346577X | C39: FJALLRAVEN | D39: 23346 | E39: Skule 28 | F39: 577 | G39: Nimbus Blue | H39: X | I39: 1 | J39: =VLOOKUP(A39,店舗コード!A:B,2,FALSE) -> 08 ルクア大阪
A40: FJALLRAVEN by 3NITY ルクア大阪 | B40: 23785299X | C40: FJALLRAVEN | D40: 23785 | E40: Kanken Keyring | F40: 299 | G40: Dark Oak | H40: X | I40: 1 | J40: =VLOOKUP(A40,店舗コード!A:B,2,FALSE) -> 08 ルクア大阪
...

Sheet pivot
A4: a | B4: =TRIM(MID(B6,3,10)) -> 名古屋 | C4: =TRIM(MID(C6,3,10)) -> TOKYO | D4: =TRIM(MID(D6,3,10)) -> ルクア大阪 | E4: =TRIM(MID(E6,3,10)) -> ヒュッテ | F4: =TRIM(MID(F6,3,10)) -> 京王新宿 | G4: =TRIM(MID(G6,3,10)) -> 大丸心斎橋 | H4: =TRIM(MID(H6,3,10))*1 -> 6142 | I4: =TRIM(MID(I6,3,10)) -> 玉川高島屋 | J4: =TRIM(MID(J6,3,10)) -> NARITA | K4: =TRIM(MID(K6,3,10)) | L4: =MID(L6,3,10) | M4: =MID(M6,3,10) | N4: 1
A5: 合計 / 数量 | B5: 列ラベル
A6: 行ラベル | B6: 04 名古屋 | C6: 07 TOKYO | D6: 08 ルクア大阪 | E6: 10 ヒュッテ | F6: 13 京王新宿 | G6: 15 大丸心斎橋 | H6: 16 6142 | I6: 17 玉川高島屋 | J6: 20 NARITA
A7: 23524031X | F7: 1
A8: 23510302X | B8: 1 | C8: 8 | D8: 3 | E8: 2 | F8: 2 | G8: 1 | H8: 1 | I8: 4 | J8: 2
A9: 23620550-907X | B9: 1 | C9: 1 | D9: 1 | J9: 1
A10: 23622907X | D10: 2 | H10: 1 | J10: 1
A11: 23344050X | H11: 1
A12: 23804550X | C12: 2 | D12: 2 | E12: 1 | J12: 1
A13: 23345560X | C13: 1 | D13: 2
A14: 23510118X | C14: 1 | F14: 1
A15: 23510664X | C15: 1 | F15: 1 | G15: 1 | H15: 1
A16: 23227543X | C16: 2 | H16: 1 | J16: 1
A17: 23166550X | D17: 1 | J17: 1
A18: 23346550X | C18: 1 | D18: 1 | G18: 1 | I18: 1 | J18: 1
A19: 23223550X | C19: 2 | D19: 2
A20: 23510600X | C20: 2 | E20: 1 | F20: 1 | G20: 1 | J20: 1
A21: 23803560X | C21: 2 | J21: 1
A22: 23510021-312X | B22: 1 | E22: 1 | H22: 2 | J22: 2
A23: 23510501-115X | B23: 1 | C23: 4 | D23: 1 | E23: 3 | F23: 4 | I23: 2 | J23: 2
A24: 23561021-312X | C24: 1 | D24: 2 | G24: 1 | J24: 1
A25: 23505160X | C25: 1 | G25: 2
A26: 23797302X | C26: 1 | H26: 2
A27: 23510312X | B27: 1 | C27: 2 | D27: 3 | E27: 1 | F27: 2 | I27: 1 | J27: 3
A28: 23524560X | B28: 1 | D28: 1
A29: 23510560X | B29: 1 | C29: 1 | I29: 1
A30: 23227221X | C30: 2 | D30: 2 | F30: 1
A31: 23349550X | D31: 4 | H31: 1 | J31: 2
A32: 23623550-907X | D32: 1
A33: 23561457X | I33: 1 | J33: 1
A34: 23200339037X | B34: 1 | D34: 1
A35: 23200395550X | C35: 2 | D35: 1 | J35: 3
A36: 23523424X | I36: 1
A37: 23510540X | C37: 1 | D37: 1 | G37: 2 | I37: 1
A38: 23523501X | C38: 1
A39: 23510326X | E39: 1 | F39: 3 | G39: 3 | H39: 2
A40: 77357030S/M | D40: 2 | E40: 1 | G40: 2 | J40: 1
A41: 23510424X | C41: 2 | D41: 3 | G41: 1
A42: 87153300XS | J42: 1
A43: 23797118X | G43: 1
...

Sheet ZOZOOIOI
A1: ZOZO | B1: 商品コード | C1: ブランド名 | D1: StyleNo | E1: 商品名 | F1: ColorNo | G1: ColorName | H1: Size | I1: 標準単価 | J1: 販売数量 | L1: 行ラベル | M1: 合計 / 販売数量 | O1: OIOI | P1: 商品コード | Q1: ブランド名 | R1: StyleNo | S1: 商品名 | T1: ColorNo | U1: ColorName | V1: Size | W1: 標準単価 | X1: 販売数量 | Z1: 行ラベル | AA1: 合計 / 販売数量
A2: =SUM(J:J) -> 44 | B2: 23561501-115X | C2: FJALLRAVEN | D2: 23561 | E2: Kanken Mini | F2: 501-115 | G2: Sky Blue-Light Oak | H2: X | I2: 12000 | J2: -1 | L2: 23344550X | M2: 2 | O2: =SUM(X:X) -> 28 | P2: 23510501X | Q2: FJALLRAVEN | R2: 23510 | S2: Kanken | T2: 501 | U2: Sky blue | V2: X | W2: 13000 | X2: -1 | Z2: 23505560X | AA2: 0
B3: 23510457X | C3: FJALLRAVEN | D3: 23510 | E3: Kanken | F3: 457 | G3: Pastel Lavender | H3: X | I3: 13000 | J3: 1 | L3: 23510312X | M3: 1 | P3: 23505560X | Q3: FJALLRAVEN | R3: 23505 | S3: Kanken Shoulder Pads | T3: 560 | U3: Navy | V3: X | W3: 3500 | X3: -1 | Z3: 23510312X | AA3: 1
B4: 23561021-312X | C4: FJALLRAVEN | D4: 23561 | E4: Kanken Mini | F4: 021-312 | G4: Fog-Pink | H4: X | I4: 12000 | J4: 1 | L4: 23510457X | M4: 1 | P4: 23346662X | Q4: FJALLRAVEN | R4: 23346 | S4: Skule 28 | T4: 662 | U4: Deep Forest | V4: X | W4: 14000 | X4: -1 | Z4: 23510501X | AA4: -1
B5: 23561326X | C5: FJALLRAVEN | D5: 23561 | E5: Kanken Mini | F5: 326 | G5: Ox Red | H5: X | I5: 12000 | J5: 1 | L5: 23510501X | M5: 1 | P5: 23525160X | Q5: FJALLRAVEN | R5: 23525 | S5: Kanken Laptop 17 | T5: 160 | U5: Ochre | V5: X | W5: 19000 | X5: 1 | Z5: 23510540X | AA5: 2
B6: 23223543X | C6: FJALLRAVEN | D6: 23223 | E6: High Coast Hip Pack | F6: 543 | G6: Dawn Blue | H6: X | I6: 6500 | J6: 1 | L6: 23510540X | M6: 1 | P6: 23510126X | Q6: FJALLRAVEN | R6: 23510 | S6: Kanken | T6: 126 | U6: Corn | V6: X | W6: 13000 | X6: 1 | Z6: 23510550X | AA6: 1
B7: 23349662X | C7: FJALLRAVEN | D7: 23349 | E7: Skule 20 | F7: 662 | G7: Deep Forest | H7: X | I7: 12000 | J7: 1 | L7: 23510600X | M7: 1 | P7: 23510312X | Q7: FJALLRAVEN | R7: 23510 | S7: Kanken | T7: 312 | U7: Pink | V7: X | W7: 13000 | X7: 1 | Z7: 23510021X | AA7: 2
B8: 23200330016X | C8: FJALLRAVEN | D8: 23200330 | E8: High Coast Backpack 24 | F8: 16 | G8: Shark Grey | H8: X | I8: 17000 | J8: 1 | L8: 23561021-312X | M8: 4 | P8: 23561046X | Q8: FJALLRAVEN | R8: 23561 | S8: Kanken Mini | T8: 46 | U8: Super grey | V8: X | W8: 12000 | X8: 1 | Z8: 23165550X | AA8: 1
B9: 23561021-312X | C9: FJALLRAVEN | D9: 23561 | E9: Kanken Mini | F9: 021-312 | G9: Fog-Pink | H9: X | I9: 12000 | J9: 1 | L9: 23561312X | M9: -1 | P9: 23510664X | Q9: FJALLRAVEN | R9: 23510 | S9: Kanken | T9: 664 | U9: Frost Green | V9: X | W9: 13000 | X9: 1 | Z9: 79030X | AA9: 1
B10: 23561326X | C10: FJALLRAVEN | D10: 23561 | E10: Kanken Mini | F10: 326 | G10: Ox Red | H10: X | I10: 12000 | J10: 1 | L10: 23620550-907X | M10: 2 | P10: 23510126X | Q10: FJALLRAVEN | R10: 23510 | S10: Kanken | T10: 126 | U10: Corn | V10: X | W10: 13000 | X10: 1 | Z10: 23561046X | AA10: 1
B11: 23223623X | C11: FJALLRAVEN | D11: 23223 | E11: High Coast Hip Pack | F11: 623 | G11: Mountain Green | H11: X | I11: 6500 | J11: 1 | L11: 23796118X | M11: 1 | P11: 23781550X | Q11: FJALLRAVEN | R11: 23781 | S11: Kanken Travel Wallet | T11: 550 | U11: Black | V11: X | W11: 9000 | X11: 1 | Z11: (空白)
B12: 23524031X | C12: FJALLRAVEN | D12: 23524 | E12: Kanken Laptop 15 | F12: 31 | G12: Graphite | H12: X | I12: 18000 | J12: 1 | L12: 24213030X | M12: 1 | P12: 23165550X | Q12: FJALLRAVEN | R12: 23165 | S12: Ulvo Hip Pack Medium | T12: 550 | U12: Black | V12: X | W12: 8000 | X12: 1 | Z12: 23510126X | AA12: 2
B13: 23344550-550X | C13: FJALLRAVEN | D13: 23344 | E13: Raven 20 | F13: 550-550 | G13: Black-Black | H13: X | I13: 16000 | J13: 1 | L13: (空白) | P13: 79030X | Q13: FJALLRAVEN | R13: 79030 | S13: Greenland Wax travel pack | V13: X | W13: 850 | X13: 1 | Z13: 23796424X | AA13: 1
B14: 23804550X | C14: FJALLRAVEN | D14: 23804 | E14: Kanken no. 2 Black Laptop 15 | F14: 550 | G14: Black | H14: X | I14: 26000 | J14: 1 | L14: 23797031X | M14: 1 | P14: 23510540X | Q14: FJALLRAVEN | R14: 23510 | S14: Kanken | T14: 540 | U14: Royal Blue | V14: X | W14: 13000 | X14: 1 | Z14: 23510501-115X | AA14: 2
B15: TNT026164L | C15: TENNEN | D15: TNT026 | E15: 天撚Tシャツ /メリノウール | F15: 164 | G15: Burgundy | H15: L | I15: 11000 | J15: 1 | L15: 23796457X | M15: 1 | P15: 23510501-115X | Q15: FJALLRAVEN | R15: 23510 | S15: Kanken | T15: 501-115 | U15: Sky Blue-Light Oak | V15: X | W15: 13000 | X15: 1 | Z15: 23525160X | AA15: 1
B16: 23510160X | C16: FJALLRAVEN | D16: 23510 | E16: Kanken | F16: 160 | G16: Ochre | H16: X | I16: 13000 | J16: 1 | L16: 23510664X | M16: 1 | P16: 23565238X | Q16: FJALLRAVEN | R16: 23565 | S16: Kanken No.2 | T16: 238 | U16: Hazel Brown | V16: X | W16: 20000 | X16: 1 | Z16: 23510424X | AA16: 1
B17: 23510664X | C17: FJALLRAVEN | D17: 23510 | E17: Kanken | F17: 664 | G17: Frost Green | H17: X | I17: 13000 | J17: 1 | L17: 23510560X | M17: 1 | P17: 23200251021X | Q17: FJALLRAVEN | R17: 23200251 | S17: Kanken Outlong | T17: 21 | U17: Fog | V17: X | W17: 19000 | X17: 1 | Z17: 23510664X | AA17: 1
B18: 23561021-312X | C18: FJALLRAVEN | D18: 23561 | E18: Kanken Mini | F18: 021-312 | G18: Fog-Pink | H18: X | I18: 12000 | J18: 1 | L18: 23346050X | M18: 1 | P18: 23510424X | Q18: FJALLRAVEN | R18: 23510 | S18: Kanken | T18: 424 | U18: Blackberry | V18: X | W18: 13000 | X18: 1 | Z18: 23346550X | AA18: 1
B19: 23524031X | C19: FJALLRAVEN | D19: 23524 | E19: Kanken Laptop 15 | F19: 31 | G19: Graphite | H19: X | I19: 18000 | J19: 1 | L19: 23561600X | M19: -1 | P19: 23510540X | Q19: FJALLRAVEN | R19: 23510 | S19: Kanken | T19: 540 | U19: Royal Blue | V19: X | W19: 13000 | X19: 1 | Z19: 23349662X | AA19: 1
B20: 23344550X | C20: FJALLRAVEN | D20: 23344 | E20: Raven 20 | F20: 550 | G20: Black | H20: X | I20: 16000 | J20: 1 | L20: 23804550X | M20: 1 | P20: 23510501-115X | Q20: FJALLRAVEN | R20: 23510 | S20: Kanken | T20: 501-115 | U20: Sky Blue-Light Oak | V20: X | W20: 13000 | X20: 1 | Z20: 23349550X | AA20: 1
B21: 23200330620X | C21: FJALLRAVEN | D21: 23200330 | E21: High Coast Backpack 24 | F21: 620 | G21: Green | H21: X | I21: 17000 | J21: 1 | L21: 23200251160X | M21: 1 | P21: 23349662X | Q21: FJALLRAVEN | R21: 23349 | S21: Skule 20 | T21: 662 | U21: Deep Forest | V21: X | W21: 12000 | X21: 1 | Z21: 23565633X | AA21: 1
B22: 23561021-312X | C22: FJALLRAVEN | D22: 23561 | E22: Kanken Mini | F22: 021-312 | G22: Fog-Pink | H22: X | I22: 12000 | J22: 1 | L22: 23510021X | M22: 1 | P22: 23349550X | Q22: FJALLRAVEN | R22: 23349 | S22: Skule 20 | T22: 550 | U22: Black | V22: X | W22: 12000 | X22: 1 | Z22: 23345550X | AA22: 1
B23: 23200251160X | C23: FJALLRAVEN | D23: 23200251 | E23: Kanken Outlong | F23: 160 | G23: Ochre | H23: X | I23: 19000 | J23: 1 | L23: 23561457-916X | M23: 1 | P23: 23510021X | Q23: FJALLRAVEN | R23: 23510 | S23: Kanken | T23: 21 | U23: Fog | V23: X | W23: 13000 | X23: 1 | Z23: 23223207X | AA23: 1
B24: 23510664X | C24: FJALLRAVEN | D24: 23510 | E24: Kanken | F24: 664 | G24: Frost Green | H24: X | I24: 13000 | J24: -1 | L24: 23561326X | M24: 3 | P24: 23565633X | Q24: FJALLRAVEN | R24: 23565 | S24: Kanken No.2 | T24: 633 | U24: Dark Olive | V24: X | W24: 20000 | X24: 1 | Z24: 23508560X | AA24: 1
B25: 23561600X | C25: FJALLRAVEN | D25: 23561 | E25: Kanken Mini | F25: 600 | G25: Mint Green | H25: X | I25: 12000 | J25: -1 | L25: 23710031X | M25: 1 | P25: 23345550X | Q25: FJALLRAVEN | R25: 23345 | S25: Raven 28 | T25: 550 | U25: Black | V25: X | W25: 19000 | X25: 1 | Z25: 23322633X | AA25: 1
B26: 23510021X | C26: FJALLRAVEN | D26: 23510 | E26: Kanken | F26: 21 | G26: Fog | H26: X | I26: 13000 | J26: 1 | L26: 23796664X | M26: 1 | P26: 23223207X | Q26: FJALLRAVEN | R26: 23223 | S26: High Coast Hip Pack | T26: 207 | U26: Sunset Orange | V26: X | W26: 6500 | X26: 1 | Z26: 23346662X | AA26: 0
B27: 23510501X | C27: FJALLRAVEN | D27: 23510 | E27: Kanken | F27: 501 | G27: Sky blue | H27: X | I27: 13000 | J27: 1 | L27: 23796221X | M27: 1 | P27: 23508560X | Q27: FJALLRAVEN | R27: 23508 | S27: Kanken Organizer | T27: 560 | U27: Navy | V27: X | W27: 5500 | X27: 1 | Z27: 23226333X | AA27: 1
B28: 23561457-916X | C28: FJALLRAVEN | D28: 23561 | E28: Kanken Mini | F28: 457-916 | G28: Pastel Lavender-Confetti Pattern | H28: X | I28: 12000 | J28: 1 | L28: 23561501X | M28: -1 | P28: 23322633X | Q28: FJALLRAVEN | R28: 23322 | S28: Singi Stubben | T28: 633 | U28: Dark Olive | V28: X | W28: 42000 | X28: 1 | Z28: 23781550X | AA28: 1
B29: 23561326X | C29: FJALLRAVEN | D29: 23561 | E29: Kanken Mini | F29: 326 | G29: Ox Red | H29: X | I29: 12000 | J29: 1 | L29: 23561501-115X | M29: 0 | P29: 23510021X | Q29: FJALLRAVEN | R29: 23510 | S29: Kanken | T29: 21 | U29: Fog | V29: X | W29: 13000 | X29: 1 | Z29: 23565238X | AA29: 1
B30: 23710031X | C30: FJALLRAVEN | D30: 23710 | E30: Kanken Totepack | F30: 31 | G30: Graphite | H30: X | I30: 15000 | J30: 1 | L30: 23796031X | M30: 1 | P30: 23510550X | Q30: FJALLRAVEN | R30: 23510 | S30: Kanken | T30: 550 | U30: Black | V30: X | W30: 13000 | X30: 1 | Z30: 23200251021X | AA30: 1
B31: 23796664X | C31: FJALLRAVEN | D31: 23796 | E31: Kanken Hip Pack | F31: 664 | G31: Frost Green | H31: X | I31: 8000 | J31: 1 | L31: 23561457X | M31: 2 | P31: 23346662X | Q31: FJALLRAVEN | R31: 23346 | S31: Skule 28 | T31: 662 | U31: Deep Forest | V31: X | W31: 14000 | X31: 1 | Z31: 総計 | AA31: 28
B32: 23796221X | C32: FJALLRAVEN | D32: 23796 | E32: Kanken Hip Pack | F32: 221 | G32: Clay | H32: X | I32: 8000 | J32: 1 | L32: 23524160X | M32: 1 | P32: 23346550X | Q32: FJALLRAVEN | R32: 23346 | S32: Skule 28 | T32: 550 | U32: Black | V32: X | W32: 14000 | X32: 1
B33: 23346050X | C33: FJALLRAVEN | D33: 23346 | E33: Skule 28 | F33: 50 | G33: Basalt | H33: X | I33: 14000 | J33: 1 | L33: 23796560X | M33: 1 | P33: 23226333X | Q33: FJALLRAVEN | R33: 23226 | S33: High Coast Pocket | T33: 333 | U33: Rowan Red | V33: X | W33: 5000 | X33: 1
B34: 23561501X | C34: FJALLRAVEN | D34: 23561 | E34: Kanken Mini | F34: 501 | G34: Sky blue | H34: X | I34: 12000 | J34: -1 | L34: 23345550-550X | M34: 1 | P34: 23505560X | Q34: FJALLRAVEN | R34: 23505 | S34: Kanken Shoulder Pads | T34: 560 | U34: Navy | V34: X | W34: 3500 | X34: 1
B35: 23561312X | C35: FJALLRAVEN | D35: 23561 | E35: Kanken Mini | F35: 312 | G35: Pink | H35: X | I35: 12000 | J35: -1 | L35: 23345357X | M35: 1 | P35: 23796424X | Q35: FJALLRAVEN | R35: 23796 | S35: Kanken Hip Pack | T35: 424 | U35: Blackberry | V35: X | W35: 8000 | X35: 1
B36: 23561501-115X | C36: FJALLRAVEN | D36: 23561 | E36: Kanken Mini | F36: 501-115 | G36: Sky Blue-Light Oak | H36: X | I36: 12000 | J36: 1 | L36: 23510160X | M36: 1
B37: 23797031X | C37: FJALLRAVEN | D37: 23797 | E37: Kanken Sling | F37: 31 | G37: GRAPHITE | H37: X | I37: 10500 | J37: 1 | L37: 23223543X | M37: 1
B38: 23796031X | C38: FJALLRAVEN | D38: 23796 | E38: Kanken Hip Pack | F38: 31 | G38: Graphite | H38: X | I38: 8000 | J38: 1 | L38: 23349662X | M38: 1
B39: 23344550X | C39: FJALLRAVEN | D39: 23344 | E39: Raven 20 | F39: 550 | G39: Black | H39: X | I39: 16000 | J39: 1 | L39: 23200330016X | M39: 1
B40: 23561457X | C40: FJALLRAVEN | D40: 23561 | E40: Kanken Mini | F40: 457 | G40: Pastel Lavender | H40: X | I40: 12000 | J40: 2 | L40: 23223623X | M40: 1
...

Sheet EC_ORDER
A1: 日付 | B1: 注文時間 | C1: 注文番号 | D1: 決済方法(ステータス) | E1: 注文者 | F1: 注文者電話番号 | G1: 注文者電話番号 緊急時連絡先 | H1: 緊急時連絡先2 | I1: 注文者の住所 | J1: 受取人 | K1: 受取人の電話番号 | L1: 住所 | M1: 郵便番号 | N1: 商品名 | O1: 個数 | P1: 商品価格 | Q1: ポイント | R1: 商品コード | S1: 独自商品コード | T1: オプション独自コード | U1: JANコード | V1: 決済方法 | W1: 支払金額 | X1: 送料 | Y1: 代金引換決済方法 | Z1: 代金引換手数料 | AA1: 利用ポイント | AB1: 消費税 | AC1: 消費税率 | AD1: 利用GMOポイント | AE1: 優待会員特典 | AF1: 配送先ごとの金額 | AG1: 配送方法 | AH1: 配送希望日 | AI1: 出荷予定日 | AJ1: 配送希望時間帯 | AK1: 配送日 | AL1: 伝票番号 | AM1: 注文メッセージ | AN1: 配送メッセージ | AO1: メッセージ | AP1: メモ
A2: 46204 | B2: 123737 | C2: P186948209336569367 | D2: PGクレジットカード [決済完了] | E2: 松原由未子 | F2: 070-8340-6798 | G2: 7083406798 | I2: (192-0066) 東京都八王子市本町31-9 | J2: 松原由未子 | K2: 070-8340-6798 | L2: 東京都八王子市本町31-9 | M2: 192-0066 | N2: Kanken Laptop 15 | O2: 1 | P2: 19800 | Q2: 1980 | R2: 000000001143 | S2: 23524 | T2: 23524046X | V2: PGクレジットカード | W2: 20350 | X2: 550 | Z2: 0 | AA2: 0 | AB2: 0 | AC2: 10 | AD2: 0 | AE2: 0 | AG2: 佐川急便 | AM2: 伝達メッセージ : | AO2: 伝達メッセージ :
A3: 46204 | B3: 084011 | C3: P186946715506715034 | D3: Amazon Pay [決済完了] | E3: 井原裕樹 | F3: 080-6146-8353 | G3: 8061468353 | I3: (595-0805) 大阪府泉北郡忠岡町忠岡東1丁目22-13 忠岡グリーンハイツ 6-L | J3: 井原裕樹 | K3: 080-6146-8353 | L3: 大阪府泉北郡忠岡町忠岡東1丁目22-13 忠岡グリーンハイツ 6-L | M3: 595-0805 | N3: Abisko Wool Logo SS M | O3: 1 | P3: 12100 | Q3: 1210 | R3: 000000001465 | S3: 86977 | T3: 86977550M | V3: Amazon Pay | W3: 22440 | X3: 550 | Z3: 0 | AA3: 0 | AB3: 0 | AC3: 10 | AD3: 0 | AE3: 0 | AG3: 佐川急便 | AM3: 伝達メッセージ : | AO3: 伝達メッセージ :
A4: 46204 | B4: 084011 | C4: P186946715506715034 | D4: Amazon Pay [決済完了] | E4: 井原裕樹 | F4: 080-6146-8353 | G4: 8061468353 | I4: (595-0805) 大阪府泉北郡忠岡町忠岡東1丁目22-13 忠岡グリーンハイツ 6-L | J4: 井原裕樹 | K4: 080-6146-8353 | L4: 大阪府泉北郡忠岡町忠岡東1丁目22-13 忠岡グリーンハイツ 6-L | M4: 595-0805 | N4: Multicolor Logo T-shirt M | O4: 1 | P4: 9790 | Q4: 979 | R4: 000000001734 | S4: 12600268 | T4: 12600268244M | V4: Amazon Pay | W4: 22440 | X4: 550 | Z4: 0 | AA4: 0 | AB4: 0 | AC4: 10 | AD4: 0 | AE4: 0 | AG4: 佐川急便 | AM4: 伝達メッセージ : | AO4: 伝達メッセージ :
A5: 46204 | B5: 082508 | C5: P186946620811731880 | D5: PayPay [決済完了] | E5: 井亦伶 | F5: 090-8097-8515 | G5: 9080978515 | I5: (937-0816) 富山県魚津市大海寺野855-8 | J5: 井亦伶 | K5: 090-8097-8515 | L5: 富山県魚津市大海寺野855-8 | M5: 937-0816 | N5: Kanken 16L (Frost Green 664) | O5: 1 | P5: 14300 | Q5: 1430 | R5: 000000000897 | S5: 23510 | T5: 23510664X | V5: PayPay | W5: 14850 | X5: 550 | Z5: 0 | AA5: 0 | AB5: 0 | AC5: 10 | AD5: 0 | AE5: 0 | AG5: 佐川急便 | AM5: 伝達メッセージ : | AO5: 伝達メッセージ :
A6: 46204 | B6: 002517 | C6: P186943601856493114 | D6: PayPay [決済完了] | E6: Indri | F6: 070-9036-5335 | G6: 7090365335 | I6: (635-0832) 奈良県北葛城郡広陵町馬見中5丁目1番1号アーバンハイツ真美201 | J6: Indri | K6: 070-9036-5335 | L6: 奈良県北葛城郡広陵町馬見中5丁目1番1号アーバンハイツ真美201 | M6: 635-0832 | N6: Kanken Totepack | O6: 1 | P6: 16500 | Q6: 1650 | R6: 000000000594 | S6: 23710 | T6: 23710550X | V6: PayPay | W6: 17050 | X6: 550 | Z6: 0 | AA6: 0 | AB6: 0 | AC6: 10 | AD6: 0 | AE6: 0 | AG6: 佐川急便 | AM6: 伝達メッセージ : | AO6: 伝達メッセージ :
A7: 46203 | B7: 234528 | C7: P186943351358138473 | D7: PayPay [決済完了] | E7: SameerDeshmukh | F7: 070-4465-5316 | G7: 7044655316 | I7: (210-0011) 神奈川県川崎市川崎区富士見１丁目６番１５-２０９ | J7: SameerDeshmukh | K7: 070-4465-5316 | L7: 神奈川県川崎市川崎区富士見１丁目６番１５-２０９ | M7: 210-0011 | N7: High Coast Totepack | O7: 1 | P7: 14300 | Q7: 1430 | R7: 000000000802 | S7: 23225 | T7: 23225424X | V7: PayPay | W7: 14850 | X7: 550 | Z7: 0 | AA7: 0 | AB7: 0 | AC7: 10 | AD7: 0 | AE7: 0 | AG7: 佐川急便 | AM7: 伝達メッセージ : | AO7: 伝達メッセージ :
A8: 46203 | B8: 234423 | C8: P186943344623497308 | D8: Amazon Pay [要確認] | E8: SameerDeshmukh | F8: 070-4465-5316 | G8: 7044655316 | I8: (210-0011) 神奈川県川崎市川崎区富士見１丁目６番１５-２０９ | J8: デシュムクサミーア | K8: 070-4465-5316 | L8: 神奈川県川崎市川崎区富士見１丁目６番１５ コンフォーレ川崎富士見５棟 ２０９ | M8: 210-0011 | N8: High Coast Totepack | O8: 1 | P8: 14300 | Q8: 1430 | R8: 000000000802 | S8: 23225 | T8: 23225424X | V8: Amazon Pay | W8: 14850 | X8: 550 | Z8: 0 | AA8: 0 | AB8: 0 | AC8: 10 | AD8: 0 | AE8: 0 | AG8: 佐川急便 | AM8: 伝達メッセージ : | AO8: 伝達メッセージ :
A9: 46203 | B9: 222006 | C9: P186942814264413677 | D9: Amazon Pay [決済完了] | E9: 白須政人 | F9: 080-6588-6230 | G9: 8065886230 | I9: (402-0032) 山梨県都留市 鹿留１０９９－２ | J9: 白須政人 | K9: 080-6588-6230 | L9: 山梨県都留市 鹿留１０９９－２ | M9: 402-0032 | N9: Kanken 16L (Navy 560) | O9: 1 | P9: 14300 | Q9: 1430 | R9: 000000000882 | S9: 23510 | T9: 23510560X | V9: Amazon Pay | W9: 14850 | X9: 550 | Z9: 0 | AA9: 0 | AB9: 0 | AC9: 10 | AD9: 0 | AE9: 0 | AG9: 佐川急便 | AM9: 伝達メッセージ : | AO9: 伝達メッセージ :
A10: 46203 | B10: 220720 | C10: P186942733978574865 | D10: PGクレジットカード [決済完了] | E10: 中川文江 | F10: 090-9033-4798 | G10: 9090334798 | I10: (999-3716) 山形県東根市蟹沢1447-14 | J10: 中川文江 | K10: 090-9033-4798 | L10: 山形県東根市蟹沢1447-14 | M10: 999-3716 | N10: Keb Trekking Belt | O10: 1 | P10: 5280 | Q10: 528 | R10: 000000000210 | S10: 77316 | T10: 77316633X | V10: PGクレジットカード | W10: 45338 | X10: 550 | Z10: 0 | AA10: -3062 | AB10: 0 | AC10: 10 | AD10: 0 | AE10: 0 | AG10: 佐川急便 | AM10: 伝達メッセージ : | AO10: 伝達メッセージ :
A11: 46203 | B11: 220720 | C11: P186942733978574865 | D11: PGクレジットカード [決済完了] | E11: 中川文江 | F11: 090-9033-4798 | G11: 9090334798 | I11: (999-3716) 山形県東根市蟹沢1447-14 | J11: 中川文江 | K11: 090-9033-4798 | L11: 山形県東根市蟹沢1447-14 | M11: 999-3716 | N11: Marlin Mosquito Hat | O11: 1 | P11: 7370 | Q11: 737 | R11: 000000001244 | S11: 79339 | T11: 79339030M | V11: PGクレジットカード | W11: 45338 | X11: 550 | Z11: 0 | AA11: -3062 | AB11: 0 | AC11: 10 | AD11: 0 | AE11: 0 | AG11: 佐川急便 | AM11: 伝達メッセージ : | AO11: 伝達メッセージ :
A12: 46203 | B12: 220720 | C12: P186942733978574865 | D12: PGクレジットカード [決済完了] | E12: 中川文江 | F12: 090-9033-4798 | G12: 9090334798 | I12: (999-3716) 山形県東根市蟹沢1447-14 | J12: 中川文江 | K12: 090-9033-4798 | L12: 山形県東根市蟹沢1447-14 | M12: 999-3716 | N12: 【Women’s】【UPDATED】Keb Trousers W | O12: 1 | P12: 35200 | Q12: 3520 | R12: 000000001613 | S12: 86706 | T12: 86706662-62538/S | V12: PGクレジットカード | W12: 45338 | X12: 550 | Z12: 0 | AA12: -3062 | AB12: 0 | AC12: 10 | AD12: 0 | AE12: 0 | AG12: 佐川急便 | AM12: 伝達メッセージ : | AO12: 伝達メッセージ :
A13: 46203 | B13: 210659 | C13: P186942354275062894 | D13: PayPay [決済完了] | E13: 株式会社冨田工業 | F13: 090-5332-1465 | G13: 9053321465 | I13: (315-0031) 茨城県石岡市東大橋1805 | J13: 株式会社冨田工業 | K13: 090-5332-1465 | L13: 茨城県石岡市東大橋1805 | M13: 315-0031 | N13: Kanken 16L (Sky Blue 501) | O13: 1 | P13: 14300 | Q13: 1430 | R13: 000000000872 | S13: 23510 | T13: 23510501X | V13: PayPay | W13: 14850 | X13: 550 | Z13: 0 | AA13: 0 | AB13: 0 | AC13: 10 | AD13: 0 | AE13: 0 | AG13: 佐川急便 | AM13: 伝達メッセージ : | AO13: 伝達メッセージ :
... A16: 46203 | B16: 192150 | C16: P186941692737373587 | D16: Amazon Pay [決済完了] | E16: 松本健次郎 | F16: 053-485-9631 | G16: 534859631 | I16: (432-8001) 静岡県浜松市西区西山町1055-57ブライトタウン西山402 | J16: 松本健次郎 | K16: 053-485-9631 | L16: 静岡県浜松市西区西山町1055-57ブライトタウン西山402 | M16: 432-8001 | N16: Kanken 16L (Chalk Rose 302) | O16: 1 | P16: 14300 | Q16: 1430 | R16: 000000001723 | S16: 23510 | T16: 23510302X | V16: Amazon Pay | W16: 14850 | X16: 550 | Z16: 0 | AA16: 0 | AB16: 0 | AC16: 10 | AD16: 0 | AE16: 0 | AG16: 佐川急便 | AM16: 伝達メッセージ : | AO16: 伝達メッセージ :
A17: 46203 | B17: 192119 | C17: P186941775968513272 | D17: Yahoo!ショッピングPayPay残高払い [支払完了] | E17: 大内雅 | F17: 8033042628 | G17: 8033042628 | I17: (253-0105) 神奈川県高座郡寒川町岡田5-13-25メゾン・ド・フラン2 101 | J17: 大内雅 | K17: 8033042628 | L17: 神奈川県高座郡寒川町岡田5-13-25メゾン・ド・フラン2 101 | M17: 253-0105 | N17: Greenland Wax Bag | O17: 1 | P17: 3520 | Q17: 10 | R17: 000000000296 | S17: 79061 | T17: 79061X | V17: Yahoo!ショッピングPayPay残高払い | W17: 3520 | X17: 0 | Z17: 0 | AA17: 0 | AB17: 0 | AC17: 10 | AD17: 0 | AE17: 0 | AG17: 当店規定の配送方法（Yahoo!ショッピングの注文） | AM17: 伝達メッセージ : | AO17: 伝達メッセージ :
A18: 46203 | B18: 191057 | C18: P186941624301428941 | D18: Amazon Pay [決済完了] | E18: 下重智也 | F18: 090-4374-7589 | G18: 9043747589 | I18: (108-0074) 東京都港区高輪1-4-23 コスモ高輪シティーフォルム1403 | J18: 下重智也 | K18: 090-4374-7589 | L18: 東京都港区高輪1-4-23コスモ高輪シティフォルム1403 | M18: 108-0074 | N18: High Coast Wind Jacket M | O18: 1 | P18: 30250 | Q18: 3025 | R18: 000000001531 | S18: 82606 | T18: 82606232-620M | V18: Amazon Pay | W18: 24750 | X18: 550 | Z18: 0 | AA18: 0 | AB18: 0 | AC18: 10 | AD18: 0 | AE18: 0 | AG18: 佐川急便 | AM18: 伝達メッセージ : | AO18: 伝達メッセージ :
A19: 46203 | B19: 181915 | C19: P186941298978322974 | D19: Amazon Pay [決済完了] | E19: 千葉里花 | F19: 0285-84-5470 | G19: 285845470 | I19: (321-4357) 栃木県真岡市下大沼一丁目11-6 | J19: 千葉里花 | K19: 0285-84-5470 | L19: 栃木県真岡市下大沼一丁目11-6 | M19: 321-4357 | N19: Kanken 16L (Sky Blue 501) | O19: 1 | P19: 14300 | Q19: 1430 | R19: 000000000872 | S19: 23510 | T19: 23510501X | V19: Amazon Pay | W19: 14850 | X19: 550 | Z19: 0 | AA19: 0 | AB19: 0 | AC19: 10 | AD19: 0 | AE19: 0 | AG19: 佐川急便 | AM19: 伝達メッセージ : | AO19: 伝達メッセージ :
A20: 46203 | B20: 173536 | C20: P186941024353087257 | D20: PayPay [決済完了] | E20: 久野慶次 | F20: 090-1724-6514 | G20: 9017246514 | I20: (411-0041) 静岡県三島市佐野見晴台1-23-2 | J20: 久野慶次 | K20: 090-1724-6514 | L20: 静岡県三島市佐野見晴台1-23-2 | M20: 411-0041 | N20: Gift Wrapping (L) | O20: 1 | P20: 550 | Q20: 55 | R20: 000000000584 | S20: GIFT500 | T20: GIFT500 | V20: PayPay | W20: 15400 | X20: 550 | Z20: 0 | AA20: 0 | AB20: 0 | AC20: 10 | AD20: 0 | AE20: 0 | AG20: 佐川急便 | AM20: 伝達メッセージ : | AO20: 伝達メッセージ :
A21: 46203 | B21: 173536 | C21: P186941024353087257 | D21: PayPay [決済完了] | E21: 久野慶次 | F21: 090-1724-6514 | G21: 9017246514 | I21: (411-0041) 静岡県三島市佐野見晴台1-23-2 | J21: 久野慶次 | K21: 090-1724-6514 | L21: 静岡県三島市佐野見晴台1-23-2 | M21: 411-0041 | N21: Kanken 16L (Graphite 031) | O21: 1 | P21: 14300 | Q21: 1430 | R21: 000000000851 | S21: 23510 | T21: 23510031X | V21: PayPay | W21: 15400 | X21: 550 | Z21: 0 | AA21: 0 | AB21: 0 | AC21: 10 | AD21: 0 | AE21: 0 | AG21: 佐川急便 | AM21: 伝達メッセージ : | AO21: 伝達メッセージ :
A22: 46203 | B22: 173320 | C22: P186941010112151775 | D22: PayPay [要確認] | E22: 久野慶次 | F22: 090-1724-6514 | G22: 9017246514 | I22: (411-0041) 静岡県三島市佐野見晴台1-23-2 | J22: 久野慶次 | K22: 090-1724-6514 | L22: 静岡県三島市佐野見晴台1-23-2 | M22: 411-0041 | N22: Gift Wrapping (L) | O22: 1 | P22: 550 | Q22: 55 | R22: 000000000584 | S22: GIFT500 | T22: GIFT500 | V22: PayPay | W22: 15400 | X22: 550 | Z22: 0 | AA22: 0 | AB22: 0 | AC22: 10 | AD22: 0 | AE22: 0 | AG22: 佐川急便 | AM22: 伝達メッセージ : | AO22: 伝達メッセージ :
A23: 46203 | B23: 173320 | C23: P186941010112151775 | D23: PayPay [要確認] | E23: 久野慶次 | F23: 090-1724-6514 | G23: 9017246514 | I23: (411-0041) 静岡県三島市佐野見晴台1-23-2 | J23: 久野慶次 | K23: 090-1724-6514 | L23: 静岡県三島市佐野見晴台1-23-2 | M23: 411-0041 | N23: Kanken 16L (Graphite 031) | O23: 1 | P23: 14300 | Q23: 1430 | R23: 000000000851 | S23: 23510 | T23: 23510031X | V23: PayPay | W23: 15400 | X23: 550 | Z23: 0 | AA23: 0 | AB23: 0 | AC23: 10 | AD23: 0 | AE23: 0 | AG23: 佐川急便 | AM23: 伝達メッセージ : | AO23: 伝達メッセージ :
A24: 46203 | B24: 165300 | C24: P186940756332847537 | D24: 代金引換 [未入金] | E24: viarputrirahayu | F24: 070-5360-6276 | G24: 7053606276 | I24: (889-4314) 宮崎県えびの市大河平ichigokan life suport 4327-27 ebino-shi miyazaki ken | J24: viarputrirahayu | K24: 070-5360-6276 | L24: 宮崎県えびの市大河平ichigokan life suport 4327-27 ebino-shi miyazaki ken | M24: 889-4314 | N24: Kanken Laptop 15 | O24: 1 | P24: 19800 | Q24: 1980 | R24: 000000001143 | S24: 23524 | T24: 23524560X | V24: 代金引換 | W24: 20790 | X24: 550 | Z24: 440 | AA24: 0 | AB24: 0 | AC24: 10 | AD24: 0 | AE24: 0 | AG24: 佐川急便 | AM24: 伝達メッセージ : | AO24: 伝達メッセージ :
A25: 46203 | B25: 162703 | C25: P186940593147033594 | D25: PGクレジットカード [決済完了] | E25: 中島華子 | F25: 090-4275-1379 | G25: 9042751379 | I25: (652-0058) 兵庫県神戸市兵庫区菊水町6丁目1-20-807 | J25: 中島華子 | K25: 090-4275-1379 | L25: 兵庫県神戸市兵庫区菊水町6丁目1-20-807 | M25: 652-0058 | N25: Gift Wrapping (L) | O25: 1 | P25: 550 | Q25: 55 | R25: 000000000584 | S25: GIFT500 | T25: GIFT500 | V25: PGクレジットカード | W25: 15400 | X25: 550 | Z25: 0 | AA25: 0 | AB25: 0 | AC25: 10 | AD25: 0 | AE25: 0 | AG25: 佐川急便 | AM25: 伝達メッセージ : | AO25: 伝達メッセージ :
A26: 46203 | B26: 162703 | C26: P186940593147033594 | D26: PGクレジットカード [決済完了] | E26: 中島華子 | F26: 090-4275-1379 | G26: 9042751379 | I26: (652-0058) 兵庫県神戸市兵庫区菊水町6丁目1-20-807 | J26: 中島華子 | K26: 090-4275-1379 | L26: 兵庫県神戸市兵庫区菊水町6丁目1-20-807 | M26: 652-0058 | N26: Kanken 16L (Blackberry 424) | O26: 1 | P26: 14300 | Q26: 1430 | R26: 000000001481 | S26: 23510 | T26: 23510424X | V26: PGクレジットカード | W26: 15400 | X26: 550 | Z26: 0 | AA26: 0 | AB26: 0 | AC26: 10 | AD26: 0 | AE26: 0 | AG26: 佐川急便 | AM26: 伝達メッセージ : | AO26: 伝達メッセージ :
A27: 46203 | B27: 160142 | C27: P186940517637469789 | D27: Yahoo!ショッピングPayPay残高払い [支払完了] | E27: 伊藤雅章 | F27: 9069688928 | G27: 9069688928 | I27: (550-0013) 大阪府大阪市西区新町２丁目１０－１２ー403 | J27: 伊藤雅章 | K27: 9069688928 | L27: 大阪府大阪市西区新町２丁目１０－１２ー403 | M27: 550-0013 | N27: Kanken 16L (Chalk Rose 302) | O27: 1 | P27: 14300 | Q27: 10 | R27: 000000001723 | S27: 23510 | T27: 23510302X | V27: Yahoo!ショッピングPayPay残高払い | W27: 14300 | X27: 0 | Z27: 0 | AA27: 0 | AB27: 0 | AC27: 10 | AD27: 0 | AE27: 0 | AG27: 当店規定の配送方法（Yahoo!ショッピングの注文） | AM27: 伝達メッセージ : 電話させていただきました。 よろしくお願いいたします。 | AO27: 伝達メッセージ : 電話させていただきました。 よろしくお願いいたします。
A28: 46203 | B28: 153030 | C28: P186940237333588905 | D28: Amazon Pay [決済完了] | E28: 袖山桂子 | F28: 026-222-5427 | G28: 262225427 | I28: (381-0022) 長野県長野市大豆島745-12 | J28: 袖山治嗣 | K28: 090-4399-0246 | L28: 北海道札幌市中央区北五条西2-5 JRタワーホテル日航札幌気付 袖山 | M28: 060-0005 | N28: Gift Wrapping (L) | O28: 1 | P28: 550 | Q28: 55 | R28: 000000000584 | S28: GIFT500 | T28: GIFT500 | V28: Amazon Pay | W28: 15400 | X28: 550 | Z28: 0 | AA28: 0 | AB28: 0 | AC28: 10 | AD28: 0 | AE28: 0 | AG28: 佐川急便 | AM28: 伝達メッセージ : | AO28: 伝達メッセージ :
A29: 46203 | B29: 153030 | C29: P186940237333588905 | D29: Amazon Pay [決済完了] | E29: 袖山桂子 | F29: 026-222-5427 | G29: 262225427 | I29: (381-0022) 長野県長野市大豆島745-12 | J29: 袖山治嗣 | K29: 090-4399-0246 | L29: 北海道札幌市中央区北五条西2-5 JRタワーホテル日航札幌気付 袖山 | M29: 060-0005 | N29: Kanken 16L (Black 550) | O29: 1 | P29: 14300 | Q29: 1430 | R29: 000000000881 | S29: 23510 | T29: 23510550X | V29: Amazon Pay | W29: 15400 | X29: 550 | Z29: 0 | AA29: 0 | AB29: 0 | AC29: 10 | AD29: 0 | AE29: 0 | AG29: 佐川急便 | AM29: 伝達メッセージ : | AO29: 伝達メッセージ :
A30: 46203 | B30: 152329 | C30: P186940193233028634 | D30: Amazon Pay [決済完了] | E30: 田宮昌子 | F30: 0166-53-5104 | G30: 166535104 | I30: (070-0875) 北海道旭川市春光５条２丁目2-22 | J30: 田宮優衣 | K30: 090-6982-5183 | L30: 京都府京都市東山区妙法院前側町メゾンジョスラン 412 | M30: 605-0932 | N30: Kanken 16L (Navy 560) | O30: 1 | P30: 14300 | Q30: 1430 | R30: 000000000882 | S30: 23510 | T30: 23510560X | V30: Amazon Pay | W30: 14850 | X30: 550 | Z30: 0 | AA30: 0 | AB30: 0 | AC30: 10 | AD30: 0 | AE30: 0 | AG30: 佐川急便 | AM30: 伝達メッセージ : | AO30: 伝達メッセージ :
A31: 46203 | B31: 143752 | C31: P186939906199401290 | D31: PayPay [決済完了] | E31: 野田彩乃 | F31: 080-3963-1451 | G31: 8039631451 | I31: (880-0841) 宮崎県宮崎市吉村町西田甲656-5 | J31: 野田彩乃 | K31: 080-3963-1451 | L31: 宮崎県宮崎市吉村町西田甲656-5 | M31: 880-0841 | N31: Kanken Hip Pack | O31: 1 | P31: 8800 | Q31: 880 | R31: 000000000596 | S31: 23796 | T31: 23796115X | V31: PayPay | W31: 9790 | X31: 550 | Z31: 0 | AA31: 0 | AB31: 0 | AC31: 10 | AD31: 0 | AE31: 0 | AG31: 佐川急便 | AM31: 伝達メッセージ : | AO31: 伝達メッセージ :
A32: 46203 | B32: 143752 | C32: P186939906199401290 | D32: PayPay [決済完了] | E32: 野田彩乃 | F32: 080-3963-1451 | G32: 8039631451 | I32: (880-0841) 宮崎県宮崎市吉村町西田甲656-5 | J32: 野田彩乃 | K32: 080-3963-1451 | L32: 宮崎県宮崎市吉村町西田甲656-5 | M32: 880-0841 | N32: 【NEW】Gift Wrapping (M) | O32: 1 | P32: 440 | Q32: 44 | R32: 000000001472 | S32: GIFT400 | T32: GIFT400 | V32: PayPay | W32: 9790 | X32: 550 | Z32: 0 | AA32: 0 | AB32: 0 | AC32: 10 | AD32: 0 | AE32: 0 | AG32: 佐川急便 | AM32: 伝達メッセージ : | AO32: 伝達メッセージ :
A33: 46203 | B33: 133952 | C33: P186939541319158992 | D33: PGクレジットカード [決済完了] | E33: 木村世瑠奈 | F33: 080-7986-9082 | G33: 8079869082 | I33: (860-0035) 熊本県熊本市中央区呉服町2-5-6-701 | J33: 中川美啓 | K33: 090-8405-0506 | L33: 熊本県熊本市中央区坪井1-3-6-206 | M33: 860-0863 | N33: 【ミニ】Kanken Mini (Green 620) | O33: 1 | P33: 13200 | Q33: 1320 | R33: 000000001740 | S33: 23561 | T33: 23561620X | V33: PGクレジットカード | W33: 13750 | X33: 550 | Z33: 0 | AA33: 0 | AB33: 0 | AC33: 10 | AD33: 0 | AE33: 0 | AG33: 佐川急便 | AM33: 伝達メッセージ : | AO33: 伝達メッセージ :
A34: 46203 | B34: 113427 | C34: P186938752241301512 | D34: PGクレジットカード [決済完了] | E34: 平井俊介 | F34: 090-7278-0377 | G34: 9072780377 | I34: (252-1124) 神奈川県綾瀬市吉岡1968-10 | J34: 田村心 | K34: 080-9441-1125 | L34: 神奈川県横浜市旭区若葉台3-2-1320 | M34: 241-0801 | N34: Kanken 16L (Chalk Rose 302) | O34: 1 | P34: 14300 | Q34: 1430 | R34: 000000001723 | S34: 23510 | T34: 23510302X | V34: PGクレジットカード | W34: 14850 | X34: 550 | Z34: 0 | AA34: 0 | AB34: 0 | AC34: 10 | AD34: 0 | AE34: 0 | AG34: 佐川急便 | AM34: 伝達メッセージ : | AO34: 伝達メッセージ :
A35: 46203 | B35: 081414 | C35: P186937492531212070 | D35: Amazon Pay [決済完了] | E35: 井之上寿子 | F35: 042-708-9170 | G35: 427089170 | I35: (195-0073) 東京都町田市薬師台2-19-3 | J35: 井之上寿子 | K35: 042-708-9170 | L35: 東京都町田市薬師台2-19-3 | M35: 195-0073 | N35: Kanken 16L (Chalk Rose 302) | O35: 1 | P35: 14300 | Q35: 1430 | R35: 000000001723 | S35: 23510 | T35: 23510302X | V35: Amazon Pay | W35: 14850 | X35: 550 | Z35: 0 | AA35: 0 | AB35: 0 | AC35: 10 | AD35: 0 | AE35: 0 | AG35: 佐川急便 | AM35: 伝達メッセージ : | AO35: 伝達メッセージ :
A36: 46203 | B36: 065310 | C36: P186936982589581854 | D36: Amazon Pay [決済完了] | E36: 永嶋美華子 | F36: 080-3330-4037 | G36: 8033304037 | I36: (990-2423) 山形県山形市東青田2-1-7 | J36: 永嶋美華子 | K36: 080-3330-4037 | L36: 山形県山形市東青田2-1-7 | M36: 990-2423 | N36: Vardag Backpack 17 | O36: 1 | P36: 17050 | Q36: 1705 | R36: 000000001624 | S36: 23200300 | T36: 23200300354-228X | V36: Amazon Pay | W36: 17600 | X36: 550 | Z36: 0 | AA36: 0 | AB36: 0 | AC36: 10 | AD36: 0 | AE36: 0 | AG36: 佐川急便 | AM36: 伝達メッセージ : | AO36: 伝達メッセージ :
A37: 46203 | B37: 005827 | C37: P186934750900161998 | D37: PGクレジットカード [決済完了] | E37: 下山和子 | F37: 090-4754-7355 | G37: 9047547355 | I37: (371-0012) 群馬県前橋市東片貝町482 | J37: 下山和子 | K37: 090-4754-7355 | L37: 群馬県前橋市東片貝町482 | M37: 371-0012 | N37: Kanken 16L (Frost Green 664) | O37: 1 | P37: 14300 | Q37: 1430 | R37: 000000000897 | S37: 23510 | T37: 23510664X | V37: PGクレジットカード | W37: 14850 | X37: 550 | Z37: 0 | AA37: 0 | AB37: 0 | AC37: 10 | AD37: 0 | AE37: 0 | AG37: 佐川急便 | AM37: 伝達メッセージ : | AO37: 伝達メッセージ :
A38: 46202 | B38: 235918 | C38: P186934378738521684 | D38: 代金引換 [未入金] | E38: 本田美鳥 | F38: 090-3904-2870 | G38: 9039042870 | I38: (151-0072) 東京都渋谷区幡ヶ谷1-23-17-302 | J38: 本田美鳥 | K38: 090-3904-2870 | L38: 東京都渋谷区幡ヶ谷1-23-17-302 | M38: 151-0072 | N38: 【Women’s】Vardag Shorts W | O38: 1 | P38: 19800 | Q38: 1980 | R38: 000000001662 | S38: 87105 | T38: 8710503036 | V38: 代金引換 | W38: 20000 | X38: 550 | Z38: 440 | AA38: -790 | AB38: 0 | AC38: 10 | AD38: 0 | AE38: 0 | AG38: 佐川急便 | AM38: 伝達メッセージ : 木曜か土曜の18時-20時の時間指定での受け取りをお願いできればと思います | AO38: 伝達メッセージ : 木曜か土曜の18時-20時の時間指定での受け取りをお願いできればと思います
A39: 46202 | B39: 235435 | C39: P186934349043842164 | D39: PGクレジットカード [決済完了] | E39: 福田桃香 | F39: 080-5347-5352 | G39: 8053475352 | I39: (582-0029) 大阪府柏原市石川町7-24メゾンドール玉手山406号室 | J39: 福田桃香 | K39: 080-5347-5352 | L39: 大阪府柏原市石川町7-24メゾンドール玉手山406号室 | M39: 582-0029 | N39: Kanken Hip Pack | O39: 1 | P39: 8800 | Q39: 880 | R39: 000000000596 | S39: 23796 | T39: 23796312X | V39: PGクレジットカード | W39: 9350 | X39: 550 | Z39: 0 | AA39: 0 | AB39: 0 | AC39: 10 | AD39: 0 | AE39: 0 | AG39: 佐川急便 | AM39: 伝達メッセージ : | AO39: 伝達メッセージ :
A40: 46202 | B40: 234924 | C40: P186934316412265114 | D40: Amazon Pay [決済完了] | E40: 星野亜衣子 | F40: 080-6776-1140 | G40: 8067761140 | I40: (208-0032) 東京都武蔵村山市三ツ木1-25-27 | J40: 星野亜衣子 | K40: 080-6776-1140 | L40: 東京都武蔵村山市三ツ木1-25-27 | M40: 208-0032 | N40: Kanken 16L (Sky Blue 501) | O40: 1 | P40: 14300 | Q40: 1430 | R40: 000000000872 | S40: 23510 | T40: 23510501X | V40: Amazon Pay | W40: 14850 | X40: 550 | Z40: 0 | AA40: 0 | AB40: 0 | AC40: 10 | AD40: 0 | AE40: 0 | AG40: 佐川急便 | AM40: 伝達メッセージ : | AO40: 伝達メッセージ :
A41: 46202 | B41: 232651 | C41: P186934174609888011 | D41: Amazon Pay [決済完了] | E41: 辻本雄紀 | F41: 080-3783-8861 | G41: 8037838861 | I41: (158-0081) 東京都世田谷区深沢5-24-23 ルナコート等々力503号室 | J41: 辻本雄紀 | K41: 080-3783-8861 | L41: 東京都世田谷区深沢5-24-23 ルナコート等々力503号室 | M41: 158-0081 | N41: Kanken 16L (Chalk Rose 302) | O41: 1 | P41: 14300 | Q41: 1430 | R41: 000000001723 | S41: 23510 | T41: 23510302X | V41: Amazon Pay | W41: 14850 | X41: 550 | Z41: 0 | AA41: 0 | AB41: 0 | AC41: 10 | AD41: 0 | AE41: 0 | AG41: 佐川急便 | AM41: 伝達メッセージ : | AO41: 伝達メッセージ :
A42: 46202 | B42: 231110 | C42: P186934075917743692 | D42: Amazon Pay [決済完了] | E42: 後藤貴也 | F42: 042-810-0890 | G42: 428100890 | I42: (252-0104) 神奈川県相模原市緑区向原2-6-49 | J42: 後藤貴也 | K42: 042-810-0890 | L42: 神奈川県相模原市緑区向原2-6-49 | M42: 252-0104 | N42: Kanken 16L (Chalk Rose 302) | O42: 1 | P42: 14300 | Q42: 1430 | R42: 000000001723 | S42: 23510 | T42: 23510302X | V42: Amazon Pay | W42: 14850 | X42: 550 | Z42: 0 | AA42: 0 | AB42: 0 | AC42: 10 | AD42: 0 | AE42: 0 | AG42: 佐川急便 | AM42: 伝達メッセージ : | AO42: 伝達メッセージ :
...

Sheet EC_PIVOT
A1: TTL: | B1: =SUMIF(A:A,"総計",B:B) -> 284
A2: 行ラベル | B2: 合計 / 個数
A3: 23510031X | B3: 6
A4: 23510046X | B4: 4
A5: 23510160X | B5: 2
A6: 23510228X | B6: 1
A7: 23510312X | B7: 12
A8: 23510424X | B8: 4
A9: 23510457X | B9: 5
A10: 23510501-115X | B10: 5
A11: 23510501X | B11: 15
A12: 23510540X | B12: 6
A13: 23510550X | B13: 2
A14: 23510560X | B14: 3
A15: (空白)
A16: 23510126X | B16: 3
A17: 23510302X | B17: 19
A18: 23200408570-260X | B18: 1
A19: 23510600X | B19: 8
A20: 23227543X | B20: 1
A21: 23561501-115X | B21: 1
A22: 23513907X | B22: 1
A23: 23561302X | B23: 1
A24: 23323633X | B24: 1
A25: 23505228X | B25: 2
A26: 23510118X | B26: 2
A27: 23346550X | B27: 2
... A139: 23200300354-228X | B139: 1
A140: 8710503036 | B140: 1
A141: 23796312X | B141: 1
A142: 23508021X | B142: 1
A143: 23200251021X | B143: 1
A144: 23796550X | B144: 1
A145: 23510620X | B145: 1
A146: 23796560X | B146: 1
A147: 23796620X | B147: 1
A148: 23524326X | B148: 1
A149: 12600216555L | B149: 1
A150: 23711350X | B150: 1
A151: 24221030X | B151: 1
...

Sheet 計算式2026
C1: =SUBTOTAL(9,C4:C3000) -> 21102 | D1: =SUBTOTAL(9,D4:D3000) -> 4932 | E1: =SUBTOTAL(9,E4:E3000) -> 0 | F1: =SUBTOTAL(9,F4:F3000) -> 0 | G1: =SUBTOTAL(9,G4:G3000) -> 0 | H1: =SUBTOTAL(9,H4:H3000) -> 0 | I1: =SUBTOTAL(9,I4:I3000) -> 0 | J1: =SUBTOTAL(9,J4:J3000) -> 0 | K1: =SUBTOTAL(9,K4:K3000) -> 0 | R1: =SUBTOTAL(9,R4:R3000) -> 1557 | S1: =SUBTOTAL(9,S4:S3000) -> 2778 | T1: =SUBTOTAL(9,T4:T3000) -> 1572 | U1: =SUBTOTAL(9,U4:U3000) -> 1313 | V1: =SUBTOTAL(9,V4:V3000) -> 2817 | W1: =SUBTOTAL(9,W4:W3000) -> 573 | X1: =SUBTOTAL(9,X4:X3000) -> 2745 | AF1: =MATCH(AF3,pivot!4:4,0) -> 2 | AI1: =MATCH(AI3,pivot!4:4,0) -> 3 | AJ1: =MATCH(AJ3,pivot!4:4,0) -> 4 | AK1: =MATCH(AK3,pivot!4:4,0) -> 5 | AL1: =MATCH(AL3,pivot!4:4,0) -> 6 | AM1: =MATCH(AM3,pivot!4:4,0) -> 8 | AN1: =MATCH(AN3,pivot!4:4,0) -> 9 | AO1: =MATCH(AO3,pivot!4:4,0) -> #N/A | AP1: =MATCH(AP3,pivot!4:4,0) -> 7 | AQ1: =MATCH(AQ3,pivot!4:4,0) -> 10
C2: 確保 | R2: 在庫 | AE2: RETAIL
A3: 商品コード | B3: 商品名 | C3: NWA | D3: RETAIL確保 | E3: ZOZO | F3: 名古屋 | G3: 丸井web | H3: YSEC | I3: TOKYO | J3: ルクア大阪 | K3: ヒュッテ | L3: 京王新宿 | M3: 6142 | N3: 玉川高島屋 | O3: NODE | P3: 大丸心斎橋 | Q3: NARITA | R3: ZOZO | S3: 名古屋 | T3: 丸井web | U3: YSEC | V3: TOKYO | W3: ルクア大阪 | X3: ヒュッテ | Y3: 京王新宿 | Z3: 6142 | AA3: 玉川高島屋 | AB3: NODE | AC3: 大丸心斎橋 | AD3: NARITA | AE3: ZOZO | AF3: 名古屋 | AG3: 丸井web | AH3: YSEC | AI3: TOKYO | AJ3: ルクア大阪 | AK3: ヒュッテ | AL3: 京王新宿 | AM3: 6142 | AN3: 玉川高島屋 | AO3: NODE | AP3: 大丸心斎橋 | AQ3: NARITA | AR3: ZOZO | AS3: 名古屋 | AT3: 丸井web | AU3: YSEC | AV3: TOKYO | AW3: ルクア大阪 | AX3: ヒュッテ | AY3: 京王新宿 | AZ3: 6142 | BA3: 玉川高島屋 | BB3: 越一 | BC3: 大丸心斎橋 | BD3: NARITA | BE3: マイナス | BF3: R | BG3: F
A4: 02357645X | B4: Kanken Rainbow Mini | C4: 0 | D4: 0 | E4: 0 | F4: 0 | G4: 0 | H4: 0 | I4: 0 | J4: 0 | K4: 0 | R4: 0 | S4: 0 | T4: 1 | U4: 0 | V4: 0 | W4: 0 | X4: 0 | AE4: =IFERROR(VLOOKUP(A4,ZOZOOIOI!L:M,2,FALSE),0) -> 0 | AF4: =IFERROR(VLOOKUP($A4,pivot!$A:$K,計算式2026!AF$1,FALSE),0) -> 0 | AG4: =IFERROR(VLOOKUP(A4,ZOZOOIOI!Z:AA,2,FALSE),0) -> 0 | AH4: =IFERROR(VLOOKUP(A4,EC_PIVOT!A:B,2,FALSE),0) -> 0 | AI4: =IFERROR(VLOOKUP($A4,pivot!$A:$K,計算式2026!AI$1,FALSE),0) -> 0 | AJ4: =IFERROR(VLOOKUP($A4,pivot!$A:$K,計算式2026!AJ$1,FALSE),0) -> 0 | AK4: =IFERROR(VLOOKUP($A4,pivot!$A:$K,計算式2026!AK$1,FALSE),0) -> 0 | AL4: =IFERROR(VLOOKUP($A4,pivot!$A:$K,計算式2026!AL$1,FALSE),0) -> 0 | AM4: =IFERROR(VLOOKUP($A4,pivot!$A:$K,計算式2026!AM$1,FALSE),0) -> 0 | AN4: =IFERROR(VLOOKUP($A4,pivot!$A:$K,計算式2026!AN$1,FALSE),0) -> 0 | AO4: =IFERROR(VLOOKUP($A4,pivot!$A:$K,計算式2026!AO$1,FALSE),0) -> 0 | AP4: =IFERROR(VLOOKUP($A4,pivot!$A:$K,計算式2026!AP$1,FALSE),0) -> 0 | AQ4: =IFERROR(VLOOKUP($A4,pivot!$A:$K,計算式2026!AQ$1,FALSE),0) -> 0 | AR4: =E4-AE4 -> 0 | AS4: =F4-AF4 -> 0 | AT4: =G4-AG4 -> 0 | AU4: =H4-AH4 -> 0 | AV4: =I4-AI4 -> 0 | AW4: =J4-AJ4 -> 0 | AX4: =K4-AK4 -> 0 | AY4: =L4-AL4 -> 0 | ... BD4: =Q4-AQ4 -> 0 | BE4: =SUMIF(AR4:BD4,"<0",AR4:BD4) -> 0 | BF4: =IF(BE4<0,D4+BE4,D4) -> 0 | BG4: =IF(BF4<0,C4+BF4,C4) -> 0
A5: 08164205AS | B5: Ovik Organic Printed T-Shirts W | C5: 0 | D5: 0 | E5: 0 | F5: 0 | G5: 0 | H5: 0 | I5: 0 | J5: 0 | K5: 0 | R5: 0 | S5: 1 | T5: 0 | U5: 0 | V5: 0 | W5: 0 | X5: 0 | AE5: =IFERROR(VLOOKUP($A5,pivot!$A:$G,計算式2026!AE$1,FALSE),0) -> 0 | AF5: =IFERROR(VLOOKUP($A5,pivot!$A:$I,計算式2026!AF$1,FALSE),0) -> 0 | AI5: =IFERROR(VLOOKUP($A5,pivot!$A:$I,計算式2026!AI$1,FALSE),0) -> 0 | AJ5: =IFERROR(VLOOKUP($A5,pivot!$A:$I,計算式2026!AJ$1,FALSE),0) -> 0 | AK5: =IFERROR(VLOOKUP($A5,pivot!$A:$I,計算式2026!AK$1,FALSE),0) -> 0 | AL5: =IFERROR(VLOOKUP($A5,pivot!$A:$I,計算式2026!AL$1,FALSE),0) -> 0
A6: 08164509AM | B6: Ovik Organic Printed T-Shirts W | C6: 0 | D6: 0 | E6: 0 | F6: 0 | G6: 0 | H6: 0 | I6: 0 | J6: 0 | K6: 0 | R6: 0 | S6: 1 | T6: 0 | U6: 0 | V6: 1 | W6: 0 | X6: 0 | AE6: =IFERROR(VLOOKUP($A6,pivot!$A:$G,計算式2026!AE$1,FALSE),0) -> 0 | AF6: =IFERROR(VLOOKUP($A6,pivot!$A:$I,計算式2026!AF$1,FALSE),0) -> 0 | AI6: =IFERROR(VLOOKUP($A6,pivot!$A:$I,計算式2026!AI$1,FALSE),0) -> 0 | AJ6: =IFERROR(VLOOKUP($A6,pivot!$A:$I,計算式2026!AJ$1,FALSE),0) -> 0 | AK6: =IFERROR(VLOOKUP($A6,pivot!$A:$I,計算式2026!AK$1,FALSE),0) -> 0 | AL6: =IFERROR(VLOOKUP($A6,pivot!$A:$I,計算式2026!AL$1,FALSE),0) -> 0
A7: 08164509AS | B7: Ovik Organic Printed T-Shirts W | C7: 0 | D7: 0 | E7: 0 | F7: 0 | G7: 0 | H7: 0 | I7: 0 | J7: 0 | K7: 0 | R7: 0 | S7: 0 | T7: 0 | U7: 0 | V7: 0 | W7: 0 | X7: 0 | AE7: =IFERROR(VLOOKUP($A7,pivot!$A:$G,計算式2026!AE$1,FALSE),0) -> 0 | AF7: =IFERROR(VLOOKUP($A7,pivot!$A:$I,計算式2026!AF$1,FALSE),0) -> 0 | AI7: =IFERROR(VLOOKUP($A7,pivot!$A:$I,計算式2026!AI$1,FALSE),0) -> 0 | AJ7: =IFERROR(VLOOKUP($A7,pivot!$A:$I,計算式2026!AJ$1,FALSE),0) -> 0 | AK7: =IFERROR(VLOOKUP($A7,pivot!$A:$I,計算式2026!AK$1,FALSE),0) -> 0 | AL7: =IFERROR(VLOOKUP($A7,pivot!$A:$I,計算式2026!AL$1,FALSE),0) -> 0
A8: 08164509AXS | B8: Ovik Organic Printed T-Shirts W | C8: 0 | D8: 0 | E8: 0 | F8: 0 | G8: 0 | H8: 0 | I8: 0 | J8: 0 | K8: 0 | R8: 0 | S8: 1 | T8: 0 | U8: 0 | V8: 0 | W8: 0 | X8: 0 | AE8: =IFERROR(VLOOKUP($A8,pivot!$A:$G,計算式2026!AE$1,FALSE),0) -> 0 | AF8: =IFERROR(VLOOKUP($A8,pivot!$A:$I,計算式2026!AF$1,FALSE),0) -> 0 | AI8: =IFERROR(VLOOKUP($A8,pivot!$A:$I,計算式2026!AI$1,FALSE),0) -> 0 | AJ8: =IFERROR(VLOOKUP($A8,pivot!$A:$I,計算式2026!AJ$1,FALSE),0) -> 0 | AK8: =IFERROR(VLOOKUP($A8,pivot!$A:$I,計算式2026!AK$1,FALSE),0) -> 0 | AL8: =IFERROR(VLOOKUP($A8,pivot!$A:$I,計算式2026!AL$1,FALSE),0) -> 0
A9: 08180550A42 | B9: Abisko H-loft Trekking Trousers | C9: 1 | D9: 0 | E9: 0 | F9: 0 | G9: 0 | H9: 0 | I9: 0 | J9: 0 | K9: 0 | R9: 0 | S9: 0 | T9: 0 | U9: 0 | V9: 0 | W9: 0 | X9: 0 | AE9: =IFERROR(VLOOKUP($A9,pivot!$A:$G,計算式2026!AE$1,FALSE),0) -> 0 | AF9: =IFERROR(VLOOKUP($A9,pivot!$A:$I,計算式2026!AF$1,FALSE),0) -> 0 | AI9: =IFERROR(VLOOKUP($A9,pivot!$A:$I,計算式2026!AI$1,FALSE),0) -> 0 | AJ9: =IFERROR(VLOOKUP($A9,pivot!$A:$I,計算式2026!AJ$1,FALSE),0) -> 0 | AK9: =IFERROR(VLOOKUP($A9,pivot!$A:$I,計算式2026!AK$1,FALSE),0) -> 0 | AL9: =IFERROR(VLOOKUP($A9,pivot!$A:$I,計算式2026!AL$1,FALSE),0) -> 0
A10: 08180550A44 | B10: Abisko H-loft Trekking Trousers | C10: 1 | D10: 0 | E10: 0 | F10: 0 | G10: 0 | H10: 0 | I10: 0 | J10: 0 | K10: 0 | R10: 0 | S10: 0 | T10: 0 | U10: 0 | V10: 0 | W10: 0 | X10: 0 | AE10: =IFERROR(VLOOKUP($A10,pivot!$A:$G,計算式2026!AE$1,FALSE),0) -> 0 | AF10: =IFERROR(VLOOKUP($A10,pivot!$A:$I,計算式2026!AF$1,FALSE),0) -> 0 | AI10: =IFERROR(VLOOKUP($A10,pivot!$A:$I,計算式2026!AI$1,FALSE),0) -> 0 | AJ10: =IFERROR(VLOOKUP($A10,pivot!$A:$I,計算式2026!AJ$1,FALSE),0) -> 0 | AK10: =IFERROR(VLOOKUP($A10,pivot!$A:$I,計算式2026!AK$1,FALSE),0) -> 0 | AL10: =IFERROR(VLOOKUP($A10,pivot!$A:$I,計算式2026!AL$1,FALSE),0) -> 0
A11: 08186550A32 | B11: Barents Pro Stretch Trousers W | C11: 3 | D11: 0 | E11: 0 | F11: 0 | G11: 0 | H11: 0 | I11: 0 | J11: 0 | K11: 0 | R11: 0 | S11: 0 | T11: 0 | U11: 0 | V11: 0 | W11: 0 | X11: 0 | AE11: =IFERROR(VLOOKUP($A11,pivot!$A:$G,計算式2026!AE$1,FALSE),0) -> 0 | AF11: =IFERROR(VLOOKUP($A11,pivot!$A:$I,計算式2026!AF$1,FALSE),0) -> 0 | AI11: =IFERROR(VLOOKUP($A11,pivot!$A:$I,計算式2026!AI$1,FALSE),0) -> 0 | AJ11: =IFERROR(VLOOKUP($A11,pivot!$A:$I,計算式2026!AJ$1,FALSE),0) -> 0 | AK11: =IFERROR(VLOOKUP($A11,pivot!$A:$I,計算式2026!AK$1,FALSE),0) -> 0 | AL11: =IFERROR(VLOOKUP($A11,pivot!$A:$I,計算式2026!AL$1,FALSE),0) -> 0
A12: 08186550A34 | B12: Barents Pro Stretch Trousers W | C12: 1 | D12: 0 | E12: 0 | F12: 0 | G12: 0 | H12: 0 | I12: 0 | J12: 0 | K12: 0 | R12: 0 | S12: 0 | T12: 0 | U12: 0 | V12: 0 | W12: 0 | X12: 0 | AE12: =IFERROR(VLOOKUP($A12,pivot!$A:$G,計算式2026!AE$1,FALSE),0) -> 0 | AF12: =IFERROR(VLOOKUP($A12,pivot!$A:$I,計算式2026!AF$1,FALSE),0) -> 0 | AI12: =IFERROR(VLOOKUP($A12,pivot!$A:$I,計算式2026!AI$1,FALSE),0) -> 0 | AJ12: =IFERROR(VLOOKUP($A12,pivot!$A:$I,計算式2026!AJ$1,FALSE),0) -> 0 | AK12: =IFERROR(VLOOKUP($A12,pivot!$A:$I,計算式2026!AK$1,FALSE),0) -> 0 | AL12: =IFERROR(VLOOKUP($A12,pivot!$A:$I,計算式2026!AL$1,FALSE),0) -> 0
A13: 08186550A36 | B13: Barents Pro Stretch Trousers W | C13: 1 | D13: 0 | E13: 0 | F13: 0 | G13: 0 | H13: 0 | I13: 0 | J13: 0 | K13: 0 | R13: 0 | S13: 0 | T13: 0 | U13: 0 | V13: 0 | W13: 0 | X13: 0 | AE13: =IFERROR(VLOOKUP($A13,pivot!$A:$G,計算式2026!AE$1,FALSE),0) -> 0 | AF13: =IFERROR(VLOOKUP($A13,pivot!$A:$I,計算式2026!AF$1,FALSE),0) -> 0 | AI13: =IFERROR(VLOOKUP($A13,pivot!$A:$I,計算式2026!AI$1,FALSE),0) -> 0 | AJ13: =IFERROR(VLOOKUP($A13,pivot!$A:$I,計算式2026!AJ$1,FALSE),0) -> 0 | AK13: =IFERROR(VLOOKUP($A13,pivot!$A:$I,計算式2026!AK$1,FALSE),0) -> 0 | AL13: =IFERROR(VLOOKUP($A13,pivot!$A:$I,計算式2026!AL$1,FALSE),0) -> 0
A14: 21758160X | B14: Rucksack No.21 Mini | C14: 36 | D14: 0 | E14: 0 | F14: 0 | G14: 0 | H14: 0 | I14: 0 | J14: 0 | K14: 0 | R14: 0 | S14: 0 | T14: 1 | U14: 0 | V14: 0 | W14: 1 | X14: 4 | AE14: =IFERROR(VLOOKUP($A14,pivot!$A:$G,計算式2026!AE$1,FALSE),0) -> 0 | AF14: =IFERROR(VLOOKUP($A14,pivot!$A:$I,計算式2026!AF$1,FALSE),0) -> 0 | AI14: =IFERROR(VLOOKUP($A14,pivot!$A:$I,計算式2026!AI$1,FALSE),0) -> 0 | AJ14: =IFERROR(VLOOKUP($A14,pivot!$A:$I,計算式2026!AJ$1,FALSE),0) -> 0 | AK14: =IFERROR(VLOOKUP($A14,pivot!$A:$I,計算式2026!AK$1,FALSE),0) -> 0 | AL14: =IFERROR(VLOOKUP($A14,pivot!$A:$I,計算式2026!AL$1,FALSE),0) -> 0
A15: 21758320X | B15: Rucksack No.21 Mini | C15: 22 | D15: 0 | E15: 0 | F15: 0 | G15: 0 | H15: 0 | I15: 0 | J15: 0 | K15: 0 | R15: 0 | S15: 0 | T15: 1 | U15: 0 | V15: 0 | W15: 1 | X15: 3 | AE15: =IFERROR(VLOOKUP($A15,pivot!$A:$G,計算式2026!AE$1,FALSE),0) -> 0 | AF15: =IFERROR(VLOOKUP($A15,pivot!$A:$I,計算式2026!AF$1,FALSE),0) -> 0 | AI15: =IFERROR(VLOOKUP($A15,pivot!$A:$I,計算式2026!AI$1,FALSE),0) -> 0 | AJ15: =IFERROR(VLOOKUP($A15,pivot!$A:$I,計算式2026!AJ$1,FALSE),0) -> 0 | AK15: =IFERROR(VLOOKUP($A15,pivot!$A:$I,計算式2026!AK$1,FALSE),0) -> 0 | AL15: =IFERROR(VLOOKUP($A15,pivot!$A:$I,計算式2026!AL$1,FALSE),0) -> 0
A16: 21758519X | B16: Rucksack No.21 Mini | C16: 9 | D16: 0 | E16: 0 | F16: 0 | G16: 0 | H16: 0 | I16: 0 | J16: 0 | K16: 0 | R16: 0 | S16: 0 | T16: 1 | U16: 0 | V16: 0 | W16: 1 | X16: 3 | AE16: =IFERROR(VLOOKUP($A16,pivot!$A:$G,計算式2026!AE$1,FALSE),0) -> 0 | AF16: =IFERROR(VLOOKUP($A16,pivot!$A:$I,計算式2026!AF$1,FALSE),0) -> 0 | AI16: =IFERROR(VLOOKUP($A16,pivot!$A:$I,計算式2026!AI$1,FALSE),0) -> 0 | AJ16: =IFERROR(VLOOKUP($A16,pivot!$A:$I,計算式2026!AJ$1,FALSE),0) -> 0 | AK16: =IFERROR(VLOOKUP($A16,pivot!$A:$I,計算式2026!AK$1,FALSE),0) -> 0 | AL16: =IFERROR(VLOOKUP($A16,pivot!$A:$I,計算式2026!AL$1,FALSE),0) -> 0
... A967: 77279335M | B967: Singi Trekking Cap | C967: 1 | D967: 0 | E967: 0 | F967: 0 | G967: 0 | H967: 0 | I967: 0 | J967: 0 | K967: 0 | R967: 0 | S967: 0 | T967: 0 | U967: 0 | V967: 0 | W967: 0 | X967: 0 | AE967: =IFERROR(VLOOKUP($A967,pivot!$A:$G,計算式2026!AE$1,FALSE),0) -> 0 | AF967: =IFERROR(VLOOKUP($A967,pivot!$A:$I,計算式2026!AF$1,FALSE),0) -> 0 | AI967: =IFERROR(VLOOKUP($A967,pivot!$A:$I,計算式2026!AI$1,FALSE),0) -> 0 | AJ967: =IFERROR(VLOOKUP($A967,pivot!$A:$I,計算式2026!AJ$1,FALSE),0) -> 0 | AK967: =IFERROR(VLOOKUP($A967,pivot!$A:$I,計算式2026!AK$1,FALSE),0) -> 0 | AL967: =IFERROR(VLOOKUP($A967,pivot!$A:$I,計算式2026!AL$1,FALSE),0) -> 0
A968: 77280249110 | B968: Singi Belt 2.5cm | C968: 0 | D968: 0 | E968: 0 | F968: 0 | G968: 0 | H968: 0 | I968: 0 | J968: 0 | K968: 0 | R968: 0 | S968: 0 | T968: 0 | U968: 0 | V968: 1 | W968: 0 | X968: 1 | AE968: =IFERROR(VLOOKUP($A968,pivot!$A:$G,計算式2026!AE$1,FALSE),0) -> 0 | AF968: =IFERROR(VLOOKUP($A968,pivot!$A:$I,計算式2026!AF$1,FALSE),0) -> 0 | AI968: =IFERROR(VLOOKUP($A968,pivot!$A:$I,計算式2026!AI$1,FALSE),0) -> 0 | AJ968: =IFERROR(VLOOKUP($A968,pivot!$A:$I,計算式2026!AJ$1,FALSE),0) -> 0 | AK968: =IFERROR(VLOOKUP($A968,pivot!$A:$I,計算式2026!AK$1,FALSE),0) -> 0 | AL968: =IFERROR(VLOOKUP($A968,pivot!$A:$I,計算式2026!AL$1,FALSE),0) -> 0
A969: 7728024995 | B969: Singi Belt 2.5cm | C969: 1 | D969: 0 | E969: 0 | F969: 0 | G969: 0 | H969: 0 | I969: 0 | J969: 0 | K969: 0 | R969: 0 | S969: 0 | T969: 1 | U969: 0 | V969: 0 | W969: 1 | X969: 1 | AE969: =IFERROR(VLOOKUP($A969,pivot!$A:$G,計算式2026!AE$1,FALSE),0) -> 0 | AF969: =IFERROR(VLOOKUP($A969,pivot!$A:$I,計算式2026!AF$1,FALSE),0) -> 0 | AI969: =IFERROR(VLOOKUP($A969,pivot!$A:$I,計算式2026!AI$1,FALSE),0) -> 0 | AJ969: =IFERROR(VLOOKUP($A969,pivot!$A:$I,計算式2026!AJ$1,FALSE),0) -> 0 | AK969: =IFERROR(VLOOKUP($A969,pivot!$A:$I,計算式2026!AK$1,FALSE),0) -> 0 | AL969: =IFERROR(VLOOKUP($A969,pivot!$A:$I,計算式2026!AL$1,FALSE),0) -> 0
A970: 77291555X | B970: Singi Balaclava Cap | C970: 5 | D970: 0 | E970: 0 | F970: 0 | G970: 0 | H970: 0 | I970: 0 | J970: 0 | K970: 0 | R970: 0 | S970: 0 | T970: 0 | U970: 0 | V970: 0 | W970: 0 | X970: 1 | AE970: =IFERROR(VLOOKUP($A970,pivot!$A:$G,計算式2026!AE$1,FALSE),0) -> 0 | AF970: =IFERROR(VLOOKUP($A970,pivot!$A:$I,計算式2026!AF$1,FALSE),0) -> 0 | AI970: =IFERROR(VLOOKUP($A970,pivot!$A:$I,計算式2026!AI$1,FALSE),0) -> 0 | AJ970: =IFERROR(VLOOKUP($A970,pivot!$A:$I,計算式2026!AJ$1,FALSE),0) -> 0 | AK970: =IFERROR(VLOOKUP($A970,pivot!$A:$I,計算式2026!AK$1,FALSE),0) -> 0 | AL970: =IFERROR(VLOOKUP($A970,pivot!$A:$I,計算式2026!AL$1,FALSE),0) -> 0
A971: 77291633X | B971: Singi Balaclava Cap | C971: 0 | D971: 0 | E971: 0 | F971: 0 | G971: 0 | H971: 0 | I971: 0 | J971: 0 | K971: 0 | R971: 0 | S971: 0 | T971: 0 | U971: 0 | V971: 0 | W971: 0 | X971: 1 | AE971: =IFERROR(VLOOKUP($A971,pivot!$A:$G,計算式2026!AE$1,FALSE),0) -> 0 | AF971: =IFERROR(VLOOKUP($A971,pivot!$A:$I,計算式2026!AF$1,FALSE),0) -> 0 | AI971: =IFERROR(VLOOKUP($A971,pivot!$A:$I,計算式2026!AI$1,FALSE),0) -> 0 | AJ971: =IFERROR(VLOOKUP($A971,pivot!$A:$I,計算式2026!AJ$1,FALSE),0) -> 0 | AK971: =IFERROR(VLOOKUP($A971,pivot!$A:$I,計算式2026!AK$1,FALSE),0) -> 0 | AL971: =IFERROR(VLOOKUP($A971,pivot!$A:$I,計算式2026!AL$1,FALSE),0) -> 0
A972: 77294030L | B972: Singi Winter Cap | C972: 0 | D972: 0 | E972: 0 | F972: 0 | G972: 0 | H972: 0 | I972: 0 | J972: 0 | K972: 0 | R972: 0 | S972: 0 | T972: 1 | U972: 0 | V972: 0 | W972: 2 | X972: 2 | AE972: =IFERROR(VLOOKUP($A972,pivot!$A:$G,計算式2026!AE$1,FALSE),0) -> 0 | AF972: =IFERROR(VLOOKUP($A972,pivot!$A:$I,計算式2026!AF$1,FALSE),0) -> 0 | AI972: =IFERROR(VLOOKUP($A972,pivot!$A:$I,計算式2026!AI$1,FALSE),0) -> 0 | AJ972: =IFERROR(VLOOKUP($A972,pivot!$A:$I,計算式2026!AJ$1,FALSE),0) -> 0 | AK972: =IFERROR(VLOOKUP($A972,pivot!$A:$I,計算式2026!AK$1,FALSE),0) -> 0 | AL972: =IFERROR(VLOOKUP($A972,pivot!$A:$I,計算式2026!AL$1,FALSE),0) -> 0
A973: 77294030M | B973: Singi Winter Cap | C973: 0 | D973: 0 | E973: 0 | F973: 0 | G973: 0 | H973: 0 | I973: 0 | J973: 0 | K973: 0 | R973: 0 | S973: 0 | T973: 0 | U973: 0 | V973: 0 | W973: 0 | X973: 2 | AE973: =IFERROR(VLOOKUP($A973,pivot!$A:$G,計算式2026!AE$1,FALSE),0) -> 0 | AF973: =IFERROR(VLOOKUP($A973,pivot!$A:$I,計算式2026!AF$1,FALSE),0) -> 0 | AI973: =IFERROR(VLOOKUP($A973,pivot!$A:$I,計算式2026!AI$1,FALSE),0) -> 0 | AJ973: =IFERROR(VLOOKUP($A973,pivot!$A:$I,計算式2026!AJ$1,FALSE),0) -> 0 | AK973: =IFERROR(VLOOKUP($A973,pivot!$A:$I,計算式2026!AK$1,FALSE),0) -> 0 | AL973: =IFERROR(VLOOKUP($A973,pivot!$A:$I,計算式2026!AL$1,FALSE),0) -> 0
A974: 77294555L | B974: Singi Winter Cap | C974: 0 | D974: 0 | E974: 0 | F974: 0 | G974: 0 | H974: 0 | I974: 0 | J974: 0 | K974: 0 | R974: 0 | S974: 0 | T974: 1 | U974: 0 | V974: 0 | W974: 2 | X974: 1 | AE974: =IFERROR(VLOOKUP($A974,pivot!$A:$G,計算式2026!AE$1,FALSE),0) -> 0 | AF974: =IFERROR(VLOOKUP($A974,pivot!$A:$I,計算式2026!AF$1,FALSE),0) -> 0 | AI974: =IFERROR(VLOOKUP($A974,pivot!$A:$I,計算式2026!AI$1,FALSE),0) -> 0 | AJ974: =IFERROR(VLOOKUP($A974,pivot!$A:$I,計算式2026!AJ$1,FALSE),0) -> 0 | AK974: =IFERROR(VLOOKUP($A974,pivot!$A:$I,計算式2026!AK$1,FALSE),0) -> 0 | AL974: =IFERROR(VLOOKUP($A974,pivot!$A:$I,計算式2026!AL$1,FALSE),0) -> 0
A975: 77294555M | B975: Singi Winter Cap | C975: 0 | D975: 0 | E975: 0 | F975: 0 | G975: 0 | H975: 0 | I975: 0 | J975: 0 | K975: 0 | R975: 0 | S975: 0 | T975: 0 | U975: 0 | V975: 0 | W975: 0 | X975: 1 | AE975: =IFERROR(VLOOKUP($A975,pivot!$A:$G,計算式2026!AE$1,FALSE),0) -> 0 | AF975: =IFERROR(VLOOKUP($A975,pivot!$A:$I,計算式2026!AF$1,FALSE),0) -> 0 | AI975: =IFERROR(VLOOKUP($A975,pivot!$A:$I,計算式2026!AI$1,FALSE),0) -> 0 | AJ975: =IFERROR(VLOOKUP($A975,pivot!$A:$I,計算式2026!AJ$1,FALSE),0) -> 0 | AK975: =IFERROR(VLOOKUP($A975,pivot!$A:$I,計算式2026!AK$1,FALSE),0) -> 0 | AL975: =IFERROR(VLOOKUP($A975,pivot!$A:$I,計算式2026!AL$1,FALSE),0) -> 0
