Workbook

Sheet 計算式2026
C1: =SUBTOTAL(9,C4:C3000) | D1: =SUBTOTAL(9,D4:D3000) | E1: =SUBTOTAL(9,E4:E3000) | F1: =SUBTOTAL(9,F4:F3000) | G1: =SUBTOTAL(9,G4:G3000) | H1: =SUBTOTAL(9,H4:H3000) | I1: =SUBTOTAL(9,I4:I3000) | J1: =SUBTOTAL(9,J4:J3000) | K1: =SUBTOTAL(9,K4:K3000) | R1: =SUBTOTAL(9,R4:R3000) | S1: =SUBTOTAL(9,S4:S3000) | T1: =SUBTOTAL(9,T4:T3000) | U1: =SUBTOTAL(9,U4:U3000) | V1: =SUBTOTAL(9,V4:V3000) | W1: =SUBTOTAL(9,W4:W3000) | X1: =SUBTOTAL(9,X4:X3000) | AF1: =MATCH(AF3,pivot!4:4,0) | AI1: =MATCH(AI3,pivot!4:4,0) | AJ1: =MATCH(AJ3,pivot!4:4,0) | AK1: =MATCH(AK3,pivot!4:4,0) | AL1: =MATCH(AL3,pivot!4:4,0) | AM1: =MATCH(AM3,pivot!4:4,0) | AN1: =MATCH(AN3,pivot!4:4,0) | AO1: =MATCH(AO3,pivot!4:4,0) | AP1: =MATCH(AP3,pivot!4:4,0) | AQ1: =MATCH(AQ3,pivot!4:4,0)
C2: 確保 | R2: 在庫 | AE2: RETAIL
A3: 商品コード | B3: 商品名 | C3: NWA | D3: RETAIL確保 | E3: ZOZO | F3: 名古屋 | G3: 丸井web | H3: YSEC | I3: TOKYO | J3: ルクア大阪 | K3: ヒュッテ | L3: 京王新宿 | M3: 6142 | N3: 玉川高島屋 | O3: NODE | P3: 大丸心斎橋 | Q3: NARITA | R3: ZOZO | S3: 名古屋 | T3: 丸井web | U3: YSEC | V3: TOKYO | W3: ルクア大阪 | X3: ヒュッテ | Y3: 京王新宿 | Z3: 6142 | AA3: 玉川高島屋 | AB3: NODE | AC3: 大丸心斎橋 | AD3: NARITA | AE3: ZOZO | AF3: 名古屋 | AG3: 丸井web | AH3: YSEC | AI3: TOKYO | AJ3: ルクア大阪 | AK3: ヒュッテ | AL3: 京王新宿 | AM3: 6142 | AN3: 玉川高島屋 | AO3: NODE | AP3: 大丸心斎橋 | AQ3: NARITA | AR3: ZOZO | AS3: 名古屋 | AT3: 丸井web | AU3: YSEC | AV3: TOKYO | AW3: ルクア大阪 | AX3: ヒュッテ | AY3: 京王新宿 | AZ3: 6142 | BA3: 玉川高島屋 | BB3: 越一 | BC3: 大丸心斎橋 | BD3: NARITA | BE3: マイナス | BF3: R | BG3: F
A4: 02357645X | B4: Kanken Rainbow Mini | C4: 0 | D4: 0 | E4: 0 | F4: 0 | G4: 0 | H4: 0 | I4: 0 | J4: 0 | K4: 0 | R4: 0 | S4: 0 | T4: 1 | U4: 0 | V4: 0 | W4: 0 | X4: 0
A5: 08164205AS | B5: Ovik Organic Printed T-Shirts W | C5: 0 | D5: 0 | E5: 0 | F5: 0 | G5: 0 | H5: 0 | I5: 0 | J5: 0 | K5: 0 | R5: 0 | S5: 1 | T5: 0 | U5: 0 | V5: 0 | W5: 0 | X5: 0
A6: 08164509AM | B6: Ovik Organic Printed T-Shirts W | C6: 0 | D6: 0 | E6: 0 | F6: 0 | G6: 0 | H6: 0 | I6: 0 | J6: 0 | K6: 0 | R6: 0 | S6: 1 | T6: 0 | U6: 0 | V6: 1 | W6: 0 | X6: 0
A7: 08164509AS | B7: Ovik Organic Printed T-Shirts W | C7: 0 | D7: 0 | E7: 0 | F7: 0 | G7: 0 | H7: 0 | I7: 0 | J7: 0 | K7: 0 | R7: 0 | S7: 0 | T7: 0 | U7: 0 | V7: 0 | W7: 0 | X7: 0
A8: 08164509AXS | B8: Ovik Organic Printed T-Shirts W | C8: 0 | D8: 0 | E8: 0 | F8: 0 | G8: 0 | H8: 0 | I8: 0 | J8: 0 | K8: 0 | R8: 0 | S8: 1 | T8: 0 | U8: 0 | V8: 0 | W8: 0 | X8: 0
A9: 08180550A42 | B9: Abisko H-loft Trekking Trousers | C9: 1 | D9: 0 | E9: 0 | F9: 0 | G9: 0 | H9: 0 | I9: 0 | J9: 0 | K9: 0 | R9: 0 | S9: 0 | T9: 0 | U9: 0 | V9: 0 | W9: 0 | X9: 0
A10: 08180550A44 | B10: Abisko H-loft Trekking Trousers | C10: 1 | D10: 0 | E10: 0 | F10: 0 | G10: 0 | H10: 0 | I10: 0 | J10: 0 | K10: 0 | R10: 0 | S10: 0 | T10: 0 | U10: 0 | V10: 0 | W10: 0 | X10: 0
A11: 08186550A32 | B11: Barents Pro Stretch Trousers W | C11: 3 | D11: 0 | E11: 0 | F11: 0 | G11: 0 | H11: 0 | I11: 0 | J11: 0 | K11: 0 | R11: 0 | S11: 0 | T11: 0 | U11: 0 | V11: 0 | W11: 0 | X11: 0
A12: 08186550A34 | B12: Barents Pro Stretch Trousers W | C12: 1 | D12: 0 | E12: 0 | F12: 0 | G12: 0 | H12: 0 | I12: 0 | J12: 0 | K12: 0 | R12: 0 | S12: 0 | T12: 0 | U12: 0 | V12: 0 | W12: 0 | X12: 0
A13: 08186550A36 | B13: Barents Pro Stretch Trousers W | C13: 1 | D13: 0 | E13: 0 | F13: 0 | G13: 0 | H13: 0 | I13: 0 | J13: 0 | K13: 0 | R13: 0 | S13: 0 | T13: 0 | U13: 0 | V13: 0 | W13: 0 | X13: 0
A14: 21758160X | B14: Rucksack No.21 Mini | C14: 36 | D14: 0 | E14: 0 | F14: 0 | G14: 0 | H14: 0 | I14: 0 | J14: 0 | K14: 0 | R14: 0 | S14: 0 | T14: 1 | U14: 0 | V14: 0 | W14: 1 | X14: 4
A15: 21758320X | B15: Rucksack No.21 Mini | C15: 22 | D15: 0 | E15: 0 | F15: 0 | G15: 0 | H15: 0 | I15: 0 | J15: 0 | K15: 0 | R15: 0 | S15: 0 | T15: 1 | U15: 0 | V15: 0 | W15: 1 | X15: 3
... A967: 77279335M | B967: Singi Trekking Cap | C967: 1 | D967: 0 | E967: 0 | F967: 0 | G967: 0 | H967: 0 | I967: 0 | J967: 0 | K967: 0 | R967: 0 | S967: 0 | T967: 0 | U967: 0 | V967: 0 | W967: 0 | X967: 0
A968: 77280249110 | B968: Singi Belt 2.5cm | C968: 0 | D968: 0 | E968: 0 | F968: 0 | G968: 0 | H968: 0 | I968: 0 | J968: 0 | K968: 0 | R968: 0 | S968: 0 | T968: 0 | U968: 0 | V968: 1 | W968: 0 | X968: 1
A969: 7728024995 | B969: Singi Belt 2.5cm | C969: 1 | D969: 0 | E969: 0 | F969: 0 | G969: 0 | H969: 0 | I969: 0 | J969: 0 | K969: 0 | R969: 0 | S969: 0 | T969: 1 | U969: 0 | V969: 0 | W969: 1 | X969: 1
A970: 77291555X | B970: Singi Balaclava Cap | C970: 5 | D970: 0 | E970: 0 | F970: 0 | G970: 0 | H970: 0 | I970: 0 | J970: 0 | K970: 0 | R970: 0 | S970: 0 | T970: 0 | U970: 0 | V970: 0 | W970: 0 | X970: 1
A971: 77291633X | B971: Singi Balaclava Cap | C971: 0 | D971: 0 | E971: 0 | F971: 0 | G971: 0 | H971: 0 | I971: 0 | J971: 0 | K971: 0 | R971: 0 | S971: 0 | T971: 0 | U971: 0 | V971: 0 | W971: 0 | X971: 1
A972: 77294030L | B972: Singi Winter Cap | C972: 0 | D972: 0 | E972: 0 | F972: 0 | G972: 0 | H972: 0 | I972: 0 | J972: 0 | K972: 0 | R972: 0 | S972: 0 | T972: 1 | U972: 0 | V972: 0 | W972: 2 | X972: 2
A973: 77294030M | B973: Singi Winter Cap | C973: 0 | D973: 0 | E973: 0 | F973: 0 | G973: 0 | H973: 0 | I973: 0 | J973: 0 | K973: 0 | R973: 0 | S973: 0 | T973: 0 | U973: 0 | V973: 0 | W973: 0 | X973: 2
A974: 77294555L | B974: Singi Winter Cap | C974: 0 | D974: 0 | E974: 0 | F974: 0 | G974: 0 | H974: 0 | I974: 0 | J974: 0 | K974: 0 | R974: 0 | S974: 0 | T974: 1 | U974: 0 | V974: 0 | W974: 2 | X974: 1
A975: 77294555M | B975: Singi Winter Cap | C975: 0 | D975: 0 | E975: 0 | F975: 0 | G975: 0 | H975: 0 | I975: 0 | J975: 0 | K975: 0 | R975: 0 | S975: 0 | T975: 0 | U975: 0 | V975: 0 | W975: 0 | X975: 1
A976: 77295550L | B976: Singi Field Cap | C976: 0 | D976: 0 | E976: 0 | F976: 0 | G976: 0 | H976: 0 | I976: 0 | J976: 0 | K976: 0 | R976: 0 | S976: 0 | T976: 0 | U976: 0 | V976: 0 | W976: 0 | X976: 1
A977: 77295550M | B977: Singi Field Cap | C977: 0 | D977: 0 | E977: 0 | F977: 0 | G977: 0 | H977: 0 | I977: 0 | J977: 0 | K977: 0 | R977: 0 | S977: 0 | T977: 0 | U977: 0 | V977: 0 | W977: 0 | X977: 1
A978: 77295633L | B978: Singi Field Cap | C978: 0 | D978: 0 | E978: 0 | F978: 0 | G978: 0 | H978: 0 | I978: 0 | J978: 0 | K978: 0 | R978: 0 | S978: 0 | T978: 0 | U978: 0 | V978: 0 | W978: 0 | X978: 1
A979: 77295633M | B979: Singi Field Cap | C979: 0 | D979: 0 | E979: 0 | F979: 0 | G979: 0 | H979: 0 | I979: 0 | J979: 0 | K979: 0 | R979: 0 | S979: 0 | T979: 0 | U979: 0 | V979: 0 | W979: 0 | X979: 1
A980: 77297021X | B980: Canvas Brass Belt 4 cm | C980: 0 | D980: 0 | E980: 0 | F980: 0 | G980: 0 | H980: 0 | I980: 0 | J980: 0 | K980: 0 | R980: 0 | S980: 0 | T980: 0 | U980: 0 | V980: 0 | W980: 0 | X980: 0
A981: 77297032X | B981: Canvas Brass Belt 4 cm | C981: 34 | D981: 0 | E981: 0 | F981: 0 | G981: 0 | H981: 0 | I981: 0 | J981: 0 | K981: 0 | R981: 1 | S981: 2 | T981: 1 | U981: 0 | V981: 3 | W981: 0 | X981: 1
... A1132: 80522646-555146 | B1132: Kids Singi Fleece Jacket | C1132: 0 | D1132: 0 | E1132: 0 | F1132: 0 | G1132: 0 | H1132: 0 | I1132: 0 | J1132: 0 | K1132: 0 | R1132: 0 | S1132: 0 | T1132: 0 | U1132: 0 | V1132: 0 | W1132: 0 | X1132: 1
A1133: 80524550134 | B1133: Kids Keb Jacket | C1133: 0 | D1133: 0 | E1133: 0 | F1133: 0 | G1133: 0 | H1133: 0 | I1133: 0 | J1133: 0 | K1133: 0 | R1133: 0 | S1133: 0 | T1133: 1 | U1133: 0 | V1133: 0 | W1133: 0 | X1133: 1
A1134: 80524550146 | B1134: Kids Keb Jacket | C1134: 0 | D1134: 0 | E1134: 0 | F1134: 0 | G1134: 0 | H1134: 0 | I1134: 0 | J1134: 0 | K1134: 0 | R1134: 0 | S1134: 0 | T1134: 2 | U1134: 0 | V1134: 0 | W1134: 0 | X1134: 1
A1135: 80524646-555134 | B1135: Kids Keb Jacket | C1135: 0 | D1135: 0 | E1135: 0 | F1135: 0 | G1135: 0 | H1135: 0 | I1135: 0 | J1135: 0 | K1135: 0 | R1135: 0 | S1135: 0 | T1135: 1 | U1135: 0 | V1135: 0 | W1135: 0 | X1135: 1
A1136: 80524646-555146 | B1136: Kids Keb Jacket | C1136: 0 | D1136: 0 | E1136: 0 | F1136: 0 | G1136: 0 | H1136: 0 | I1136: 0 | J1136: 0 | K1136: 0 | R1136: 0 | S1136: 0 | T1136: 2 | U1136: 0 | V1136: 0 | W1136: 0 | X1136: 1
A1137: 80526525104 | B1137: Kids Trail T-Shirt | C1137: 4 | D1137: 0 | E1137: 0 | F1137: 0 | G1137: 0 | H1137: 0 | I1137: 0 | J1137: 0 | K1137: 0 | R1137: 0 | S1137: 0 | T1137: 0 | U1137: 0 | V1137: 0 | W1137: 0 | X1137: 1
A1138: 80526525110 | B1138: Kids Trail T-Shirt | C1138: 4 | D1138: 0 | E1138: 0 | F1138: 0 | G1138: 0 | H1138: 0 | I1138: 0 | J1138: 0 | K1138: 0 | R1138: 0 | S1138: 0 | T1138: 0 | U1138: 0 | V1138: 0 | W1138: 0 | X1138: 1
A1139: 80526525116 | B1139: Kids Trail T-Shirt | C1139: 4 | D1139: 0 | E1139: 0 | F1139: 0 | G1139: 0 | H1139: 0 | I1139: 0 | J1139: 0 | K1139: 0 | R1139: 0 | S1139: 0 | T1139: 0 | U1139: 0 | V1139: 0 | W1139: 0 | X1139: 1
A1140: 80526525122 | B1140: Kids Trail T-Shirt | C1140: 4 | D1140: 0 | E1140: 0 | F1140: 0 | G1140: 0 | H1140: 0 | I1140: 0 | J1140: 0 | K1140: 0 | R1140: 0 | S1140: 0 | T1140: 0 | U1140: 0 | V1140: 0 | W1140: 0 | X1140: 1
A1141: 80526525128 | B1141: Kids Trail T-Shirt | C1141: 3 | D1141: 0 | E1141: 0 | F1141: 0 | G1141: 0 | H1141: 0 | I1141: 0 | J1141: 0 | K1141: 0 | R1141: 0 | S1141: 0 | T1141: 0 | U1141: 0 | V1141: 0 | W1141: 0 | X1141: 1
...
