Workbook

Sheet RETAIL
A1: 1 | B1: 2 | C1: 3 | D1: 4 | E1: 5 | F1: 6 | G1: 7 | H1: 8 | I1: 9 | J1: 10 | K1: 11 | L1: 12 | M1: 13 | N1: 14 | O1: 15 | P1: 16 | Q1: 17 | R1: 18 | S1: 19 | T1: 20 | U1: 21 | V1: 22 | W1: 23 | X1: 24 | Y1: 25 | Z1: 26 | AA1: 27 | AB1: 28 | AC1: 29 | AD1: 30 | AE1: 31 | AF1: 32 | AG1: 33 | AH1: 34 | AI1: 35 | AJ1: 36 | AK1: 37 | AL1: 38 | AM1: 39 | AN1: 40 | AO1: 41 | AP1: 42 | AQ1: 43 | AR1: 44 | AS1: 45 | AT1: 46 | AU1: 47 | AV1: 48 | AW1: 49 | AX1: 50 | AY1: 51 | AZ1: 52 | BA1: 53 | BB1: 54 | BC1: 55 | BD1: 56 | BE1: 57 | BF1: 58 | BG1: 59 | BH1: 60 | BI1: 61 | BJ1: 69
A2: 受注番号 | B2: 納品先コード | C2: 納品先名 | D2: 商品コード | E2: 商品名 | F2: Brand | G2: NWA | H2: BULK | I2: BULK | J2: BULK | K2: BULK | L2: BULK | M2: BULK | N2: BULK | O2: BULK | P2: BULK | Q2: BULK | R2: BULK | S2: BULK | T2: BULK | U2: BULK | V2: BULK | W2: BULK | X2: BULK | Y2: BULK | Z2: BULK | AA2: BULK | AB2: BULK | AC2: 現在庫 | AD2: 現在庫 | AE2: 現在庫 | AF2: 現在庫 | AG2: 現在庫 | AH2: 現在庫 | AI2: 現在庫 | AJ2: 現在庫 | AK2: 現在庫 | AL2: 現在庫 | AM2: 現在庫 | AN2: 現在庫 | AO2: 現在庫 | AP2: 現在庫 | AQ2: 現在庫 | AR2: 現在庫 | AS2: 現在庫 | AT2: 現在庫 | AU2: 現在庫 | AV2: 現在庫 | AW2: 出荷指示数 | AX2: 出荷指示数 | AY2: 出荷指示数 | AZ2: 出荷指示数 | BA2: 出荷指示数 | BB2: 出荷指示数 | BC2: 出荷指示数 | BD2: 出荷指示数 | BE2: 出荷指示数 | BF2: 出荷指示数 | BG2: 出荷指示数 | BH2: 出荷指示数 | BI2: 出荷指示数 | BJ2: 出荷予定日
G3: NWA | H3: 納品先BULK | I3: 201050 | J3: 201127 | K3: 201223 | L3: 201236 | M3: 201268 | N3: 201499 | O3: 201549 | P3: 201684 | Q3: 201703 | R3: 201716 | S3: 201720 | T3: 201738 | U3: 201762 | AC3: 201050 | AD3: 201127 | AE3: 201223 | AF3: 201236 | AG3: 201268 | AH3: 201499 | AI3: 201549 | AJ3: 201684 | AK3: 201703 | AL3: 201716 | AM3: 201720 | AN3: 201738 | AO3: 201762 | AW3: 201050 | AX3: 201127 | AY3: 201223 | AZ3: 201236 | BA3: 201268 | BB3: 201499 | BC3: 201549 | BD3: 201684 | BE3: 201703 | BF3: 201716 | BG3: 201720 | BH3: 201738 | BI3: 201762
G4: NWA | H4: 納品先BULK | I4: ZOZO | J4: 名古屋 | K4: 丸井web | L4: YSEC | M4: TOKYO | N4: ルクア大阪 | O4: ヒュッテ | P4: 京王新宿 | Q4: 6142 | R4: 玉川高島屋 | S4: NODE | T4: 大丸心斎橋 | U4: NARITA | AC4: ZOZO | AD4: 名古屋 | AE4: 丸井web | AF4: YSEC | AG4: TOKYO | AH4: ルクア大阪 | AI4: ヒュッテ | AJ4: 京王新宿 | AK4: 6142 | AL4: 玉川高島屋 | AM4: NODE | AN4: 大丸心斎橋 | AO4: NARITA | AW4: ZOZO | AX4: 名古屋 | AY4: 丸井web | AZ4: YSEC | BA4: TOKYO | BB4: ルクア大阪 | BC4: ヒュッテ | BD4: 京王新宿 | BE4: 6142 | BF4: 玉川高島屋 | BG4: NODE | BH4: 大丸心斎橋 | BI4: NARITA
D5: 12100003210L/XL | E5: Varmland Cap | F5: FRV | G5: 0 | H5: 0 | I5: 0 | J5: 0 | K5: 0 | L5: 0 | M5: 0 | N5: 0 | O5: 0 | P5: 0 | Q5: 0 | R5: 0 | S5: 0 | T5: 0 | U5: 0 | AC5: 0 | AD5: 1 | AE5: 0 | AF5: 1 | AG5: 0 | AH5: 1 | AI5: 0 | AJ5: 0 | AK5: 0 | AL5: 0 | AM5: 0 | AN5: 0 | AO5: 0 | AW5: =order!AE4 -> 0 | AX5: =order!AF4 -> 0 | AY5: =order!AG4 -> 0 | AZ5: =order!AH4 -> 0 | BA5: =order!AI4 -> 0 | BB5: =order!AJ4 -> 0 | BC5: =order!AK4 -> 0 | BD5: =order!AL4 -> 0 | ... BI5: =order!AQ4 -> 0 | BJ5: 20260706
D6: 12100003210S/M | E6: Varmland Cap | F6: FRV | G6: 0 | H6: 0 | I6: 0 | J6: 0 | K6: 0 | L6: 0 | M6: 0 | N6: 0 | O6: 0 | P6: 0 | Q6: 0 | R6: 0 | S6: 0 | T6: 0 | U6: 0 | AC6: 0 | AD6: 1 | AE6: 0 | AF6: 1 | AG6: 0 | AH6: 1 | AI6: 1 | AJ6: 0 | AK6: 0 | AL6: 0 | AM6: 0 | AN6: 1 | AO6: 0 | AW6: =order!AE5 -> 0 | AX6: =order!AF5 -> 0 | AY6: =order!AG5 -> 0 | AZ6: =order!AH5 -> 0 | BA6: =order!AI5 -> 0 | BB6: =order!AJ5 -> 0 | BC6: =order!AK5 -> 0 | BD6: =order!AL5 -> 0 | ... BI6: =order!AQ5 -> 0 | BJ6: 20260706
D7: 12100003625L/XL | E7: Varmland Cap | F7: FRV | G7: 0 | H7: 0 | I7: 0 | J7: 0 | K7: 0 | L7: 0 | M7: 0 | N7: 0 | O7: 0 | P7: 0 | Q7: 0 | R7: 0 | S7: 0 | T7: 0 | U7: 0 | AC7: 0 | AD7: 1 | AE7: 0 | AF7: 1 | AG7: 0 | AH7: 2 | AI7: 0 | AJ7: 1 | AK7: 0 | AL7: 0 | AM7: 0 | AN7: 2 | AO7: 0 | AW7: =order!AE6 -> 0 | AX7: =order!AF6 -> 0 | AY7: =order!AG6 -> 0 | AZ7: =order!AH6 -> 0 | BA7: =order!AI6 -> 0 | BB7: =order!AJ6 -> 0 | BC7: =order!AK6 -> 0 | BD7: =order!AL6 -> 0 | ... BI7: =order!AQ6 -> 0 | BJ7: 20260706
D8: 12100003625S/M | E8: Varmland Cap | F8: FRV | G8: 0 | H8: 0 | I8: 0 | J8: 0 | K8: 0 | L8: 0 | M8: 0 | N8: 0 | O8: 0 | P8: 0 | Q8: 0 | R8: 0 | S8: 0 | T8: 0 | U8: 0 | AC8: 0 | AD8: 2 | AE8: 0 | AF8: 0 | AG8: 0 | AH8: 2 | AI8: 2 | AJ8: 2 | AK8: 0 | AL8: 2 | AM8: 0 | AN8: 1 | AO8: 0 | AW8: =order!AE7 -> 0 | AX8: =order!AF7 -> 0 | AY8: =order!AG7 -> 0 | AZ8: =order!AH7 -> 0 | BA8: =order!AI7 -> 0 | BB8: =order!AJ7 -> 0 | BC8: =order!AK7 -> 0 | BD8: =order!AL7 -> 0 | ... BI8: =order!AQ7 -> 0 | BJ8: 20260706
D9: 12100003662L/XL | E9: Varmland Cap | F9: FRV | G9: 0 | H9: 0 | I9: 0 | J9: 0 | K9: 0 | L9: 0 | M9: 0 | N9: 0 | O9: 0 | P9: 0 | Q9: 0 | R9: 0 | S9: 0 | T9: 0 | U9: 0 | AC9: 0 | AD9: 1 | AE9: 0 | AF9: 0 | AG9: 0 | AH9: 0 | AI9: 0 | AJ9: 0 | AK9: 0 | AL9: 0 | AM9: 0 | AN9: 0 | AO9: 0 | AW9: =order!AE8 -> 0 | AX9: =order!AF8 -> 0 | AY9: =order!AG8 -> 0 | AZ9: =order!AH8 -> 0 | BA9: =order!AI8 -> 0 | BB9: =order!AJ8 -> 0 | BC9: =order!AK8 -> 0 | BD9: =order!AL8 -> 0 | ... BI9: =order!AQ8 -> 0 | BJ9: 20260706
D10: 12100003662S/M | E10: Varmland Cap | F10: FRV | G10: 0 | H10: 0 | I10: 0 | J10: 0 | K10: 0 | L10: 0 | M10: 0 | N10: 0 | O10: 0 | P10: 0 | Q10: 0 | R10: 0 | S10: 0 | T10: 0 | U10: 0 | AC10: 0 | AD10: 1 | AE10: 0 | AF10: 1 | AG10: 0 | AH10: 1 | AI10: 2 | AJ10: 1 | AK10: 0 | AL10: 1 | AM10: 0 | AN10: 2 | AO10: 0 | AW10: =order!AE9 -> 0 | AX10: =order!AF9 -> 0 | AY10: =order!AG9 -> 0 | AZ10: =order!AH9 -> 0 | BA10: =order!AI9 -> 0 | BB10: =order!AJ9 -> 0 | BC10: =order!AK9 -> 0 | BD10: =order!AL9 -> 0 | ... BI10: =order!AQ9 -> 0 | BJ10: 20260706
D11: 12100004113L/XL | E11: High Coast Wind Cap | F11: FRV | G11: 0 | H11: 0 | I11: 0 | J11: 0 | K11: 0 | L11: 0 | M11: 0 | N11: 0 | O11: 0 | P11: 0 | Q11: 0 | R11: 0 | S11: 0 | T11: 0 | U11: 0 | AC11: 0 | AD11: 1 | AE11: 0 | AF11: 1 | AG11: 1 | AH11: 0 | AI11: 0 | AJ11: 1 | AK11: 0 | AL11: 1 | AM11: 0 | AN11: 0 | AO11: 0 | AW11: =order!AE10 -> 0 | AX11: =order!AF10 -> 0 | AY11: =order!AG10 -> 0 | AZ11: =order!AH10 -> 0 | BA11: =order!AI10 -> 0 | BB11: =order!AJ10 -> 0 | BC11: =order!AK10 -> 0 | BD11: =order!AL10 -> 0 | ... BI11: =order!AQ10 -> 0 | BJ11: 20260706
D12: 12100004300L/XL | E12: High Coast Wind Cap | F12: FRV | G12: 0 | H12: 0 | I12: 0 | J12: 0 | K12: 0 | L12: 0 | M12: 0 | N12: 0 | O12: 0 | P12: 0 | Q12: 0 | R12: 0 | S12: 0 | T12: 0 | U12: 0 | AC12: 0 | AD12: 1 | AE12: 0 | AF12: 0 | AG12: 0 | AH12: 0 | AI12: 0 | AJ12: 0 | AK12: 0 | AL12: 0 | AM12: 0 | AN12: 0 | AO12: 0 | AW12: =order!AE11 -> 0 | AX12: =order!AF11 -> 0 | AY12: =order!AG11 -> 0 | AZ12: =order!AH11 -> 0 | BA12: =order!AI11 -> 0 | BB12: =order!AJ11 -> 0 | BC12: =order!AK11 -> 0 | BD12: =order!AL11 -> 0 | ... BI12: =order!AQ11 -> 0 | BJ12: 20260706
D13: 12100004300S/M | E13: High Coast Wind Cap | F13: FRV | G13: 0 | H13: 0 | I13: 0 | J13: 0 | K13: 0 | L13: 0 | M13: 0 | N13: 0 | O13: 0 | P13: 0 | Q13: 0 | R13: 0 | S13: 0 | T13: 0 | U13: 0 | AC13: 0 | AD13: 1 | AE13: 0 | AF13: 2 | AG13: 0 | AH13: 2 | AI13: 0 | AJ13: 0 | AK13: 0 | AL13: 0 | AM13: 0 | AN13: 1 | AO13: 0 | AW13: =order!AE12 -> 0 | AX13: =order!AF12 -> 0 | AY13: =order!AG12 -> 0 | AZ13: =order!AH12 -> 0 | BA13: =order!AI12 -> 0 | BB13: =order!AJ12 -> 0 | BC13: =order!AK12 -> 0 | BD13: =order!AL12 -> 0 | ... BI13: =order!AQ12 -> 0 | BJ13: 20260706
D14: 12100004550L/XL | E14: High Coast Wind Cap | F14: FRV | G14: 0 | H14: 0 | I14: 0 | J14: 0 | K14: 0 | L14: 0 | M14: 0 | N14: 0 | O14: 0 | P14: 0 | Q14: 0 | R14: 0 | S14: 0 | T14: 0 | U14: 0 | AC14: 0 | AD14: 1 | AE14: 0 | AF14: 0 | AG14: 0 | AH14: 0 | AI14: 1 | AJ14: 1 | AK14: 0 | AL14: 0 | AM14: 0 | AN14: 0 | AO14: 0 | AW14: =order!AE13 -> 0 | AX14: =order!AF13 -> 0 | AY14: =order!AG13 -> 0 | AZ14: =order!AH13 -> 0 | BA14: =order!AI13 -> 0 | BB14: =order!AJ13 -> 0 | BC14: =order!AK13 -> 0 | BD14: =order!AL13 -> 0 | ... BI14: =order!AQ13 -> 0 | BJ14: 20260706
D15: 12100004550S/M | E15: High Coast Wind Cap | F15: FRV | G15: 0 | H15: 0 | I15: 0 | J15: 0 | K15: 0 | L15: 0 | M15: 0 | N15: 0 | O15: 0 | P15: 0 | Q15: 0 | R15: 0 | S15: 0 | T15: 0 | U15: 0 | AC15: 0 | AD15: 1 | AE15: 0 | AF15: 0 | AG15: 0 | AH15: 0 | AI15: 1 | AJ15: 2 | AK15: 0 | AL15: 0 | AM15: 0 | AN15: 0 | AO15: 0 | AW15: =order!AE14 -> 0 | AX15: =order!AF14 -> 0 | AY15: =order!AG14 -> 0 | AZ15: =order!AH14 -> 0 | BA15: =order!AI14 -> 0 | BB15: =order!AJ14 -> 0 | BC15: =order!AK14 -> 0 | BD15: =order!AL14 -> 0 | ... BI15: =order!AQ14 -> 0 | BJ15: 20260706
D16: 12100004574-118L/XL | E16: High Coast Wind Cap | F16: FRV | G16: 0 | H16: 0 | I16: 0 | J16: 0 | K16: 0 | L16: 0 | M16: 0 | N16: 0 | O16: 0 | P16: 0 | Q16: 0 | R16: 0 | S16: 0 | T16: 0 | U16: 0 | AC16: 0 | AD16: 0 | AE16: 0 | AF16: 0 | AG16: 0 | AH16: 1 | AI16: 0 | AJ16: 0 | AK16: 0 | AL16: 0 | AM16: 0 | AN16: 0 | AO16: 0 | AW16: =order!AE15 -> 0 | AX16: =order!AF15 -> 0 | AY16: =order!AG15 -> 0 | AZ16: =order!AH15 -> 0 | BA16: =order!AI15 -> 0 | BB16: =order!AJ15 -> 0 | BC16: =order!AK15 -> 0 | BD16: =order!AL15 -> 0 | ... BI16: =order!AQ15 -> 0 | BJ16: 20260706
... D28: 12200190550XS | E28: Bergtagen GTX Pro Trousers M | F28: FRV | G28: 0 | H28: 0 | I28: 0 | J28: 0 | K28: 0 | L28: 0 | M28: 0 | N28: 0 | O28: 0 | P28: 0 | Q28: 0 | R28: 0 | S28: 0 | T28: 0 | U28: 0 | AC28: 0 | AD28: 0 | AE28: 0 | AF28: 1 | AG28: 0 | AH28: 0 | AI28: 1 | AJ28: 0 | AK28: 0 | AL28: 0 | AM28: 0 | AN28: 0 | AO28: 0 | AW28: =order!AE27 -> 0 | AX28: =order!AF27 -> 0 | AY28: =order!AG27 -> 0 | AZ28: =order!AH27 -> 0 | BA28: =order!AI27 -> 0 | BB28: =order!AJ27 -> 0 | BC28: =order!AK27 -> 0 | BD28: =order!AL27 -> 0 | ... BI28: =order!AQ27 -> 0 | BJ28: 20260706
D29: 1220019755044 | E29: Hoja Hybrid Trousers M | F29: FRV | G29: 0 | H29: 5 | I29: 0 | J29: 0 | K29: 0 | L29: 0 | M29: 0 | N29: 0 | O29: 0 | P29: 0 | Q29: 0 | R29: 0 | S29: 0 | T29: 0 | U29: 0 | AC29: 0 | AD29: 1 | AE29: 0 | AF29: 1 | AG29: 1 | AH29: 1 | AI29: 0 | AJ29: 1 | AK29: 0 | AL29: 1 | AM29: 0 | AN29: 1 | AO29: 0 | AW29: =order!AE28 -> 0 | AX29: =order!AF28 -> 0 | AY29: =order!AG28 -> 0 | AZ29: =order!AH28 -> 0 | BA29: =order!AI28 -> 0 | BB29: =order!AJ28 -> 0 | BC29: =order!AK28 -> 0 | BD29: =order!AL28 -> 0 | ... BI29: =order!AQ28 -> 0 | BJ29: 20260706
D30: 1220019755046 | E30: Hoja Hybrid Trousers M | F30: FRV | G30: 1 | H30: 10 | I30: 0 | J30: 0 | K30: 0 | L30: 0 | M30: 0 | N30: 0 | O30: 0 | P30: 0 | Q30: 0 | R30: 0 | S30: 0 | T30: 0 | U30: 0 | AC30: 0 | AD30: 1 | AE30: 0 | AF30: 2 | AG30: 1 | AH30: 1 | AI30: 1 | AJ30: 1 | AK30: 0 | AL30: 1 | AM30: 0 | AN30: 1 | AO30: 0 | AW30: =order!AE29 -> 0 | AX30: =order!AF29 -> 0 | AY30: =order!AG29 -> 0 | AZ30: =order!AH29 -> 0 | BA30: =order!AI29 -> 0 | BB30: =order!AJ29 -> 0 | BC30: =order!AK29 -> 0 | BD30: =order!AL29 -> 0 | ... BI30: =order!AQ29 -> 0 | BJ30: 20260706
D31: 1220019755048 | E31: Hoja Hybrid Trousers M | F31: FRV | G31: 0 | H31: 7 | I31: 0 | J31: 0 | K31: 0 | L31: 0 | M31: 0 | N31: 0 | O31: 0 | P31: 0 | Q31: 0 | R31: 0 | S31: 0 | T31: 0 | U31: 0 | AC31: 0 | AD31: 1 | AE31: 0 | AF31: 1 | AG31: 1 | AH31: 1 | AI31: 1 | AJ31: 1 | AK31: 0 | AL31: 1 | AM31: 0 | AN31: 1 | AO31: 0 | AW31: =order!AE30 -> 0 | AX31: =order!AF30 -> 0 | AY31: =order!AG30 -> 0 | AZ31: =order!AH30 -> 0 | BA31: =order!AI30 -> 0 | BB31: =order!AJ30 -> 0 | BC31: =order!AK30 -> 0 | BD31: =order!AL30 -> 0 | ... BI31: =order!AQ30 -> 0 | BJ31: 20260706
D32: 1220019755050 | E32: Hoja Hybrid Trousers M | F32: FRV | G32: 0 | H32: 6 | I32: 0 | J32: 0 | K32: 0 | L32: 0 | M32: 0 | N32: 0 | O32: 0 | P32: 0 | Q32: 0 | R32: 0 | S32: 0 | T32: 0 | U32: 0 | AC32: 0 | AD32: 1 | AE32: 0 | AF32: 1 | AG32: 1 | AH32: 1 | AI32: 1 | AJ32: 1 | AK32: 0 | AL32: 1 | AM32: 0 | AN32: 1 | AO32: 0 | AW32: =order!AE31 -> 0 | AX32: =order!AF31 -> 0 | AY32: =order!AG31 -> 0 | AZ32: =order!AH31 -> 0 | BA32: =order!AI31 -> 0 | BB32: =order!AJ31 -> 0 | BC32: =order!AK31 -> 0 | BD32: =order!AL31 -> 0 | ... BI32: =order!AQ31 -> 0 | BJ32: 20260706
D33: 1220019755052 | E33: Hoja Hybrid Trousers M | F33: FRV | G33: 0 | H33: 0 | I33: 0 | J33: 0 | K33: 0 | L33: 0 | M33: 0 | N33: 0 | O33: 0 | P33: 0 | Q33: 0 | R33: 0 | S33: 0 | T33: 0 | U33: 0 | AC33: 0 | AD33: 0 | AE33: 0 | AF33: 1 | AG33: 1 | AH33: 0 | AI33: 0 | AJ33: 0 | AK33: 0 | AL33: 0 | AM33: 0 | AN33: 0 | AO33: 0 | AW33: =order!AE32 -> 0 | AX33: =order!AF32 -> 0 | AY33: =order!AG32 -> 0 | AZ33: =order!AH32 -> 0 | BA33: =order!AI32 -> 0 | BB33: =order!AJ32 -> 0 | BC33: =order!AK32 -> 0 | BD33: =order!AL32 -> 0 | ... BI33: =order!AQ32 -> 0 | BJ33: 20260706
D34: 1220020755046 | E34: High Coast Pack Shorts M | F34: FRV | G34: 4 | H34: 0 | I34: 0 | J34: 0 | K34: 0 | L34: 0 | M34: 0 | N34: 0 | O34: 0 | P34: 0 | Q34: 0 | R34: 0 | S34: 0 | T34: 0 | U34: 0 | AC34: 0 | AD34: 1 | AE34: 0 | AF34: 1 | AG34: 1 | AH34: 1 | AI34: 0 | AJ34: 1 | AK34: 0 | AL34: 1 | AM34: 1 | AN34: 1 | AO34: 0 | AW34: =order!AE33 -> 0 | AX34: =order!AF33 -> 0 | AY34: =order!AG33 -> 0 | AZ34: =order!AH33 -> 0 | BA34: =order!AI33 -> 0 | BB34: =order!AJ33 -> 0 | BC34: =order!AK33 -> 0 | BD34: =order!AL33 -> 0 | ... BI34: =order!AQ33 -> 0 | BJ34: 20260706
D35: 1220020755048 | E35: High Coast Pack Shorts M | F35: FRV | G35: 3 | H35: 0 | I35: 0 | J35: 0 | K35: 0 | L35: 0 | M35: 0 | N35: 0 | O35: 0 | P35: 0 | Q35: 0 | R35: 0 | S35: 0 | T35: 0 | U35: 0 | AC35: 0 | AD35: 1 | AE35: 0 | AF35: 1 | AG35: 1 | AH35: 1 | AI35: 0 | AJ35: 1 | AK35: 0 | AL35: 1 | AM35: 1 | AN35: 1 | AO35: 0 | AW35: =order!AE34 -> 0 | AX35: =order!AF34 -> 0 | AY35: =order!AG34 -> 0 | AZ35: =order!AH34 -> 0 | BA35: =order!AI34 -> 0 | BB35: =order!AJ34 -> 0 | BC35: =order!AK34 -> 0 | BD35: =order!AL34 -> 0 | ... BI35: =order!AQ34 -> 0 | BJ35: 20260706
D36: 1220020755050 | E36: High Coast Pack Shorts M | F36: FRV | G36: 2 | H36: 0 | I36: 0 | J36: 0 | K36: 0 | L36: 0 | M36: 0 | N36: 0 | O36: 0 | P36: 0 | Q36: 0 | R36: 0 | S36: 0 | T36: 0 | U36: 0 | AC36: 0 | AD36: 1 | AE36: 0 | AF36: 1 | AG36: 0 | AH36: 1 | AI36: 0 | AJ36: 1 | AK36: 0 | AL36: 1 | AM36: 1 | AN36: 1 | AO36: 0 | AW36: =order!AE35 -> 0 | AX36: =order!AF35 -> 0 | AY36: =order!AG35 -> 0 | AZ36: =order!AH35 -> 0 | BA36: =order!AI35 -> 1 | BB36: =order!AJ35 -> 0 | BC36: =order!AK35 -> 0 | BD36: =order!AL35 -> 0 | ... BI36: =order!AQ35 -> 0 | BJ36: 20260706
D37: 1220020755052 | E37: High Coast Pack Shorts M | F37: FRV | G37: 0 | H37: 0 | I37: 0 | J37: 0 | K37: 0 | L37: 0 | M37: 0 | N37: 0 | O37: 0 | P37: 0 | Q37: 0 | R37: 0 | S37: 0 | T37: 0 | U37: 0 | AC37: 0 | AD37: 1 | AE37: 0 | AF37: 1 | AG37: 1 | AH37: 1 | AI37: 0 | AJ37: 0 | AK37: 0 | AL37: 0 | AM37: 0 | AN37: 0 | AO37: 0 | AW37: =order!AE36 -> 0 | AX37: =order!AF36 -> 0 | AY37: =order!AG36 -> 0 | AZ37: =order!AH36 -> 0 | BA37: =order!AI36 -> 0 | BB37: =order!AJ36 -> 0 | BC37: =order!AK36 -> 0 | BD37: =order!AL36 -> 0 | ... BI37: =order!AQ36 -> 0 | BJ37: 20260706
D38: 1220020762546 | E38: High Coast Pack Shorts M | F38: FRV | G38: 5 | H38: 0 | I38: 0 | J38: 0 | K38: 0 | L38: 0 | M38: 0 | N38: 0 | O38: 0 | P38: 0 | Q38: 0 | R38: 0 | S38: 0 | T38: 0 | U38: 0 | AC38: 0 | AD38: 1 | AE38: 0 | AF38: 1 | AG38: 1 | AH38: 1 | AI38: 0 | AJ38: 1 | AK38: 0 | AL38: 1 | AM38: 1 | AN38: 1 | AO38: 0 | AW38: =order!AE37 -> 0 | AX38: =order!AF37 -> 0 | AY38: =order!AG37 -> 0 | AZ38: =order!AH37 -> 0 | BA38: =order!AI37 -> 0 | BB38: =order!AJ37 -> 0 | BC38: =order!AK37 -> 0 | BD38: =order!AL37 -> 0 | ... BI38: =order!AQ37 -> 0 | BJ38: 20260706
D39: 1220020762548 | E39: High Coast Pack Shorts M | F39: FRV | G39: 2 | H39: 0 | I39: 0 | J39: 0 | K39: 0 | L39: 0 | M39: 0 | N39: 0 | O39: 0 | P39: 0 | Q39: 0 | R39: 0 | S39: 0 | T39: 0 | U39: 0 | AC39: 0 | AD39: 1 | AE39: 0 | AF39: 1 | AG39: 1 | AH39: 1 | AI39: 0 | AJ39: 1 | AK39: 0 | AL39: 1 | AM39: 1 | AN39: 1 | AO39: 0 | AW39: =order!AE38 -> 0 | AX39: =order!AF38 -> 0 | AY39: =order!AG38 -> 0 | AZ39: =order!AH38 -> 0 | BA39: =order!AI38 -> 0 | BB39: =order!AJ38 -> 0 | BC39: =order!AK38 -> 0 | BD39: =order!AL38 -> 0 | ... BI39: =order!AQ38 -> 0 | BJ39: 20260706
D40: 1220020762550 | E40: High Coast Pack Shorts M | F40: FRV | G40: 3 | H40: 0 | I40: 0 | J40: 0 | K40: 0 | L40: 0 | M40: 0 | N40: 0 | O40: 0 | P40: 0 | Q40: 0 | R40: 0 | S40: 0 | T40: 0 | U40: 0 | AC40: 0 | AD40: 1 | AE40: 0 | AF40: 1 | AG40: 1 | AH40: 1 | AI40: 0 | AJ40: 1 | AK40: 0 | AL40: 1 | AM40: 1 | AN40: 1 | AO40: 0 | AW40: =order!AE39 -> 0 | AX40: =order!AF39 -> 0 | AY40: =order!AG39 -> 0 | AZ40: =order!AH39 -> 0 | BA40: =order!AI39 -> 0 | BB40: =order!AJ39 -> 0 | BC40: =order!AK39 -> 0 | BD40: =order!AL39 -> 0 | ... BI40: =order!AQ39 -> 0 | BJ40: 20260706
D41: 12200218550L | E41: Keb GTX Trousers M | F41: FRV | G41: 0 | H41: 0 | I41: 0 | J41: 0 | K41: 0 | L41: 0 | M41: 0 | N41: 0 | O41: 0 | P41: 0 | Q41: 0 | R41: 0 | S41: 0 | T41: 0 | U41: 0 | AC41: 0 | AD41: 1 | AE41: 0 | AF41: 0 | AG41: 1 | AH41: 0 | AI41: 0 | AJ41: 0 | AK41: 0 | AL41: 0 | AM41: 1 | AN41: 0 | AO41: 0 | AW41: =order!AE40 -> 0 | AX41: =order!AF40 -> 0 | AY41: =order!AG40 -> 0 | AZ41: =order!AH40 -> 0 | BA41: =order!AI40 -> 0 | BB41: =order!AJ40 -> 0 | BC41: =order!AK40 -> 0 | BD41: =order!AL40 -> 0 | ... BI41: =order!AQ40 -> 0 | BJ41: 20260706
D42: 12200218550M | E42: Keb GTX Trousers M | F42: FRV | G42: 0 | H42: 0 | I42: 0 | J42: 0 | K42: 0 | L42: 0 | M42: 0 | N42: 0 | O42: 0 | P42: 0 | Q42: 0 | R42: 0 | S42: 0 | T42: 0 | U42: 0 | AC42: 0 | AD42: 1 | AE42: 0 | AF42: 1 | AG42: 0 | AH42: 0 | AI42: 1 | AJ42: 1 | AK42: 0 | AL42: 0 | AM42: 1 | AN42: 1 | AO42: 0 | AW42: =order!AE41 -> 0 | AX42: =order!AF41 -> 0 | AY42: =order!AG41 -> 0 | AZ42: =order!AH41 -> 0 | BA42: =order!AI41 -> 0 | BB42: =order!AJ41 -> 0 | BC42: =order!AK41 -> 0 | BD42: =order!AL41 -> 0 | ... BI42: =order!AQ41 -> 0 | BJ42: 20260706
D43: 12200218550S | E43: Keb GTX Trousers M | F43: FRV | G43: 0 | H43: 0 | I43: 0 | J43: 0 | K43: 0 | L43: 0 | M43: 0 | N43: 0 | O43: 0 | P43: 0 | Q43: 0 | R43: 0 | S43: 0 | T43: 0 | U43: 0 | AC43: 0 | AD43: 1 | AE43: 0 | AF43: 0 | AG43: 0 | AH43: 1 | AI43: 0 | AJ43: 1 | AK43: 0 | AL43: 1 | AM43: 0 | AN43: 0 | AO43: 0 | AW43: =order!AE42 -> 0 | AX43: =order!AF42 -> 0 | AY43: =order!AG42 -> 0 | AZ43: =order!AH42 -> 0 | BA43: =order!AI42 -> 0 | BB43: =order!AJ42 -> 0 | BC43: =order!AK42 -> 0 | BD43: =order!AL42 -> 0 | ... BI43: =order!AQ42 -> 0 | BJ43: 20260706
D44: 12200218550XS | E44: Keb GTX Trousers M | F44: FRV | G44: 0 | H44: 0 | I44: 0 | J44: 0 | K44: 0 | L44: 0 | M44: 0 | N44: 0 | O44: 0 | P44: 0 | Q44: 0 | R44: 0 | S44: 0 | T44: 0 | U44: 0 | AC44: 0 | AD44: 1 | AE44: 0 | AF44: 1 | AG44: 1 | AH44: 1 | AI44: 1 | AJ44: 0 | AK44: 0 | AL44: 0 | AM44: 0 | AN44: 0 | AO44: 0 | AW44: =order!AE43 -> 0 | AX44: =order!AF43 -> 0 | AY44: =order!AG43 -> 0 | AZ44: =order!AH43 -> 0 | BA44: =order!AI43 -> 0 | BB44: =order!AJ43 -> 0 | BC44: =order!AK43 -> 0 | BD44: =order!AL43 -> 0 | ... BI44: =order!AQ43 -> 0 | BJ44: 20260706
D45: 12200219537L | E45: Vardag Summer Shorts M | F45: FRV | G45: 0 | H45: 0 | I45: 0 | J45: 0 | K45: 0 | L45: 0 | M45: 0 | N45: 0 | O45: 0 | P45: 0 | Q45: 0 | R45: 0 | S45: 0 | T45: 0 | U45: 0 | AC45: 0 | AD45: 0 | AE45: 0 | AF45: 1 | AG45: 0 | AH45: 0 | AI45: 0 | AJ45: 0 | AK45: 0 | AL45: 0 | AM45: 0 | AN45: 0 | AO45: 0 | AW45: =order!AE44 -> 0 | AX45: =order!AF44 -> 0 | AY45: =order!AG44 -> 0 | AZ45: =order!AH44 -> 1 | BA45: =order!AI44 -> 0 | BB45: =order!AJ44 -> 0 | BC45: =order!AK44 -> 0 | BD45: =order!AL44 -> 0 | ... BI45: =order!AQ44 -> 0 | BJ45: 20260706
D46: 12200219537M | E46: Vardag Summer Shorts M | F46: FRV | G46: 0 | H46: 0 | I46: 0 | J46: 0 | K46: 0 | L46: 0 | M46: 0 | N46: 0 | O46: 0 | P46: 0 | Q46: 0 | R46: 0 | S46: 0 | T46: 0 | U46: 0 | AC46: 0 | AD46: 0 | AE46: 0 | AF46: 1 | AG46: 1 | AH46: 1 | AI46: 0 | AJ46: 0 | AK46: 0 | AL46: 0 | AM46: 0 | AN46: 0 | AO46: 0 | AW46: =order!AE45 -> 0 | AX46: =order!AF45 -> 1 | AY46: =order!AG45 -> 0 | AZ46: =order!AH45 -> 0 | BA46: =order!AI45 -> 0 | BB46: =order!AJ45 -> 0 | BC46: =order!AK45 -> 0 | BD46: =order!AL45 -> 0 | ... BI46: =order!AQ45 -> 0 | BJ46: 20260706
D47: 12200219537S | E47: Vardag Summer Shorts M | F47: FRV | G47: 2 | H47: 0 | I47: 0 | J47: 0 | K47: 0 | L47: 0 | M47: 0 | N47: 0 | O47: 0 | P47: 0 | Q47: 0 | R47: 0 | S47: 0 | T47: 0 | U47: 0 | AC47: 0 | AD47: 1 | AE47: 0 | AF47: 1 | AG47: 1 | AH47: 1 | AI47: 0 | AJ47: 0 | AK47: 0 | AL47: 0 | AM47: 1 | AN47: 0 | AO47: 0 | AW47: =order!AE46 -> 0 | AX47: =order!AF46 -> 0 | AY47: =order!AG46 -> 0 | AZ47: =order!AH46 -> 0 | BA47: =order!AI46 -> 0 | BB47: =order!AJ46 -> 0 | BC47: =order!AK46 -> 0 | BD47: =order!AL46 -> 0 | ... BI47: =order!AQ46 -> 0 | BJ47: 20260706
D48: 12200219550L | E48: Vardag Summer Shorts M | F48: FRV | G48: 0 | H48: 0 | I48: 0 | J48: 0 | K48: 0 | L48: 0 | M48: 0 | N48: 0 | O48: 0 | P48: 0 | Q48: 0 | R48: 0 | S48: 0 | T48: 0 | U48: 0 | AC48: 0 | AD48: 1 | AE48: 0 | AF48: 1 | AG48: 1 | AH48: 1 | AI48: 0 | AJ48: 0 | AK48: 0 | AL48: 0 | AM48: 0 | AN48: 0 | AO48: 0 | AW48: =order!AE47 -> 0 | AX48: =order!AF47 -> 0 | AY48: =order!AG47 -> 0 | AZ48: =order!AH47 -> 0 | BA48: =order!AI47 -> 0 | BB48: =order!AJ47 -> 0 | BC48: =order!AK47 -> 0 | BD48: =order!AL47 -> 0 | ... BI48: =order!AQ47 -> 0 | BJ48: 20260706
D49: 12200219550M | E49: Vardag Summer Shorts M | F49: FRV | G49: 5 | H49: 0 | I49: 0 | J49: 0 | K49: 0 | L49: 0 | M49: 0 | N49: 0 | O49: 0 | P49: 0 | Q49: 0 | R49: 0 | S49: 0 | T49: 0 | U49: 0 | AC49: 0 | AD49: 1 | AE49: 0 | AF49: 1 | AG49: 1 | AH49: 1 | AI49: 0 | AJ49: 0 | AK49: 0 | AL49: 0 | AM49: 1 | AN49: 1 | AO49: 0 | AW49: =order!AE48 -> 0 | AX49: =order!AF48 -> 0 | AY49: =order!AG48 -> 0 | AZ49: =order!AH48 -> 0 | BA49: =order!AI48 -> 0 | BB49: =order!AJ48 -> 0 | BC49: =order!AK48 -> 0 | BD49: =order!AL48 -> 0 | ... BI49: =order!AQ48 -> 0 | BJ49: 20260706
D50: 12200219550S | E50: Vardag Summer Shorts M | F50: FRV | G50: 2 | H50: 0 | I50: 0 | J50: 0 | K50: 0 | L50: 0 | M50: 0 | N50: 0 | O50: 0 | P50: 0 | Q50: 0 | R50: 0 | S50: 0 | T50: 0 | U50: 0 | AC50: 0 | AD50: 1 | AE50: 0 | AF50: 1 | AG50: 1 | AH50: 1 | AI50: 0 | AJ50: 0 | AK50: 0 | AL50: 0 | AM50: 1 | AN50: 1 | AO50: 0 | AW50: =order!AE49 -> 0 | AX50: =order!AF49 -> 0 | AY50: =order!AG49 -> 0 | AZ50: =order!AH49 -> 0 | BA50: =order!AI49 -> 0 | BB50: =order!AJ49 -> 0 | BC50: =order!AK49 -> 0 | BD50: =order!AL49 -> 0 | ... BI50: =order!AQ49 -> 0 | BJ50: 20260706
D51: 12200219625L | E51: Vardag Summer Shorts M | F51: FRV | G51: 0 | H51: 0 | I51: 0 | J51: 0 | K51: 0 | L51: 0 | M51: 0 | N51: 0 | O51: 0 | P51: 0 | Q51: 0 | R51: 0 | S51: 0 | T51: 0 | U51: 0 | AC51: 0 | AD51: 0 | AE51: 0 | AF51: 1 | AG51: 0 | AH51: 0 | AI51: 0 | AJ51: 0 | AK51: 0 | AL51: 0 | AM51: 0 | AN51: 0 | AO51: 0 | AW51: =order!AE50 -> 0 | AX51: =order!AF50 -> 0 | AY51: =order!AG50 -> 0 | AZ51: =order!AH50 -> 0 | BA51: =order!AI50 -> 0 | BB51: =order!AJ50 -> 0 | BC51: =order!AK50 -> 0 | BD51: =order!AL50 -> 0 | ... BI51: =order!AQ50 -> 0 | BJ51: 20260706
...

Sheet order
C1: =SUBTOTAL(9,C4:C3500) -> 6982 | D1: =SUBTOTAL(9,D4:D3500) -> 14299 | E1: =SUBTOTAL(9,E4:E3500) -> 0 | F1: =SUBTOTAL(9,F4:F3500) -> 0 | G1: =SUBTOTAL(9,G4:G3500) -> 0 | H1: =SUBTOTAL(9,H4:H3500) -> 0 | I1: =SUBTOTAL(9,I4:I3500) -> 0 | J1: =SUBTOTAL(9,J4:J3500) -> 1 | ... AQ1: =SUBTOTAL(9,AQ4:AQ3500) -> 83
C2: 確保 | R2: 在庫 | AE2: ORDER
A3: 商品コード | B3: 商品名 | C3: NWA | D3: RETAIL確保 | E3: ZOZO | F3: 名古屋 | G3: 丸井web | H3: YSEC | I3: TOKYO | J3: ルクア大阪 | K3: ヒュッテ | L3: 京王新宿 | M3: 6142 | N3: 玉川高島屋 | O3: NODE | P3: 大丸心斎橋 | Q3: NARITA | R3: ZOZO | S3: 名古屋 | T3: 丸井web | U3: YSEC | V3: TOKYO | W3: ルクア大阪 | X3: ヒュッテ | Y3: 京王新宿 | Z3: 6142 | AA3: 玉川高島屋 | AB3: NODE | AC3: 大丸心斎橋 | AD3: NARITA | AE3: ZOZO | AF3: 名古屋 | AG3: 丸井web | AH3: YSEC | AI3: TOKYO | AJ3: ルクア大阪 | AK3: ヒュッテ | AL3: 京王新宿 | AM3: 6142 | AN3: 玉川高島屋 | AO3: NODE | AP3: 大丸心斎橋 | AQ3: NARITA | AR3: ZOZO | AS3: 名古屋 | AT3: 丸井web | AU3: YSEC | AV3: TOKYO | AW3: ルクア大阪 | AX3: ヒュッテ | AY3: 京王新宿 | AZ3: 6142 | BA3: 玉川高島屋 | BB3: 越一 | BC3: 大丸心斎橋 | BD3: NARITA | BE3: マイナス | BF3: R | BG3: 過不足
A4: 12100003210L/XL | B4: Varmland Cap | C4: 0 | D4: 0 | E4: 0 | F4: 0 | G4: 0 | H4: 0 | I4: 0 | J4: 0 | K4: 0 | L4: 0 | M4: 0 | N4: 0 | O4: 0 | P4: 0 | Q4: 0 | R4: 0 | S4: 1 | T4: 0 | U4: 1 | V4: 0 | W4: 1 | X4: 0 | Y4: 0 | Z4: 0 | AA4: 0 | AB4: 0 | AC4: 0 | AD4: 0 | AE4: 0 | AF4: 0 | AG4: 0 | AH4: 0 | AI4: 0 | AJ4: 0 | AK4: 0 | AL4: 0 | AM4: 0 | AN4: 0 | AO4: 0 | AP4: 0 | AQ4: 0 | AR4: =E4-AE4 -> 0 | AS4: =F4-AF4 -> 0 | AT4: =G4-AG4 -> 0 | AU4: =H4-AH4 -> 0 | AV4: =I4-AI4 -> 0 | AW4: =J4-AJ4 -> 0 | AX4: =K4-AK4 -> 0 | AY4: =L4-AL4 -> 0 | ... BD4: =Q4-AQ4 -> 0 | BE4: =SUMIF(AR4:BD4,"<0",AR4:BD4) -> 0 | BF4: =IF(BE4<0,D4+BE4,D4) -> 0 | BG4: =IF(BF4<0,C4+BF4,C4) -> 0
A5: 12100003210S/M | B5: Varmland Cap | C5: 0 | D5: 0 | E5: 0 | F5: 0 | G5: 0 | H5: 0 | I5: 0 | J5: 0 | K5: 0 | L5: 0 | M5: 0 | N5: 0 | O5: 0 | P5: 0 | Q5: 0 | R5: 0 | S5: 1 | T5: 0 | U5: 1 | V5: 0 | W5: 1 | X5: 1 | Y5: 0 | Z5: 0 | AA5: 0 | AB5: 0 | AC5: 1 | AD5: 0 | AE5: 0 | AF5: 0 | AG5: 0 | AH5: 0 | AI5: 0 | AJ5: 0 | AK5: 0 | AL5: 0 | AM5: 0 | AN5: 0 | AO5: 0 | AP5: 0 | AQ5: 0 | AR5: =E5-AE5 -> 0 | AS5: =F5-AF5 -> 0 | AT5: =G5-AG5 -> 0 | AU5: =H5-AH5 -> 0 | AV5: =I5-AI5 -> 0 | AW5: =J5-AJ5 -> 0 | AX5: =K5-AK5 -> 0 | AY5: =L5-AL5 -> 0 | ... BD5: =Q5-AQ5 -> 0 | BE5: =SUMIF(AR5:BD5,"<0",AR5:BD5) -> 0 | BF5: =IF(BE5<0,D5+BE5,D5) -> 0 | BG5: =IF(BF5<0,C5+BF5,C5) -> 0
A6: 12100003625L/XL | B6: Varmland Cap | C6: 0 | D6: 0 | E6: 0 | F6: 0 | G6: 0 | H6: 0 | I6: 0 | J6: 0 | K6: 0 | L6: 0 | M6: 0 | N6: 0 | O6: 0 | P6: 0 | Q6: 0 | R6: 0 | S6: 1 | T6: 0 | U6: 1 | V6: 0 | W6: 2 | X6: 0 | Y6: 1 | Z6: 0 | AA6: 0 | AB6: 0 | AC6: 2 | AD6: 0 | AE6: 0 | AF6: 0 | AG6: 0 | AH6: 0 | AI6: 0 | AJ6: 0 | AK6: 0 | AL6: 0 | AM6: 0 | AN6: 0 | AO6: 0 | AP6: 0 | AQ6: 0 | AR6: =E6-AE6 -> 0 | AS6: =F6-AF6 -> 0 | AT6: =G6-AG6 -> 0 | AU6: =H6-AH6 -> 0 | AV6: =I6-AI6 -> 0 | AW6: =J6-AJ6 -> 0 | AX6: =K6-AK6 -> 0 | AY6: =L6-AL6 -> 0 | ... BD6: =Q6-AQ6 -> 0 | BE6: =SUMIF(AR6:BD6,"<0",AR6:BD6) -> 0 | BF6: =IF(BE6<0,D6+BE6,D6) -> 0 | BG6: =IF(BF6<0,C6+BF6,C6) -> 0
A7: 12100003625S/M | B7: Varmland Cap | C7: 0 | D7: 0 | E7: 0 | F7: 0 | G7: 0 | H7: 0 | I7: 0 | J7: 0 | K7: 0 | L7: 0 | M7: 0 | N7: 0 | O7: 0 | P7: 0 | Q7: 0 | R7: 0 | S7: 2 | T7: 0 | U7: 0 | V7: 0 | W7: 2 | X7: 2 | Y7: 2 | Z7: 0 | AA7: 2 | AB7: 0 | AC7: 1 | AD7: 0 | AE7: 0 | AF7: 0 | AG7: 0 | AH7: 0 | AI7: 0 | AJ7: 0 | AK7: 0 | AL7: 0 | AM7: 0 | AN7: 0 | AO7: 0 | AP7: 0 | AQ7: 0 | AR7: =E7-AE7 -> 0 | AS7: =F7-AF7 -> 0 | AT7: =G7-AG7 -> 0 | AU7: =H7-AH7 -> 0 | AV7: =I7-AI7 -> 0 | AW7: =J7-AJ7 -> 0 | AX7: =K7-AK7 -> 0 | AY7: =L7-AL7 -> 0 | ... BD7: =Q7-AQ7 -> 0 | BE7: =SUMIF(AR7:BD7,"<0",AR7:BD7) -> 0 | BF7: =IF(BE7<0,D7+BE7,D7) -> 0 | BG7: =IF(BF7<0,C7+BF7,C7) -> 0
A8: 12100003662L/XL | B8: Varmland Cap | C8: 0 | D8: 0 | E8: 0 | F8: 0 | G8: 0 | H8: 0 | I8: 0 | J8: 0 | K8: 0 | L8: 0 | M8: 0 | N8: 0 | O8: 0 | P8: 0 | Q8: 0 | R8: 0 | S8: 1 | T8: 0 | U8: 0 | V8: 0 | W8: 0 | X8: 0 | Y8: 0 | Z8: 0 | AA8: 0 | AB8: 0 | AC8: 0 | AD8: 0 | AE8: 0 | AF8: 0 | AG8: 0 | AH8: 0 | AI8: 0 | AJ8: 0 | AK8: 0 | AL8: 0 | AM8: 0 | AN8: 0 | AO8: 0 | AP8: 0 | AQ8: 0 | AR8: =E8-AE8 -> 0 | AS8: =F8-AF8 -> 0 | AT8: =G8-AG8 -> 0 | AU8: =H8-AH8 -> 0 | AV8: =I8-AI8 -> 0 | AW8: =J8-AJ8 -> 0 | AX8: =K8-AK8 -> 0 | AY8: =L8-AL8 -> 0 | ... BD8: =Q8-AQ8 -> 0 | BE8: =SUMIF(AR8:BD8,"<0",AR8:BD8) -> 0 | BF8: =IF(BE8<0,D8+BE8,D8) -> 0 | BG8: =IF(BF8<0,C8+BF8,C8) -> 0
A9: 12100003662S/M | B9: Varmland Cap | C9: 0 | D9: 0 | E9: 0 | F9: 0 | G9: 0 | H9: 0 | I9: 0 | J9: 0 | K9: 0 | L9: 0 | M9: 0 | N9: 0 | O9: 0 | P9: 0 | Q9: 0 | R9: 0 | S9: 1 | T9: 0 | U9: 1 | V9: 0 | W9: 1 | X9: 2 | Y9: 1 | Z9: 0 | AA9: 1 | AB9: 0 | AC9: 2 | AD9: 0 | AE9: 0 | AF9: 0 | AG9: 0 | AH9: 0 | AI9: 0 | AJ9: 0 | AK9: 0 | AL9: 0 | AM9: 0 | AN9: 0 | AO9: 0 | AP9: 0 | AQ9: 0 | AR9: =E9-AE9 -> 0 | AS9: =F9-AF9 -> 0 | AT9: =G9-AG9 -> 0 | AU9: =H9-AH9 -> 0 | AV9: =I9-AI9 -> 0 | AW9: =J9-AJ9 -> 0 | AX9: =K9-AK9 -> 0 | AY9: =L9-AL9 -> 0 | ... BD9: =Q9-AQ9 -> 0 | BE9: =SUMIF(AR9:BD9,"<0",AR9:BD9) -> 0 | BF9: =IF(BE9<0,D9+BE9,D9) -> 0 | BG9: =IF(BF9<0,C9+BF9,C9) -> 0
A10: 12100004113L/XL | B10: High Coast Wind Cap | C10: 0 | D10: 0 | E10: 0 | F10: 0 | G10: 0 | H10: 0 | I10: 0 | J10: 0 | K10: 0 | L10: 0 | M10: 0 | N10: 0 | O10: 0 | P10: 0 | Q10: 0 | R10: 0 | S10: 1 | T10: 0 | U10: 1 | V10: 1 | W10: 0 | X10: 0 | Y10: 1 | Z10: 0 | AA10: 1 | AB10: 0 | AC10: 0 | AD10: 0 | AE10: 0 | AF10: 0 | AG10: 0 | AH10: 0 | AI10: 0 | AJ10: 0 | AK10: 0 | AL10: 0 | AM10: 0 | AN10: 0 | AO10: 0 | AP10: 0 | AQ10: 0 | AR10: =E10-AE10 -> 0 | AS10: =F10-AF10 -> 0 | AT10: =G10-AG10 -> 0 | AU10: =H10-AH10 -> 0 | AV10: =I10-AI10 -> 0 | AW10: =J10-AJ10 -> 0 | AX10: =K10-AK10 -> 0 | AY10: =L10-AL10 -> 0 | ... BD10: =Q10-AQ10 -> 0 | BE10: =SUMIF(AR10:BD10,"<0",AR10:BD10) -> 0 | BF10: =IF(BE10<0,D10+BE10,D10) -> 0 | BG10: =IF(BF10<0,C10+BF10,C10) -> 0
A11: 12100004300L/XL | B11: High Coast Wind Cap | C11: 0 | D11: 0 | E11: 0 | F11: 0 | G11: 0 | H11: 0 | I11: 0 | J11: 0 | K11: 0 | L11: 0 | M11: 0 | N11: 0 | O11: 0 | P11: 0 | Q11: 0 | R11: 0 | S11: 1 | T11: 0 | U11: 0 | V11: 0 | W11: 0 | X11: 0 | Y11: 0 | Z11: 0 | AA11: 0 | AB11: 0 | AC11: 0 | AD11: 0 | AE11: 0 | AF11: 0 | AG11: 0 | AH11: 0 | AI11: 0 | AJ11: 0 | AK11: 0 | AL11: 0 | AM11: 0 | AN11: 0 | AO11: 0 | AP11: 0 | AQ11: 0 | AR11: =E11-AE11 -> 0 | AS11: =F11-AF11 -> 0 | AT11: =G11-AG11 -> 0 | AU11: =H11-AH11 -> 0 | AV11: =I11-AI11 -> 0 | AW11: =J11-AJ11 -> 0 | AX11: =K11-AK11 -> 0 | AY11: =L11-AL11 -> 0 | ... BD11: =Q11-AQ11 -> 0 | BE11: =SUMIF(AR11:BD11,"<0",AR11:BD11) -> 0 | BF11: =IF(BE11<0,D11+BE11,D11) -> 0 | BG11: =IF(BF11<0,C11+BF11,C11) -> 0
A12: 12100004300S/M | B12: High Coast Wind Cap | C12: 0 | D12: 0 | E12: 0 | F12: 0 | G12: 0 | H12: 0 | I12: 0 | J12: 0 | K12: 0 | L12: 0 | M12: 0 | N12: 0 | O12: 0 | P12: 0 | Q12: 0 | R12: 0 | S12: 1 | T12: 0 | U12: 2 | V12: 0 | W12: 2 | X12: 0 | Y12: 0 | Z12: 0 | AA12: 0 | AB12: 0 | AC12: 1 | AD12: 0 | AE12: 0 | AF12: 0 | AG12: 0 | AH12: 0 | AI12: 0 | AJ12: 0 | AK12: 0 | AL12: 0 | AM12: 0 | AN12: 0 | AO12: 0 | AP12: 0 | AQ12: 0 | AR12: =E12-AE12 -> 0 | AS12: =F12-AF12 -> 0 | AT12: =G12-AG12 -> 0 | AU12: =H12-AH12 -> 0 | AV12: =I12-AI12 -> 0 | AW12: =J12-AJ12 -> 0 | AX12: =K12-AK12 -> 0 | AY12: =L12-AL12 -> 0 | ... BD12: =Q12-AQ12 -> 0 | BE12: =SUMIF(AR12:BD12,"<0",AR12:BD12) -> 0 | BF12: =IF(BE12<0,D12+BE12,D12) -> 0 | BG12: =IF(BF12<0,C12+BF12,C12) -> 0
A13: 12100004550L/XL | B13: High Coast Wind Cap | C13: 0 | D13: 0 | E13: 0 | F13: 0 | G13: 0 | H13: 0 | I13: 0 | J13: 0 | K13: 0 | L13: 0 | M13: 0 | N13: 0 | O13: 0 | P13: 0 | Q13: 0 | R13: 0 | S13: 1 | T13: 0 | U13: 0 | V13: 0 | W13: 0 | X13: 1 | Y13: 1 | Z13: 0 | AA13: 0 | AB13: 0 | AC13: 0 | AD13: 0 | AE13: 0 | AF13: 0 | AG13: 0 | AH13: 0 | AI13: 0 | AJ13: 0 | AK13: 0 | AL13: 0 | AM13: 0 | AN13: 0 | AO13: 0 | AP13: 0 | AQ13: 0 | AR13: =E13-AE13 -> 0 | AS13: =F13-AF13 -> 0 | AT13: =G13-AG13 -> 0 | AU13: =H13-AH13 -> 0 | AV13: =I13-AI13 -> 0 | AW13: =J13-AJ13 -> 0 | AX13: =K13-AK13 -> 0 | AY13: =L13-AL13 -> 0 | ... BD13: =Q13-AQ13 -> 0 | BE13: =SUMIF(AR13:BD13,"<0",AR13:BD13) -> 0 | BF13: =IF(BE13<0,D13+BE13,D13) -> 0 | BG13: =IF(BF13<0,C13+BF13,C13) -> 0
A14: 12100004550S/M | B14: High Coast Wind Cap | C14: 0 | D14: 0 | E14: 0 | F14: 0 | G14: 0 | H14: 0 | I14: 0 | J14: 0 | K14: 0 | L14: 0 | M14: 0 | N14: 0 | O14: 0 | P14: 0 | Q14: 0 | R14: 0 | S14: 1 | T14: 0 | U14: 0 | V14: 0 | W14: 0 | X14: 1 | Y14: 2 | Z14: 0 | AA14: 0 | AB14: 0 | AC14: 0 | AD14: 0 | AE14: 0 | AF14: 0 | AG14: 0 | AH14: 0 | AI14: 0 | AJ14: 0 | AK14: 0 | AL14: 0 | AM14: 0 | AN14: 0 | AO14: 0 | AP14: 0 | AQ14: 0 | AR14: =E14-AE14 -> 0 | AS14: =F14-AF14 -> 0 | AT14: =G14-AG14 -> 0 | AU14: =H14-AH14 -> 0 | AV14: =I14-AI14 -> 0 | AW14: =J14-AJ14 -> 0 | AX14: =K14-AK14 -> 0 | AY14: =L14-AL14 -> 0 | ... BD14: =Q14-AQ14 -> 0 | BE14: =SUMIF(AR14:BD14,"<0",AR14:BD14) -> 0 | BF14: =IF(BE14<0,D14+BE14,D14) -> 0 | BG14: =IF(BF14<0,C14+BF14,C14) -> 0
A15: 12100004574-118L/XL | B15: High Coast Wind Cap | C15: 0 | D15: 0 | E15: 0 | F15: 0 | G15: 0 | H15: 0 | I15: 0 | J15: 0 | K15: 0 | L15: 0 | M15: 0 | N15: 0 | O15: 0 | P15: 0 | Q15: 0 | R15: 0 | S15: 0 | T15: 0 | U15: 0 | V15: 0 | W15: 1 | X15: 0 | Y15: 0 | Z15: 0 | AA15: 0 | AB15: 0 | AC15: 0 | AD15: 0 | AE15: 0 | AF15: 0 | AG15: 0 | AH15: 0 | AI15: 0 | AJ15: 0 | AK15: 0 | AL15: 0 | AM15: 0 | AN15: 0 | AO15: 0 | AP15: 0 | AQ15: 0 | AR15: =E15-AE15 -> 0 | AS15: =F15-AF15 -> 0 | AT15: =G15-AG15 -> 0 | AU15: =H15-AH15 -> 0 | AV15: =I15-AI15 -> 0 | AW15: =J15-AJ15 -> 0 | AX15: =K15-AK15 -> 0 | AY15: =L15-AL15 -> 0 | ... BD15: =Q15-AQ15 -> 0 | BE15: =SUMIF(AR15:BD15,"<0",AR15:BD15) -> 0 | BF15: =IF(BE15<0,D15+BE15,D15) -> 0 | BG15: =IF(BF15<0,C15+BF15,C15) -> 0
... A27: 12200190550XS | B27: Bergtagen GTX Pro Trousers M | C27: 0 | D27: 0 | E27: 0 | F27: 0 | G27: 0 | H27: 0 | I27: 0 | J27: 0 | K27: 0 | L27: 0 | M27: 0 | N27: 0 | O27: 0 | P27: 0 | Q27: 0 | R27: 0 | S27: 0 | T27: 0 | U27: 1 | V27: 0 | W27: 0 | X27: 1 | Y27: 0 | Z27: 0 | AA27: 0 | AB27: 0 | AC27: 0 | AD27: 0 | AE27: 0 | AF27: 0 | AG27: 0 | AH27: 0 | AI27: 0 | AJ27: 0 | AK27: 0 | AL27: 0 | AM27: 0 | AN27: 0 | AO27: 0 | AP27: 0 | AQ27: 0 | AR27: =E27-AE27 -> 0 | AS27: =F27-AF27 -> 0 | AT27: =G27-AG27 -> 0 | AU27: =H27-AH27 -> 0 | AV27: =I27-AI27 -> 0 | AW27: =J27-AJ27 -> 0 | AX27: =K27-AK27 -> 0 | AY27: =L27-AL27 -> 0 | ... BD27: =Q27-AQ27 -> 0 | BE27: =SUMIF(AR27:BD27,"<0",AR27:BD27) -> 0 | BF27: =IF(BE27<0,D27+BE27,D27) -> 0 | BG27: =IF(BF27<0,C27+BF27,C27) -> 0
A28: 1220019755044 | B28: Hoja Hybrid Trousers M | C28: 0 | D28: 5 | E28: 0 | F28: 0 | G28: 0 | H28: 0 | I28: 0 | J28: 0 | K28: 0 | L28: 0 | M28: 0 | N28: 0 | O28: 0 | P28: 0 | Q28: 0 | R28: 0 | S28: 1 | T28: 0 | U28: 1 | V28: 1 | W28: 1 | X28: 0 | Y28: 1 | Z28: 0 | AA28: 1 | AB28: 0 | AC28: 1 | AD28: 0 | AE28: 0 | AF28: 0 | AG28: 0 | AH28: 0 | AI28: 0 | AJ28: 0 | AK28: 0 | AL28: 0 | AM28: 0 | AN28: 0 | AO28: 0 | AP28: 0 | AQ28: 0 | AR28: =E28-AE28 -> 0 | AS28: =F28-AF28 -> 0 | AT28: =G28-AG28 -> 0 | AU28: =H28-AH28 -> 0 | AV28: =I28-AI28 -> 0 | AW28: =J28-AJ28 -> 0 | AX28: =K28-AK28 -> 0 | AY28: =L28-AL28 -> 0 | ... BD28: =Q28-AQ28 -> 0 | BE28: =SUMIF(AR28:BD28,"<0",AR28:BD28) -> 0 | BF28: =IF(BE28<0,D28+BE28,D28) -> 5 | BG28: =IF(BF28<0,C28+BF28,C28) -> 0
A29: 1220019755046 | B29: Hoja Hybrid Trousers M | C29: 1 | D29: 10 | E29: 0 | F29: 0 | G29: 0 | H29: 0 | I29: 0 | J29: 0 | K29: 0 | L29: 0 | M29: 0 | N29: 0 | O29: 0 | P29: 0 | Q29: 0 | R29: 0 | S29: 1 | T29: 0 | U29: 2 | V29: 1 | W29: 1 | X29: 1 | Y29: 1 | Z29: 0 | AA29: 1 | AB29: 0 | AC29: 1 | AD29: 0 | AE29: 0 | AF29: 0 | AG29: 0 | AH29: 0 | AI29: 0 | AJ29: 0 | AK29: 0 | AL29: 0 | AM29: 0 | AN29: 0 | AO29: 0 | AP29: 0 | AQ29: 0 | AR29: =E29-AE29 -> 0 | AS29: =F29-AF29 -> 0 | AT29: =G29-AG29 -> 0 | AU29: =H29-AH29 -> 0 | AV29: =I29-AI29 -> 0 | AW29: =J29-AJ29 -> 0 | AX29: =K29-AK29 -> 0 | AY29: =L29-AL29 -> 0 | ... BD29: =Q29-AQ29 -> 0 | BE29: =SUMIF(AR29:BD29,"<0",AR29:BD29) -> 0 | BF29: =IF(BE29<0,D29+BE29,D29) -> 10 | BG29: =IF(BF29<0,C29+BF29,C29) -> 1
A30: 1220019755048 | B30: Hoja Hybrid Trousers M | C30: 0 | D30: 7 | E30: 0 | F30: 0 | G30: 0 | H30: 0 | I30: 0 | J30: 0 | K30: 0 | L30: 0 | M30: 0 | N30: 0 | O30: 0 | P30: 0 | Q30: 0 | R30: 0 | S30: 1 | T30: 0 | U30: 1 | V30: 1 | W30: 1 | X30: 1 | Y30: 1 | Z30: 0 | AA30: 1 | AB30: 0 | AC30: 1 | AD30: 0 | AE30: 0 | AF30: 0 | AG30: 0 | AH30: 0 | AI30: 0 | AJ30: 0 | AK30: 0 | AL30: 0 | AM30: 0 | AN30: 0 | AO30: 0 | AP30: 0 | AQ30: 0 | AR30: =E30-AE30 -> 0 | AS30: =F30-AF30 -> 0 | AT30: =G30-AG30 -> 0 | AU30: =H30-AH30 -> 0 | AV30: =I30-AI30 -> 0 | AW30: =J30-AJ30 -> 0 | AX30: =K30-AK30 -> 0 | AY30: =L30-AL30 -> 0 | ... BD30: =Q30-AQ30 -> 0 | BE30: =SUMIF(AR30:BD30,"<0",AR30:BD30) -> 0 | BF30: =IF(BE30<0,D30+BE30,D30) -> 7 | BG30: =IF(BF30<0,C30+BF30,C30) -> 0
A31: 1220019755050 | B31: Hoja Hybrid Trousers M | C31: 0 | D31: 6 | E31: 0 | F31: 0 | G31: 0 | H31: 0 | I31: 0 | J31: 0 | K31: 0 | L31: 0 | M31: 0 | N31: 0 | O31: 0 | P31: 0 | Q31: 0 | R31: 0 | S31: 1 | T31: 0 | U31: 1 | V31: 1 | W31: 1 | X31: 1 | Y31: 1 | Z31: 0 | AA31: 1 | AB31: 0 | AC31: 1 | AD31: 0 | AE31: 0 | AF31: 0 | AG31: 0 | AH31: 0 | AI31: 0 | AJ31: 0 | AK31: 0 | AL31: 0 | AM31: 0 | AN31: 0 | AO31: 0 | AP31: 0 | AQ31: 0 | AR31: =E31-AE31 -> 0 | AS31: =F31-AF31 -> 0 | AT31: =G31-AG31 -> 0 | AU31: =H31-AH31 -> 0 | AV31: =I31-AI31 -> 0 | AW31: =J31-AJ31 -> 0 | AX31: =K31-AK31 -> 0 | AY31: =L31-AL31 -> 0 | ... BD31: =Q31-AQ31 -> 0 | BE31: =SUMIF(AR31:BD31,"<0",AR31:BD31) -> 0 | BF31: =IF(BE31<0,D31+BE31,D31) -> 6 | BG31: =IF(BF31<0,C31+BF31,C31) -> 0
A32: 1220019755052 | B32: Hoja Hybrid Trousers M | C32: 0 | D32: 0 | E32: 0 | F32: 0 | G32: 0 | H32: 0 | I32: 0 | J32: 0 | K32: 0 | L32: 0 | M32: 0 | N32: 0 | O32: 0 | P32: 0 | Q32: 0 | R32: 0 | S32: 0 | T32: 0 | U32: 1 | V32: 1 | W32: 0 | X32: 0 | Y32: 0 | Z32: 0 | AA32: 0 | AB32: 0 | AC32: 0 | AD32: 0 | AE32: 0 | AF32: 0 | AG32: 0 | AH32: 0 | AI32: 0 | AJ32: 0 | AK32: 0 | AL32: 0 | AM32: 0 | AN32: 0 | AO32: 0 | AP32: 0 | AQ32: 0 | AR32: =E32-AE32 -> 0 | AS32: =F32-AF32 -> 0 | AT32: =G32-AG32 -> 0 | AU32: =H32-AH32 -> 0 | AV32: =I32-AI32 -> 0 | AW32: =J32-AJ32 -> 0 | AX32: =K32-AK32 -> 0 | AY32: =L32-AL32 -> 0 | ... BD32: =Q32-AQ32 -> 0 | BE32: =SUMIF(AR32:BD32,"<0",AR32:BD32) -> 0 | BF32: =IF(BE32<0,D32+BE32,D32) -> 0 | BG32: =IF(BF32<0,C32+BF32,C32) -> 0
A33: 1220020755046 | B33: High Coast Pack Shorts M | C33: 4 | D33: 0 | E33: 0 | F33: 0 | G33: 0 | H33: 0 | I33: 0 | J33: 0 | K33: 0 | L33: 0 | M33: 0 | N33: 0 | O33: 0 | P33: 0 | Q33: 0 | R33: 0 | S33: 1 | T33: 0 | U33: 1 | V33: 1 | W33: 1 | X33: 0 | Y33: 1 | Z33: 0 | AA33: 1 | AB33: 1 | AC33: 1 | AD33: 0 | AE33: 0 | AF33: 0 | AG33: 0 | AH33: 0 | AI33: 0 | AJ33: 0 | AK33: 0 | AL33: 0 | AM33: 0 | AN33: 0 | AO33: 0 | AP33: 0 | AQ33: 0 | AR33: =E33-AE33 -> 0 | AS33: =F33-AF33 -> 0 | AT33: =G33-AG33 -> 0 | AU33: =H33-AH33 -> 0 | AV33: =I33-AI33 -> 0 | AW33: =J33-AJ33 -> 0 | AX33: =K33-AK33 -> 0 | AY33: =L33-AL33 -> 0 | ... BD33: =Q33-AQ33 -> 0 | BE33: =SUMIF(AR33:BD33,"<0",AR33:BD33) -> 0 | BF33: =IF(BE33<0,D33+BE33,D33) -> 0 | BG33: =IF(BF33<0,C33+BF33,C33) -> 4
A34: 1220020755048 | B34: High Coast Pack Shorts M | C34: 3 | D34: 0 | E34: 0 | F34: 0 | G34: 0 | H34: 0 | I34: 0 | J34: 0 | K34: 0 | L34: 0 | M34: 0 | N34: 0 | O34: 0 | P34: 0 | Q34: 0 | R34: 0 | S34: 1 | T34: 0 | U34: 1 | V34: 1 | W34: 1 | X34: 0 | Y34: 1 | Z34: 0 | AA34: 1 | AB34: 1 | AC34: 1 | AD34: 0 | AE34: 0 | AF34: 0 | AG34: 0 | AH34: 0 | AI34: 0 | AJ34: 0 | AK34: 0 | AL34: 0 | AM34: 0 | AN34: 0 | AO34: 0 | AP34: 0 | AQ34: 0 | AR34: =E34-AE34 -> 0 | AS34: =F34-AF34 -> 0 | AT34: =G34-AG34 -> 0 | AU34: =H34-AH34 -> 0 | AV34: =I34-AI34 -> 0 | AW34: =J34-AJ34 -> 0 | AX34: =K34-AK34 -> 0 | AY34: =L34-AL34 -> 0 | ... BD34: =Q34-AQ34 -> 0 | BE34: =SUMIF(AR34:BD34,"<0",AR34:BD34) -> 0 | BF34: =IF(BE34<0,D34+BE34,D34) -> 0 | BG34: =IF(BF34<0,C34+BF34,C34) -> 3
A35: 1220020755050 | B35: High Coast Pack Shorts M | C35: 2 | D35: 0 | E35: 0 | F35: 0 | G35: 0 | H35: 0 | I35: 0 | J35: 0 | K35: 0 | L35: 0 | M35: 0 | N35: 0 | O35: 0 | P35: 0 | Q35: 0 | R35: 0 | S35: 1 | T35: 0 | U35: 1 | V35: 0 | W35: 1 | X35: 0 | Y35: 1 | Z35: 0 | AA35: 1 | AB35: 1 | AC35: 1 | AD35: 0 | AE35: 0 | AF35: 0 | AG35: 0 | AH35: 0 | AI35: 1 | AJ35: 0 | AK35: 0 | AL35: 0 | AM35: 0 | AN35: 0 | AO35: 0 | AP35: 0 | AQ35: 0 | AR35: =E35-AE35 -> 0 | AS35: =F35-AF35 -> 0 | AT35: =G35-AG35 -> 0 | AU35: =H35-AH35 -> 0 | AV35: =I35-AI35 -> -1 | AW35: =J35-AJ35 -> 0 | AX35: =K35-AK35 -> 0 | AY35: =L35-AL35 -> 0 | ... BD35: =Q35-AQ35 -> 0 | BE35: =SUMIF(AR35:BD35,"<0",AR35:BD35) -> -1 | BF35: =IF(BE35<0,D35+BE35,D35) -> -1 | BG35: =IF(BF35<0,C35+BF35,C35) -> 1
A36: 1220020755052 | B36: High Coast Pack Shorts M | C36: 0 | D36: 0 | E36: 0 | F36: 0 | G36: 0 | H36: 0 | I36: 0 | J36: 0 | K36: 0 | L36: 0 | M36: 0 | N36: 0 | O36: 0 | P36: 0 | Q36: 0 | R36: 0 | S36: 1 | T36: 0 | U36: 1 | V36: 1 | W36: 1 | X36: 0 | Y36: 0 | Z36: 0 | AA36: 0 | AB36: 0 | AC36: 0 | AD36: 0 | AE36: 0 | AF36: 0 | AG36: 0 | AH36: 0 | AI36: 0 | AJ36: 0 | AK36: 0 | AL36: 0 | AM36: 0 | AN36: 0 | AO36: 0 | AP36: 0 | AQ36: 0 | AR36: =E36-AE36 -> 0 | AS36: =F36-AF36 -> 0 | AT36: =G36-AG36 -> 0 | AU36: =H36-AH36 -> 0 | AV36: =I36-AI36 -> 0 | AW36: =J36-AJ36 -> 0 | AX36: =K36-AK36 -> 0 | AY36: =L36-AL36 -> 0 | ... BD36: =Q36-AQ36 -> 0 | BE36: =SUMIF(AR36:BD36,"<0",AR36:BD36) -> 0 | BF36: =IF(BE36<0,D36+BE36,D36) -> 0 | BG36: =IF(BF36<0,C36+BF36,C36) -> 0
A37: 1220020762546 | B37: High Coast Pack Shorts M | C37: 5 | D37: 0 | E37: 0 | F37: 0 | G37: 0 | H37: 0 | I37: 0 | J37: 0 | K37: 0 | L37: 0 | M37: 0 | N37: 0 | O37: 0 | P37: 0 | Q37: 0 | R37: 0 | S37: 1 | T37: 0 | U37: 1 | V37: 1 | W37: 1 | X37: 0 | Y37: 1 | Z37: 0 | AA37: 1 | AB37: 1 | AC37: 1 | AD37: 0 | AE37: 0 | AF37: 0 | AG37: 0 | AH37: 0 | AI37: 0 | AJ37: 0 | AK37: 0 | AL37: 0 | AM37: 0 | AN37: 0 | AO37: 0 | AP37: 0 | AQ37: 0 | AR37: =E37-AE37 -> 0 | AS37: =F37-AF37 -> 0 | AT37: =G37-AG37 -> 0 | AU37: =H37-AH37 -> 0 | AV37: =I37-AI37 -> 0 | AW37: =J37-AJ37 -> 0 | AX37: =K37-AK37 -> 0 | AY37: =L37-AL37 -> 0 | ... BD37: =Q37-AQ37 -> 0 | BE37: =SUMIF(AR37:BD37,"<0",AR37:BD37) -> 0 | BF37: =IF(BE37<0,D37+BE37,D37) -> 0 | BG37: =IF(BF37<0,C37+BF37,C37) -> 5
A38: 1220020762548 | B38: High Coast Pack Shorts M | C38: 2 | D38: 0 | E38: 0 | F38: 0 | G38: 0 | H38: 0 | I38: 0 | J38: 0 | K38: 0 | L38: 0 | M38: 0 | N38: 0 | O38: 0 | P38: 0 | Q38: 0 | R38: 0 | S38: 1 | T38: 0 | U38: 1 | V38: 1 | W38: 1 | X38: 0 | Y38: 1 | Z38: 0 | AA38: 1 | AB38: 1 | AC38: 1 | AD38: 0 | AE38: 0 | AF38: 0 | AG38: 0 | AH38: 0 | AI38: 0 | AJ38: 0 | AK38: 0 | AL38: 0 | AM38: 0 | AN38: 0 | AO38: 0 | AP38: 0 | AQ38: 0 | AR38: =E38-AE38 -> 0 | AS38: =F38-AF38 -> 0 | AT38: =G38-AG38 -> 0 | AU38: =H38-AH38 -> 0 | AV38: =I38-AI38 -> 0 | AW38: =J38-AJ38 -> 0 | AX38: =K38-AK38 -> 0 | AY38: =L38-AL38 -> 0 | ... BD38: =Q38-AQ38 -> 0 | BE38: =SUMIF(AR38:BD38,"<0",AR38:BD38) -> 0 | BF38: =IF(BE38<0,D38+BE38,D38) -> 0 | BG38: =IF(BF38<0,C38+BF38,C38) -> 2
A39: 1220020762550 | B39: High Coast Pack Shorts M | C39: 3 | D39: 0 | E39: 0 | F39: 0 | G39: 0 | H39: 0 | I39: 0 | J39: 0 | K39: 0 | L39: 0 | M39: 0 | N39: 0 | O39: 0 | P39: 0 | Q39: 0 | R39: 0 | S39: 1 | T39: 0 | U39: 1 | V39: 1 | W39: 1 | X39: 0 | Y39: 1 | Z39: 0 | AA39: 1 | AB39: 1 | AC39: 1 | AD39: 0 | AE39: 0 | AF39: 0 | AG39: 0 | AH39: 0 | AI39: 0 | AJ39: 0 | AK39: 0 | AL39: 0 | AM39: 0 | AN39: 0 | AO39: 0 | AP39: 0 | AQ39: 0 | AR39: =E39-AE39 -> 0 | AS39: =F39-AF39 -> 0 | AT39: =G39-AG39 -> 0 | AU39: =H39-AH39 -> 0 | AV39: =I39-AI39 -> 0 | AW39: =J39-AJ39 -> 0 | AX39: =K39-AK39 -> 0 | AY39: =L39-AL39 -> 0 | ... BD39: =Q39-AQ39 -> 0 | BE39: =SUMIF(AR39:BD39,"<0",AR39:BD39) -> 0 | BF39: =IF(BE39<0,D39+BE39,D39) -> 0 | BG39: =IF(BF39<0,C39+BF39,C39) -> 3
A40: 12200218550L | B40: Keb GTX Trousers M | C40: 0 | D40: 0 | E40: 0 | F40: 0 | G40: 0 | H40: 0 | I40: 0 | J40: 0 | K40: 0 | L40: 0 | M40: 0 | N40: 0 | O40: 0 | P40: 0 | Q40: 0 | R40: 0 | S40: 1 | T40: 0 | U40: 0 | V40: 1 | W40: 0 | X40: 0 | Y40: 0 | Z40: 0 | AA40: 0 | AB40: 1 | AC40: 0 | AD40: 0 | AE40: 0 | AF40: 0 | AG40: 0 | AH40: 0 | AI40: 0 | AJ40: 0 | AK40: 0 | AL40: 0 | AM40: 0 | AN40: 0 | AO40: 0 | AP40: 0 | AQ40: 0 | AR40: =E40-AE40 -> 0 | AS40: =F40-AF40 -> 0 | AT40: =G40-AG40 -> 0 | AU40: =H40-AH40 -> 0 | AV40: =I40-AI40 -> 0 | AW40: =J40-AJ40 -> 0 | AX40: =K40-AK40 -> 0 | AY40: =L40-AL40 -> 0 | ... BD40: =Q40-AQ40 -> 0 | BE40: =SUMIF(AR40:BD40,"<0",AR40:BD40) -> 0 | BF40: =IF(BE40<0,D40+BE40,D40) -> 0 | BG40: =IF(BF40<0,C40+BF40,C40) -> 0
A41: 12200218550M | B41: Keb GTX Trousers M | C41: 0 | D41: 0 | E41: 0 | F41: 0 | G41: 0 | H41: 0 | I41: 0 | J41: 0 | K41: 0 | L41: 0 | M41: 0 | N41: 0 | O41: 0 | P41: 0 | Q41: 0 | R41: 0 | S41: 1 | T41: 0 | U41: 1 | V41: 0 | W41: 0 | X41: 1 | Y41: 1 | Z41: 0 | AA41: 0 | AB41: 1 | AC41: 1 | AD41: 0 | AE41: 0 | AF41: 0 | AG41: 0 | AH41: 0 | AI41: 0 | AJ41: 0 | AK41: 0 | AL41: 0 | AM41: 0 | AN41: 0 | AO41: 0 | AP41: 0 | AQ41: 0 | AR41: =E41-AE41 -> 0 | AS41: =F41-AF41 -> 0 | AT41: =G41-AG41 -> 0 | AU41: =H41-AH41 -> 0 | AV41: =I41-AI41 -> 0 | AW41: =J41-AJ41 -> 0 | AX41: =K41-AK41 -> 0 | AY41: =L41-AL41 -> 0 | ... BD41: =Q41-AQ41 -> 0 | BE41: =SUMIF(AR41:BD41,"<0",AR41:BD41) -> 0 | BF41: =IF(BE41<0,D41+BE41,D41) -> 0 | BG41: =IF(BF41<0,C41+BF41,C41) -> 0
A42: 12200218550S | B42: Keb GTX Trousers M | C42: 0 | D42: 0 | E42: 0 | F42: 0 | G42: 0 | H42: 0 | I42: 0 | J42: 0 | K42: 0 | L42: 0 | M42: 0 | N42: 0 | O42: 0 | P42: 0 | Q42: 0 | R42: 0 | S42: 1 | T42: 0 | U42: 0 | V42: 0 | W42: 1 | X42: 0 | Y42: 1 | Z42: 0 | AA42: 1 | AB42: 0 | AC42: 0 | AD42: 0 | AE42: 0 | AF42: 0 | AG42: 0 | AH42: 0 | AI42: 0 | AJ42: 0 | AK42: 0 | AL42: 0 | AM42: 0 | AN42: 0 | AO42: 0 | AP42: 0 | AQ42: 0 | AR42: =E42-AE42 -> 0 | AS42: =F42-AF42 -> 0 | AT42: =G42-AG42 -> 0 | AU42: =H42-AH42 -> 0 | AV42: =I42-AI42 -> 0 | AW42: =J42-AJ42 -> 0 | AX42: =K42-AK42 -> 0 | AY42: =L42-AL42 -> 0 | ... BD42: =Q42-AQ42 -> 0 | BE42: =SUMIF(AR42:BD42,"<0",AR42:BD42) -> 0 | BF42: =IF(BE42<0,D42+BE42,D42) -> 0 | BG42: =IF(BF42<0,C42+BF42,C42) -> 0
A43: 12200218550XS | B43: Keb GTX Trousers M | C43: 0 | D43: 0 | E43: 0 | F43: 0 | G43: 0 | H43: 0 | I43: 0 | J43: 0 | K43: 0 | L43: 0 | M43: 0 | N43: 0 | O43: 0 | P43: 0 | Q43: 0 | R43: 0 | S43: 1 | T43: 0 | U43: 1 | V43: 1 | W43: 1 | X43: 1 | Y43: 0 | Z43: 0 | AA43: 0 | AB43: 0 | AC43: 0 | AD43: 0 | AE43: 0 | AF43: 0 | AG43: 0 | AH43: 0 | AI43: 0 | AJ43: 0 | AK43: 0 | AL43: 0 | AM43: 0 | AN43: 0 | AO43: 0 | AP43: 0 | AQ43: 0 | AR43: =E43-AE43 -> 0 | AS43: =F43-AF43 -> 0 | AT43: =G43-AG43 -> 0 | AU43: =H43-AH43 -> 0 | AV43: =I43-AI43 -> 0 | AW43: =J43-AJ43 -> 0 | AX43: =K43-AK43 -> 0 | AY43: =L43-AL43 -> 0 | ... BD43: =Q43-AQ43 -> 0 | BE43: =SUMIF(AR43:BD43,"<0",AR43:BD43) -> 0 | BF43: =IF(BE43<0,D43+BE43,D43) -> 0 | BG43: =IF(BF43<0,C43+BF43,C43) -> 0
A44: 12200219537L | B44: Vardag Summer Shorts M | C44: 0 | D44: 0 | E44: 0 | F44: 0 | G44: 0 | H44: 0 | I44: 0 | J44: 0 | K44: 0 | L44: 0 | M44: 0 | N44: 0 | O44: 0 | P44: 0 | Q44: 0 | R44: 0 | S44: 0 | T44: 0 | U44: 1 | V44: 0 | W44: 0 | X44: 0 | Y44: 0 | Z44: 0 | AA44: 0 | AB44: 0 | AC44: 0 | AD44: 0 | AE44: 0 | AF44: 0 | AG44: 0 | AH44: 1 | AI44: 0 | AJ44: 0 | AK44: 0 | AL44: 0 | AM44: 0 | AN44: 0 | AO44: 0 | AP44: 0 | AQ44: 0 | AR44: =E44-AE44 -> 0 | AS44: =F44-AF44 -> 0 | AT44: =G44-AG44 -> 0 | AU44: =H44-AH44 -> -1 | AV44: =I44-AI44 -> 0 | AW44: =J44-AJ44 -> 0 | AX44: =K44-AK44 -> 0 | AY44: =L44-AL44 -> 0 | ... BD44: =Q44-AQ44 -> 0 | BE44: =SUMIF(AR44:BD44,"<0",AR44:BD44) -> -1 | BF44: =IF(BE44<0,D44+BE44,D44) -> -1 | BG44: =IF(BF44<0,C44+BF44,C44) -> -1
A45: 12200219537M | B45: Vardag Summer Shorts M | C45: 0 | D45: 0 | E45: 0 | F45: 0 | G45: 0 | H45: 0 | I45: 0 | J45: 0 | K45: 0 | L45: 0 | M45: 0 | N45: 0 | O45: 0 | P45: 0 | Q45: 0 | R45: 0 | S45: 0 | T45: 0 | U45: 1 | V45: 1 | W45: 1 | X45: 0 | Y45: 0 | Z45: 0 | AA45: 0 | AB45: 0 | AC45: 0 | AD45: 0 | AE45: 0 | AF45: 1 | AG45: 0 | AH45: 0 | AI45: 0 | AJ45: 0 | AK45: 0 | AL45: 0 | AM45: 0 | AN45: 0 | AO45: 0 | AP45: 0 | AQ45: 0 | AR45: =E45-AE45 -> 0 | AS45: =F45-AF45 -> -1 | AT45: =G45-AG45 -> 0 | AU45: =H45-AH45 -> 0 | AV45: =I45-AI45 -> 0 | AW45: =J45-AJ45 -> 0 | AX45: =K45-AK45 -> 0 | AY45: =L45-AL45 -> 0 | ... BD45: =Q45-AQ45 -> 0 | BE45: =SUMIF(AR45:BD45,"<0",AR45:BD45) -> -1 | BF45: =IF(BE45<0,D45+BE45,D45) -> -1 | BG45: =IF(BF45<0,C45+BF45,C45) -> -1
A46: 12200219537S | B46: Vardag Summer Shorts M | C46: 2 | D46: 0 | E46: 0 | F46: 0 | G46: 0 | H46: 0 | I46: 0 | J46: 0 | K46: 0 | L46: 0 | M46: 0 | N46: 0 | O46: 0 | P46: 0 | Q46: 0 | R46: 0 | S46: 1 | T46: 0 | U46: 1 | V46: 1 | W46: 1 | X46: 0 | Y46: 0 | Z46: 0 | AA46: 0 | AB46: 1 | AC46: 0 | AD46: 0 | AE46: 0 | AF46: 0 | AG46: 0 | AH46: 0 | AI46: 0 | AJ46: 0 | AK46: 0 | AL46: 0 | AM46: 0 | AN46: 0 | AO46: 0 | AP46: 0 | AQ46: 0 | AR46: =E46-AE46 -> 0 | AS46: =F46-AF46 -> 0 | AT46: =G46-AG46 -> 0 | AU46: =H46-AH46 -> 0 | AV46: =I46-AI46 -> 0 | AW46: =J46-AJ46 -> 0 | AX46: =K46-AK46 -> 0 | AY46: =L46-AL46 -> 0 | ... BD46: =Q46-AQ46 -> 0 | BE46: =SUMIF(AR46:BD46,"<0",AR46:BD46) -> 0 | BF46: =IF(BE46<0,D46+BE46,D46) -> 0 | BG46: =IF(BF46<0,C46+BF46,C46) -> 2
A47: 12200219550L | B47: Vardag Summer Shorts M | C47: 0 | D47: 0 | E47: 0 | F47: 0 | G47: 0 | H47: 0 | I47: 0 | J47: 0 | K47: 0 | L47: 0 | M47: 0 | N47: 0 | O47: 0 | P47: 0 | Q47: 0 | R47: 0 | S47: 1 | T47: 0 | U47: 1 | V47: 1 | W47: 1 | X47: 0 | Y47: 0 | Z47: 0 | AA47: 0 | AB47: 0 | AC47: 0 | AD47: 0 | AE47: 0 | AF47: 0 | AG47: 0 | AH47: 0 | AI47: 0 | AJ47: 0 | AK47: 0 | AL47: 0 | AM47: 0 | AN47: 0 | AO47: 0 | AP47: 0 | AQ47: 0 | AR47: =E47-AE47 -> 0 | AS47: =F47-AF47 -> 0 | AT47: =G47-AG47 -> 0 | AU47: =H47-AH47 -> 0 | AV47: =I47-AI47 -> 0 | AW47: =J47-AJ47 -> 0 | AX47: =K47-AK47 -> 0 | AY47: =L47-AL47 -> 0 | ... BD47: =Q47-AQ47 -> 0 | BE47: =SUMIF(AR47:BD47,"<0",AR47:BD47) -> 0 | BF47: =IF(BE47<0,D47+BE47,D47) -> 0 | BG47: =IF(BF47<0,C47+BF47,C47) -> 0
A48: 12200219550M | B48: Vardag Summer Shorts M | C48: 5 | D48: 0 | E48: 0 | F48: 0 | G48: 0 | H48: 0 | I48: 0 | J48: 0 | K48: 0 | L48: 0 | M48: 0 | N48: 0 | O48: 0 | P48: 0 | Q48: 0 | R48: 0 | S48: 1 | T48: 0 | U48: 1 | V48: 1 | W48: 1 | X48: 0 | Y48: 0 | Z48: 0 | AA48: 0 | AB48: 1 | AC48: 1 | AD48: 0 | AE48: 0 | AF48: 0 | AG48: 0 | AH48: 0 | AI48: 0 | AJ48: 0 | AK48: 0 | AL48: 0 | AM48: 0 | AN48: 0 | AO48: 0 | AP48: 0 | AQ48: 0 | AR48: =E48-AE48 -> 0 | AS48: =F48-AF48 -> 0 | AT48: =G48-AG48 -> 0 | AU48: =H48-AH48 -> 0 | AV48: =I48-AI48 -> 0 | AW48: =J48-AJ48 -> 0 | AX48: =K48-AK48 -> 0 | AY48: =L48-AL48 -> 0 | ... BD48: =Q48-AQ48 -> 0 | BE48: =SUMIF(AR48:BD48,"<0",AR48:BD48) -> 0 | BF48: =IF(BE48<0,D48+BE48,D48) -> 0 | BG48: =IF(BF48<0,C48+BF48,C48) -> 5
A49: 12200219550S | B49: Vardag Summer Shorts M | C49: 2 | D49: 0 | E49: 0 | F49: 0 | G49: 0 | H49: 0 | I49: 0 | J49: 0 | K49: 0 | L49: 0 | M49: 0 | N49: 0 | O49: 0 | P49: 0 | Q49: 0 | R49: 0 | S49: 1 | T49: 0 | U49: 1 | V49: 1 | W49: 1 | X49: 0 | Y49: 0 | Z49: 0 | AA49: 0 | AB49: 1 | AC49: 1 | AD49: 0 | AE49: 0 | AF49: 0 | AG49: 0 | AH49: 0 | AI49: 0 | AJ49: 0 | AK49: 0 | AL49: 0 | AM49: 0 | AN49: 0 | AO49: 0 | AP49: 0 | AQ49: 0 | AR49: =E49-AE49 -> 0 | AS49: =F49-AF49 -> 0 | AT49: =G49-AG49 -> 0 | AU49: =H49-AH49 -> 0 | AV49: =I49-AI49 -> 0 | AW49: =J49-AJ49 -> 0 | AX49: =K49-AK49 -> 0 | AY49: =L49-AL49 -> 0 | ... BD49: =Q49-AQ49 -> 0 | BE49: =SUMIF(AR49:BD49,"<0",AR49:BD49) -> 0 | BF49: =IF(BE49<0,D49+BE49,D49) -> 0 | BG49: =IF(BF49<0,C49+BF49,C49) -> 2
A50: 12200219625L | B50: Vardag Summer Shorts M | C50: 0 | D50: 0 | E50: 0 | F50: 0 | G50: 0 | H50: 0 | I50: 0 | J50: 0 | K50: 0 | L50: 0 | M50: 0 | N50: 0 | O50: 0 | P50: 0 | Q50: 0 | R50: 0 | S50: 0 | T50: 0 | U50: 1 | V50: 0 | W50: 0 | X50: 0 | Y50: 0 | Z50: 0 | AA50: 0 | AB50: 0 | AC50: 0 | AD50: 0 | AE50: 0 | AF50: 0 | AG50: 0 | AH50: 0 | AI50: 0 | AJ50: 0 | AK50: 0 | AL50: 0 | AM50: 0 | AN50: 0 | AO50: 0 | AP50: 0 | AQ50: 0 | AR50: =E50-AE50 -> 0 | AS50: =F50-AF50 -> 0 | AT50: =G50-AG50 -> 0 | AU50: =H50-AH50 -> 0 | AV50: =I50-AI50 -> 0 | AW50: =J50-AJ50 -> 0 | AX50: =K50-AK50 -> 0 | AY50: =L50-AL50 -> 0 | ... BD50: =Q50-AQ50 -> 0 | BE50: =SUMIF(AR50:BD50,"<0",AR50:BD50) -> 0 | BF50: =IF(BE50<0,D50+BE50,D50) -> 0 | BG50: =IF(BF50<0,C50+BF50,C50) -> 0
A51: 12200219625M | B51: Vardag Summer Shorts M | C51: 0 | D51: 0 | E51: 0 | F51: 0 | G51: 0 | H51: 0 | I51: 0 | J51: 0 | K51: 0 | L51: 0 | M51: 0 | N51: 0 | O51: 0 | P51: 0 | Q51: 0 | R51: 0 | S51: 1 | T51: 0 | U51: 0 | V51: 1 | W51: 0 | X51: 0 | Y51: 0 | Z51: 0 | AA51: 0 | AB51: 1 | AC51: 1 | AD51: 0 | AE51: 0 | AF51: 0 | AG51: 0 | AH51: 0 | AI51: 0 | AJ51: 0 | AK51: 0 | AL51: 0 | AM51: 0 | AN51: 0 | AO51: 0 | AP51: 0 | AQ51: 0 | AR51: =E51-AE51 -> 0 | AS51: =F51-AF51 -> 0 | AT51: =G51-AG51 -> 0 | AU51: =H51-AH51 -> 0 | AV51: =I51-AI51 -> 0 | AW51: =J51-AJ51 -> 0 | AX51: =K51-AK51 -> 0 | AY51: =L51-AL51 -> 0 | ... BD51: =Q51-AQ51 -> 0 | BE51: =SUMIF(AR51:BD51,"<0",AR51:BD51) -> 0 | BF51: =IF(BE51<0,D51+BE51,D51) -> 0 | BG51: =IF(BF51<0,C51+BF51,C51) -> 0
...
